Workbook

Sheet Trainer
A1: BAV Excel Trainer
A2: Complete each historical model-construction and earnings-quality diagnostic formula schedule left-to-right in dependency order. Run Check to validate the yellow formula cells against the treatment currently selected in Accounting Judgment column F (blank F uses the supplied reference treatment). Generated Condensed Financials classification links are system-controlled and validated by Check—do not edit them or columns D:E. When Normalization Judgment is present, choose Recurring vs Non-recurring in column F (blank uses the supplied reference); Earnings Normalization formulas are checked against that choice. Also complete Accounting Judgment and Normalization Judgment rationale/consequence when cases are present; those responses are not graded by Check. Compare them with the matching Answer Key.
A4: Order | B4: Schedule | C4: Period scope | D4: Tab | E4: Practice cells | F4: Depends on
A5: 1 | B5: Revenue historical source link | C5: 2021–2025 (5 cells) | D5: Condensed Financials | E5: B19:F19 | F5: —
A6: 2 | B6: Net Income historical source link | C6: 2021–2025 (5 cells) | D6: Condensed Financials | E6: B20:F20 | F6: —
A7: 3 | B7: Effective tax rate | C7: 2021–2025 (5 cells) | D7: Condensed Financials | E7: B25:F25 | F7: —
A8: 4 | B8: Net interest | C8: 2021–2025 (5 cells) | D8: Condensed Financials | E8: B26:F26 | F8: —
A9: 5 | B9: Net interest after tax | C9: 2021–2025 (5 cells) | D9: Condensed Financials | E9: B27:F27 | F9: effective_tax_rate_fy, net_interest_fy
A10: 6 | B10: NOPAT | C10: 2021–2025 (5 cells) | D10: Condensed Financials | E10: B28:F28 | F10: net_income_link, net_interest_after_tax_fy
A11: 7 | B11: Operating working capital assets | C11: 2021–2025 (5 cells) | D11: Condensed Financials | E11: B31:F31 | F11: —
A12: 8 | B12: Operating working capital liabilities | C12: 2021–2025 (5 cells) | D12: Condensed Financials | E12: B32:F32 | F12: —
A13: 9 | B13: Net Operating Working Capital (NOWC) | C13: 2021–2025 (5 cells) | D13: Condensed Financials | E13: B33:F33 | F13: owca_agg, owcl_agg
A14: 10 | B14: Operating long-term assets | C14: 2021–2025 (5 cells) | D14: Condensed Financials | E14: B34:F34 | F14: —
A15: 11 | B15: Operating long-term liabilities | C15: 2021–2025 (5 cells) | D15: Condensed Financials | E15: B35:F35 | F15: —
A16: 12 | B16: Net operating long-term assets (NOLA) | C16: 2021–2025 (5 cells) | D16: Condensed Financials | E16: B36:F36 | F16: olta_agg, oltl_agg
... A82: 90 | B82: Lease Liability Growth | C82: 2022–2025 (4 cells) | D82: ALT DuPont | E82: C58:F58 | F82: lease_liability_source_link

Sheet Income Statement
A1: Company: Demo Holdings Limited (DEMO)
A2: Statement: Income Statement
A3: Units: HKD in Millions
A4: Source: manual ingestion (HK)
A6: Line Item | B6: 44561 | C6: 44926 | D6: 45291 | E6: 45657 | F6: 46022
A7: Revenue | B7: 8500 | C7: 9200 | D7: 10100 | E7: 11200 | F7: 12500
A8: Cost of sales | B8: -3400 | C8: -3680 | D8: -4040 | E8: -4480 | F8: -5000
A9: Gross profit | B9: 5100 | C9: 5520 | D9: 6060 | E9: 6720 | F9: 7500
A10: Administrative expenses | B10: -1700 | C10: -1840 | D10: -1820 | E10: -2240 | F10: -2500
A11: Restructuring expense | B11: 0 | C11: 0 | D11: -200 | E11: 0 | F11: 0
A12: Operating profit | B12: 3400 | C12: 3680 | D12: 4040 | E12: 4480 | F12: 5000
A13: Finance costs | B13: -120 | C13: -130 | D13: -140 | E13: -150 | F13: -160
A14: Finance income | B14: 45 | C14: 50 | D14: 55 | E14: 60 | F14: 65
A15: Profit before tax | B15: 3325 | C15: 3600 | D15: 3955 | E15: 4390 | F15: 4905
A16: Income tax expense | B16: -565 | C16: -612 | D16: -672 | E16: -746 | F16: -833
A17: Profit for the year | B17: 2760 | C17: 2988 | D17: 3283 | E17: 3644 | F17: 4072

Sheet Balance Sheet
A1: Company: Demo Holdings Limited (DEMO)
A2: Statement: Balance Sheet
A3: Units: HKD in Millions
A4: Source: manual ingestion (HK)
A6: Line Item | B6: 44561 | C6: 44926 | D6: 45291 | E6: 45657 | F6: 46022
A7: Cash and cash equivalents | B7: 1200 | C7: 1350 | D7: 1500 | E7: 1680 | F7: 1850
A8: Trade receivables | B8: 850 | C8: 920 | D8: 1010 | E8: 1120 | F8: 1250
A9: Inventories | B9: 680 | C9: 736 | D9: 808 | E9: 896 | F9: 1000
A10: Property, plant and equipment | B10: 3200 | C10: 3400 | D10: 3600 | E10: 3800 | F10: 4000
A11: Goodwill | B11: 900 | C11: 900 | D11: 900 | E11: 900 | F11: 900
A12: Other non-current assets | B12: 1670 | C12: 1894 | D12: 2282 | E12: 2804 | F12: 3500
A13: Total assets | B13: 8500 | C13: 9200 | D13: 10100 | E13: 11200 | F13: 12500
A14: Trade payables | B14: 595 | C14: 644 | D14: 707 | E14: 784 | F14: 875
A15: Bank borrowings | B15: 1500 | C15: 1400 | D15: 1300 | E15: 1200 | F15: 1100
A16: Operating lease liabilities | B16: 300 | C16: 320 | D16: 340 | E16: 360 | F16: 380
A17: Other non-current liabilities | B17: 1005 | C17: 1136 | D17: 1253 | E17: 1356 | F17: 1445
... A20: Total equity | B20: 5100 | C20: 5700 | D20: 6500 | E20: 7500 | F20: 8700

Sheet Cash Flow Statement
A1: Company: Demo Holdings Limited (DEMO)
A2: Statement: Cash Flow Statement
A3: Units: HKD in Millions
A4: Source: manual ingestion (HK)
A6: Line Item | B6: 44561 | C6: 44926 | D6: 45291 | E6: 45657 | F6: 46022
A7: Profit for the year | B7: 2760 | C7: 2988 | D7: 3283 | E7: 3644 | F7: 4072
A8: Depreciation and amortisation | B8: 340 | C8: 368 | D8: 404 | E8: 448 | F8: 500
A9: Net cash from operating activities | B9: 1450 | C9: 1600 | D9: 1750 | E9: 1930 | F9: 2070
A10: Net cash used in investing activities | B10: -800 | C10: -850 | D10: -900 | E10: -950 | F10: -1000
A11: Net cash from financing activities | B11: -500 | C11: -600 | D11: -700 | E11: -800 | F11: -900
A12: Net change in cash and cash equivalents | B12: 150 | C12: 150 | D12: 150 | E12: 180 | F12: 170

Sheet Condensed Financials
A1: Demo Holdings Limited (DEMO) — Condensed Financials
A4: BALANCE SHEET CLASSIFICATION
A5: Line Item | B5: Classification | C5: 44561 | D5: 44926 | E5: 45291 | F5: 45657 | G5: 46022 | H5: Notes
A6: Cash and cash equivalents | B6: Financial Asset | C6: 1200 | D6: 1350 | E6: 1500 | F6: 1680 | G6: 1850
A7: Trade receivables | B7: Operating Working Capital Asset | C7: 850 | D7: 920 | E7: 1010 | F7: 1120 | G7: 1250
A8: Inventories | B8: Operating Working Capital Asset | C8: 680 | D8: 736 | E8: 808 | F8: 896 | G8: 1000
A9: Property, plant and equipment | B9: Operating Long-Term Asset | C9: 3200 | D9: 3400 | E9: 3600 | F9: 3800 | G9: 4000
A10: Goodwill | B10: Operating Long-Term Asset | C10: 900 | D10: 900 | E10: 900 | F10: 900 | G10: 900
A11: Other non-current assets | B11: Operating Long-Term Asset | C11: 1670 | D11: 1894 | E11: 2282 | F11: 2804 | G11: 3500
A12: Trade payables | B12: Operating Working Capital Liability | C12: 595 | D12: 644 | E12: 707 | F12: 784 | G12: 875
A13: Bank borrowings | B13: Financial Liability | C13: 1500 | D13: 1400 | E13: 1300 | F13: 1200 | G13: 1100
A14: Operating lease liabilities | B14: =IF('Accounting Judgment'!$F$5="","Operating Long-Term Liability",'Accounting Judgment'!$F$5) | C14: 300 | D14: 320 | E14: 340 | F14: 360 | G14: 380 | H14: ⚠ Review: Lease liability concept — operating vs financial judgment
A15: Other non-current liabilities | B15: Operating Long-Term Liability | C15: 1005 | D15: 1136 | E15: 1253 | F15: 1356 | G15: 1445
A16: Share capital and reserves | B16: Equity | C16: 5100 | D16: 5700 | E16: 6500 | F16: 7500 | G16: 8700
A18: CONDENSED INCOME STATEMENT | B18: 44561 | C18: 44926 | D18: 45291 | E18: 45657 | F18: 46022
A19: Revenue
A20: Net Income
A21: Pretax Income | B21: ='Income Statement'!B15 | C21: ='Income Statement'!C15 | D21: ='Income Statement'!D15 | E21: ='Income Statement'!E15 | F21: ='Income Statement'!F15
A22: Tax Expense | B22: ='Income Statement'!B16 | C22: ='Income Statement'!C16 | D22: ='Income Statement'!D16 | E22: ='Income Statement'!E16 | F22: ='Income Statement'!F16
A23: Interest Expense | B23: ='Income Statement'!B13 | C23: ='Income Statement'!C13 | D23: ='Income Statement'!D13 | E23: ='Income Statement'!E13 | F23: ='Income Statement'!F13
A24: Interest Income | B24: ='Income Statement'!B14 | C24: ='Income Statement'!C14 | D24: ='Income Statement'!D14 | E24: ='Income Statement'!E14 | F24: ='Income Statement'!F14
A25: Effective Tax Rate
A26: Net Interest
A27: Net Interest After Tax
A28: NOPAT
A30: CONDENSED BALANCE SHEET
A31: Operating Working Capital Assets
A32: Operating Working Capital Liabilities
A33: NOWC
A34: Operating Long-Term Assets
A35: Operating Long-Term Liabilities
A36: NOLA
A37: NOA
... A41: Equity (NOA - Net Debt)
A42: Reported Equity | B42: ='Balance Sheet'!B20 | C42: ='Balance Sheet'!C20 | D42: ='Balance Sheet'!D20 | E42: ='Balance Sheet'!E20 | F42: ='Balance Sheet'!F20
A43: Total Capital | B43: =B40+B41 | C43: =C40+C41 | D43: =D40+D41 | E43: =E40+E41 | F43: =F40+F41
A44: CHECK | B44: =IF(ABS(B41-B42)<1,"OK","CHECK") | C44: =IF(ABS(C41-C42)<1,"OK","CHECK") | D44: =IF(ABS(D41-D42)<1,"OK","CHECK") | E44: =IF(ABS(E41-E42)<1,"OK","CHECK") | F44: =IF(ABS(F41-F42)<1,"OK","CHECK")

Sheet ALT DuPont
A1: Demo Holdings Limited — DuPont Decomposition
A2: ROE = RNOA + FLEV × Spread
A4: Metric | B4: 44561 | C4: 44926 | D4: 45291 | E4: 45657 | F4: 46022
A5: Sales Growth | B5: N/A
A6: NOPAT Margin
A7: RNOA | B7: N/A
A8: After-tax CoD | B8: N/A
A9: Spread | B9: N/A
A10: FLEV | B10: N/A
A11: ROE (decomposed) | B11: N/A
A12: Actual ROE | B12: N/A
A14: RNOA DRIVER DECOMPOSITION
A15: Average NOA | B15: N/A
A16: NOA Turnover | B16: N/A
A17: NOA Intensity | B17: N/A
A18: RNOA from Margin × Turnover | B18: N/A
A19: RNOA DRIVER CHECK | B19: N/A | C19: =IF(ISNA(C18),"N/A",IF(ISNA(C7),"CHECK",IF(ABS(C18-C7)<0.0000001,"OK","CHECK"))) | D19: =IF(ISNA(D18),"N/A",IF(ISNA(D7),"CHECK",IF(ABS(D18-D7)<0.0000001,"OK","CHECK"))) | E19: =IF(ISNA(E18),"N/A",IF(ISNA(E7),"CHECK",IF(ABS(E18-E7)<0.0000001,"OK","CHECK"))) | F19: =IF(ISNA(F18),"N/A",IF(ISNA(F7),"CHECK",IF(ABS(F18-F7)<0.0000001,"OK","CHECK")))
A21: RNOA CHANGE ATTRIBUTION
A22: Change in NOPAT Margin | B22: N/A | C22: N/A
A23: Change in NOA Turnover | B23: N/A | C23: N/A
A24: Direct Change in RNOA | B24: N/A | C24: N/A
A25: Margin Effect on RNOA Change | B25: N/A | C25: N/A
A26: Turnover Effect on RNOA Change | B26: N/A | C26: N/A
A27: RNOA Change from Drivers | B27: N/A | C27: N/A
A28: RNOA CHANGE DRIVER CHECK | B28: N/A | C28: N/A | D28: =IF(OR(ISNA(D27),ISNA(D24)),"N/A",IF(ABS(D27-D24)<0.0000001,"OK","CHECK")) | E28: =IF(OR(ISNA(E27),ISNA(E24)),"N/A",IF(ABS(E27-E24)<0.0000001,"OK","CHECK")) | F28: =IF(OR(ISNA(F27),ISNA(F24)),"N/A",IF(ABS(F27-F24)<0.0000001,"OK","CHECK"))
A30: ROE OPERATING / FINANCING ATTRIBUTION
A31: Financing Contribution to ROE | B31: N/A
A32: ROE LEVEL ATTRIBUTION CHECK | B32: N/A | C32: =IF(OR(ISNA(C7),ISNA(C31),ISNA(C11)),"N/A",IF(ABS(C7+C31-C11)<0.0000001,"OK","CHECK")) | D32: =IF(OR(ISNA(D7),ISNA(D31),ISNA(D11)),"N/A",IF(ABS(D7+D31-D11)<0.0000001,"OK","CHECK")) | E32: =IF(OR(ISNA(E7),ISNA(E31),ISNA(E11)),"N/A",IF(ABS(E7+E31-E11)<0.0000001,"OK","CHECK")) | F32: =IF(OR(ISNA(F7),ISNA(F31),ISNA(F11)),"N/A",IF(ABS(F7+F31-F11)<0.0000001,"OK","CHECK"))
A34: ROE CHANGE ATTRIBUTION
A35: Direct Change in Decomposed ROE | B35: N/A | C35: N/A
A36: Operating Effect on Change in ROE | B36: N/A | C36: N/A
A37: Leverage Effect on Change in ROE | B37: N/A | C37: N/A
A38: Spread Effect on Change in ROE | B38: N/A | C38: N/A
A39: Financing Effect on Change in ROE | B39: N/A | C39: N/A
A40: Change in ROE from Drivers | B40: N/A | C40: N/A
A41: ROE CHANGE ATTRIBUTION CHECK | B41: N/A | C41: N/A | D41: =IF(OR(ISNA(D40),ISNA(D35)),"N/A",IF(ABS(D40-D35)<0.0000001,"OK","CHECK")) | E41: =IF(OR(ISNA(E40),ISNA(E35)),"N/A",IF(ABS(E40-E35)<0.0000001,"OK","CHECK")) | F41: =IF(OR(ISNA(F40),ISNA(F35)),"N/A",IF(ABS(F40-F35)<0.0000001,"OK","CHECK"))
A43: FIXED-ASSET INTENSITY CONTEXT
A44: Property, Plant & Equipment
A45: Depreciation & Amortisation
A46: Average PP&E | B46: N/A
...

Sheet Accounting Judgment
A1: Accounting Judgment
A2: The supplied treatment is the model's reference treatment, not a universal accounting truth. Compare it with the listed alternative(s), choose the treatment you would defend, and explain the economic consequence.
A3: Choose a treatment in column F only. That choice drives the matching Condensed Financials classification and downstream historical schedules; leaving F blank uses the supplied reference treatment. Columns D:E are display context and must not be edited. Enter your rationale and economic consequence in G:H. Formula Check grades formula cells against the treatment currently selected in F and validates that the generated classification links remain intact; it does not grade the judgment response itself. Do not edit the linked Condensed Financials classification cell directly.
A4: Order | B4: Line item | C4: Topic | D4: Supplied reference treatment | E4: Alternative(s) to evaluate | F4: Treatment to defend | G4: Rationale | H4: Economic consequence
A5: 1 | B5: Operating lease liabilities | C5: Lease liability operating vs financing | D5: Operating Long-Term Liability | E5: Financial Liability

Sheet Normalization Judgment
A1: Normalization Judgment
A2: The supplied treatment is the model's reference convention, not a universal truth. Decide whether each supplied candidate should remain in recurring earnings or be normalized out.
A3: Choose the treatment in column F. Blank F uses the supplied reference treatment. G:H are ungraded reasoning. Do not edit the generated Earnings Normalization treatment link directly.
A4: Order | B4: Line item | C4: Scope | D4: Supplied reference treatment | E4: Alternative to evaluate | F4: Treatment to defend | G4: Rationale | H4: Economic consequence
A5: 1 | B5: Restructuring expense | C5: operating_pretax_effective_tax | D5: Non-recurring | E5: Recurring

Sheet Earnings Normalization
A1: Earnings Normalization
A2: Reported statements stay unchanged. Bridge reported NOPAT / Net Income to normalized earnings using the treatments chosen on Normalization Judgment.
A4: Line item | B4: Treatment | C4: 44561 | D4: 44926 | E4: 45291 | F4: 45657 | G4: 46022
A5: Restructuring expense | B5: =IF('Normalization Judgment'!$F$5="","Non-recurring",'Normalization Judgment'!$F$5) | C5: ='Income Statement'!B11 | D5: ='Income Statement'!C11 | E5: ='Income Statement'!D11 | F5: ='Income Statement'!E11 | G5: ='Income Statement'!F11
A7: Reported NOPAT | C7: ='Condensed Financials'!B28 | D7: ='Condensed Financials'!C28 | E7: ='Condensed Financials'!D28 | F7: ='Condensed Financials'!E28 | G7: ='Condensed Financials'!F28
A8: Reported Net Income | C8: ='Condensed Financials'!B20 | D8: ='Condensed Financials'!C20 | E8: ='Condensed Financials'!D20 | F8: ='Condensed Financials'!E20 | G8: ='Condensed Financials'!F20
A9: Pretax Normalization Adjustment
A10: Effective Tax Rate | C10: ='Condensed Financials'!B25 | D10: ='Condensed Financials'!C25 | E10: ='Condensed Financials'!D25 | F10: ='Condensed Financials'!E25 | G10: ='Condensed Financials'!F25
A11: After-tax Normalization Adjustment
A12: Normalized NOPAT
A13: Normalized Net Income
A14: NORMALIZATION CHECK | C14: =IF(AND(ABS((C12-C7)-C11)<0.01,ABS((C13-C8)-C11)<0.01),"OK","CHECK") | D14: =IF(AND(ABS((D12-D7)-D11)<0.01,ABS((D13-D8)-D11)<0.01),"OK","CHECK") | E14: =IF(AND(ABS((E12-E7)-E11)<0.01,ABS((E13-E8)-E11)<0.01),"OK","CHECK") | F14: =IF(AND(ABS((F12-F7)-F11)<0.01,ABS((F13-F8)-F11)<0.01),"OK","CHECK") | G14: =IF(AND(ABS((G12-G7)-G11)<0.01,ABS((G13-G8)-G11)<0.01),"OK","CHECK")

Sheet Earnings Quality
A1: Demo Holdings Limited — Earnings Quality
A2: Historical cash-conversion and accrual diagnostics. These are mechanical diagnostics, not an automatic quality score.
A4: Metric | B4: 44561 | C4: 44926 | D4: 45291 | E4: 45657 | F4: 46022
A5: Operating Cash Flow
A6: Reported Net Income | B6: ='Condensed Financials'!B20 | C6: ='Condensed Financials'!C20 | D6: ='Condensed Financials'!D20 | E6: ='Condensed Financials'!E20 | F6: ='Condensed Financials'!F20
A7: Cash Conversion Ratio
A8: Total Accruals (Net Income - CFO)
A10: Total Assets | B10: ='Balance Sheet'!B13 | C10: ='Balance Sheet'!C13 | D10: ='Balance Sheet'!D13 | E10: ='Balance Sheet'!E13 | F10: ='Balance Sheet'!F13
A11: Average Total Assets
A12: Accrual Ratio
A14: EARNINGS QUALITY TREND DIAGNOSTICS
A15: Change in Operating Cash Flow | B15: N/A
A16: Change in Cash Conversion Ratio | B16: N/A
A17: Change in Total Accruals | B17: N/A
A18: Change in Accrual Ratio | B18: N/A | C18: N/A
A19: EARNINGS QUALITY CHANGE CHECK | B19: N/A | C19: =IF(ABS(C17-((C6-B6)-C15))<0.01,"OK","CHECK") | D19: =IF(ABS(D17-((D6-C6)-D15))<0.01,"OK","CHECK") | E19: =IF(ABS(E17-((E6-D6)-E15))<0.01,"OK","CHECK") | F19: =IF(ABS(F17-((F6-E6)-F15))<0.01,"OK","CHECK")

Sheet Working Capital Analysis
A1: Working Capital Analysis
A2: Relate classified operating working capital to Revenue and identify how much incremental NOWC accompanies changes in sales.
A3: These are diagnostics, not automatic judgments. Positive Change in NOWC is an operating cash use; negative Change in NOWC is a release. Annual data alone does not prove seasonality or deterioration.
A5: Metric | B5: 44561 | C5: 44926 | D5: 45291 | E5: 45657 | F5: 46022
A6: Revenue | B6: ='Condensed Financials'!B19 | C6: ='Condensed Financials'!C19 | D6: ='Condensed Financials'!D19 | E6: ='Condensed Financials'!E19 | F6: ='Condensed Financials'!F19
A7: Operating Working Capital Assets | B7: ='Condensed Financials'!B31 | C7: ='Condensed Financials'!C31 | D7: ='Condensed Financials'!D31 | E7: ='Condensed Financials'!E31 | F7: ='Condensed Financials'!F31
A8: Operating Working Capital Liabilities | B8: ='Condensed Financials'!B32 | C8: ='Condensed Financials'!C32 | D8: ='Condensed Financials'!D32 | E8: ='Condensed Financials'!E32 | F8: ='Condensed Financials'!F32
A9: NOWC | B9: ='Condensed Financials'!B33 | C9: ='Condensed Financials'!C33 | D9: ='Condensed Financials'!D33 | E9: ='Condensed Financials'!E33 | F9: ='Condensed Financials'!F33
A11: OWCA / Revenue
A12: OWCL / Revenue
A13: NOWC / Revenue
A14: Change in Revenue | B14: N/A
A15: Change in NOWC | B15: N/A
A16: Incremental NOWC / Change in Revenue | B16: N/A
A18: WORKING-CAPITAL DRIVER DECOMPOSITION
A19: Change in OWCA | B19: N/A
A20: Change in OWCL | B20: N/A
A21: Change in NOWC from Components | B21: N/A
A22: Incremental OWCA / Change in Revenue | B22: N/A
A23: Incremental OWCL / Change in Revenue | B23: N/A
A24: DRIVER DECOMPOSITION CHECK | B24: N/A | C24: =IF(ABS(C21-C15)<0.01,"OK","CHECK") | D24: =IF(ABS(D21-D15)<0.01,"OK","CHECK") | E24: =IF(ABS(E21-E15)<0.01,"OK","CHECK") | F24: =IF(ABS(F21-F15)<0.01,"OK","CHECK")

Sheet Model_Bear
A1: Deferred from historical-only v1

Sheet Model_Base
A1: Deferred from historical-only v1

Sheet Model_Bull
A1: Deferred from historical-only v1

Sheet Scenario_Summary
A1: Deferred from historical-only v1
