Workbook

Sheet Trainer
A1: BAV Excel Trainer
A2: Complete each historical formula schedule left-to-right in dependency order. Run Check to validate the yellow formula cells against the treatment currently selected in Accounting Judgment column F (blank F uses the supplied reference treatment). Generated Condensed Financials classification links are system-controlled and validated by Check—do not edit them or columns D:E. When Normalization Judgment is present, choose Recurring vs Non-recurring in column F (blank uses the supplied reference); Earnings Normalization formulas are checked against that choice. Also complete Accounting Judgment and Normalization Judgment rationale/consequence when cases are present; those responses are not graded by Check. Compare them with the matching Answer Key.
A4: Order | B4: Schedule | C4: Period scope | D4: Tab | E4: Practice cells | F4: Depends on
A5: 1 | B5: Revenue historical source link | C5: 2021–2025 (5 cells) | D5: Condensed Financials | E5: B19:F19 | F5: —
A6: 2 | B6: Net Income historical source link | C6: 2021–2025 (5 cells) | D6: Condensed Financials | E6: B20:F20 | F6: —
A7: 3 | B7: Effective tax rate | C7: 2021–2025 (5 cells) | D7: Condensed Financials | E7: B25:F25 | F7: —
A8: 4 | B8: Net interest | C8: 2021–2025 (5 cells) | D8: Condensed Financials | E8: B26:F26 | F8: —
A9: 5 | B9: Net interest after tax | C9: 2021–2025 (5 cells) | D9: Condensed Financials | E9: B27:F27 | F9: effective_tax_rate_fy, net_interest_fy
A10: 6 | B10: NOPAT | C10: 2021–2025 (5 cells) | D10: Condensed Financials | E10: B28:F28 | F10: net_income_link, net_interest_after_tax_fy
A11: 7 | B11: Operating working capital assets | C11: 2021–2025 (5 cells) | D11: Condensed Financials | E11: B31:F31 | F11: —
A12: 8 | B12: Operating working capital liabilities | C12: 2021–2025 (5 cells) | D12: Condensed Financials | E12: B32:F32 | F12: —
A13: 9 | B13: Net Operating Working Capital (NOWC) | C13: 2021–2025 (5 cells) | D13: Condensed Financials | E13: B33:F33 | F13: owca_agg, owcl_agg
A14: 10 | B14: Operating long-term assets | C14: 2021–2025 (5 cells) | D14: Condensed Financials | E14: B34:F34 | F14: —
A15: 11 | B15: Operating long-term liabilities | C15: 2021–2025 (5 cells) | D15: Condensed Financials | E15: B35:F35 | F15: —
A16: 12 | B16: Net operating long-term assets (NOLA) | C16: 2021–2025 (5 cells) | D16: Condensed Financials | E16: B36:F36 | F16: olta_agg, oltl_agg
... A33: 29 | B33: Normalized Net Income | C33: 2021–2025 (5 cells) | D33: Earnings Normalization | E33: C13:G13 | F33: after_tax_normalization_adjustment

Sheet Income Statement
A1: Company: Demo Holdings Limited (DEMO)
A2: Statement: Income Statement
A3: Units: HKD in Millions
A4: Source: manual ingestion (HK)
A6: Line Item | B6: 44561 | C6: 44926 | D6: 45291 | E6: 45657 | F6: 46022
A7: Revenue | B7: 8500 | C7: 9200 | D7: 10100 | E7: 11200 | F7: 12500
A8: Cost of sales | B8: -3400 | C8: -3680 | D8: -4040 | E8: -4480 | F8: -5000
A9: Gross profit | B9: 5100 | C9: 5520 | D9: 6060 | E9: 6720 | F9: 7500
A10: Administrative expenses | B10: -1700 | C10: -1840 | D10: -1820 | E10: -2240 | F10: -2500
A11: Restructuring expense | B11: 0 | C11: 0 | D11: -200 | E11: 0 | F11: 0
A12: Operating profit | B12: 3400 | C12: 3680 | D12: 4040 | E12: 4480 | F12: 5000
A13: Finance costs | B13: -120 | C13: -130 | D13: -140 | E13: -150 | F13: -160
A14: Finance income | B14: 45 | C14: 50 | D14: 55 | E14: 60 | F14: 65
A15: Profit before tax | B15: 3325 | C15: 3600 | D15: 3955 | E15: 4390 | F15: 4905
A16: Income tax expense | B16: -565 | C16: -612 | D16: -672 | E16: -746 | F16: -833
A17: Profit for the year | B17: 2760 | C17: 2988 | D17: 3283 | E17: 3644 | F17: 4072

Sheet Balance Sheet
A1: Company: Demo Holdings Limited (DEMO)
A2: Statement: Balance Sheet
A3: Units: HKD in Millions
A4: Source: manual ingestion (HK)
A6: Line Item | B6: 44561 | C6: 44926 | D6: 45291 | E6: 45657 | F6: 46022
A7: Cash and cash equivalents | B7: 1200 | C7: 1350 | D7: 1500 | E7: 1680 | F7: 1850
A8: Trade receivables | B8: 850 | C8: 920 | D8: 1010 | E8: 1120 | F8: 1250
A9: Inventories | B9: 680 | C9: 736 | D9: 808 | E9: 896 | F9: 1000
A10: Property, plant and equipment | B10: 3200 | C10: 3400 | D10: 3600 | E10: 3800 | F10: 4000
A11: Goodwill | B11: 900 | C11: 900 | D11: 900 | E11: 900 | F11: 900
A12: Other non-current assets | B12: 1670 | C12: 1894 | D12: 2282 | E12: 2804 | F12: 3500
A13: Total assets | B13: 8500 | C13: 9200 | D13: 10100 | E13: 11200 | F13: 12500
A14: Trade payables | B14: 595 | C14: 644 | D14: 707 | E14: 784 | F14: 875
A15: Bank borrowings | B15: 1500 | C15: 1400 | D15: 1300 | E15: 1200 | F15: 1100
A16: Operating lease liabilities | B16: 300 | C16: 320 | D16: 340 | E16: 360 | F16: 380
A17: Other non-current liabilities | B17: 1005 | C17: 1136 | D17: 1253 | E17: 1356 | F17: 1445
... A20: Total equity | B20: 5100 | C20: 5700 | D20: 6500 | E20: 7500 | F20: 8700

Sheet Cash Flow Statement
A1: Company: Demo Holdings Limited (DEMO)
A2: Statement: Cash Flow Statement
A3: Units: HKD in Millions
A4: Source: manual ingestion (HK)
A6: Line Item | B6: 44561 | C6: 44926 | D6: 45291 | E6: 45657 | F6: 46022
A7: Profit for the year | B7: 2760 | C7: 2988 | D7: 3283 | E7: 3644 | F7: 4072
A8: Depreciation and amortisation | B8: 340 | C8: 368 | D8: 404 | E8: 448 | F8: 500
A9: Net cash from operating activities | B9: 1450 | C9: 1600 | D9: 1750 | E9: 1930 | F9: 2070
A10: Net cash used in investing activities | B10: -800 | C10: -850 | D10: -900 | E10: -950 | F10: -1000
A11: Net cash from financing activities | B11: -500 | C11: -600 | D11: -700 | E11: -800 | F11: -900
A12: Net change in cash and cash equivalents | B12: 150 | C12: 150 | D12: 150 | E12: 180 | F12: 170

Sheet Condensed Financials
A1: Demo Holdings Limited (DEMO) — Condensed Financials
A4: BALANCE SHEET CLASSIFICATION
A5: Line Item | B5: Classification | C5: 44561 | D5: 44926 | E5: 45291 | F5: 45657 | G5: 46022 | H5: Notes
A6: Cash and cash equivalents | B6: Financial Asset | C6: 1200 | D6: 1350 | E6: 1500 | F6: 1680 | G6: 1850
A7: Trade receivables | B7: Operating Working Capital Asset | C7: 850 | D7: 920 | E7: 1010 | F7: 1120 | G7: 1250
A8: Inventories | B8: Operating Working Capital Asset | C8: 680 | D8: 736 | E8: 808 | F8: 896 | G8: 1000
A9: Property, plant and equipment | B9: Operating Long-Term Asset | C9: 3200 | D9: 3400 | E9: 3600 | F9: 3800 | G9: 4000
A10: Goodwill | B10: Operating Long-Term Asset | C10: 900 | D10: 900 | E10: 900 | F10: 900 | G10: 900
A11: Other non-current assets | B11: Operating Long-Term Asset | C11: 1670 | D11: 1894 | E11: 2282 | F11: 2804 | G11: 3500
A12: Trade payables | B12: Operating Working Capital Liability | C12: 595 | D12: 644 | E12: 707 | F12: 784 | G12: 875
A13: Bank borrowings | B13: Financial Liability | C13: 1500 | D13: 1400 | E13: 1300 | F13: 1200 | G13: 1100
A14: Operating lease liabilities | B14: =IF('Accounting Judgment'!$F$5="","Operating Long-Term Liability",'Accounting Judgment'!$F$5) | C14: 300 | D14: 320 | E14: 340 | F14: 360 | G14: 380 | H14: ⚠ Review: Lease liability concept — operating vs financial judgment
A15: Other non-current liabilities | B15: Operating Long-Term Liability | C15: 1005 | D15: 1136 | E15: 1253 | F15: 1356 | G15: 1445
A16: Share capital and reserves | B16: Equity | C16: 5100 | D16: 5700 | E16: 6500 | F16: 7500 | G16: 8700
A18: CONDENSED INCOME STATEMENT | B18: 44561 | C18: 44926 | D18: 45291 | E18: 45657 | F18: 46022
A19: Revenue | B19: ='Income Statement'!B7 | C19: ='Income Statement'!C7 | D19: ='Income Statement'!D7 | E19: ='Income Statement'!E7 | F19: ='Income Statement'!F7
A20: Net Income | B20: ='Income Statement'!B17 | C20: ='Income Statement'!C17 | D20: ='Income Statement'!D17 | E20: ='Income Statement'!E17 | F20: ='Income Statement'!F17
A21: Pretax Income | B21: ='Income Statement'!B15 | C21: ='Income Statement'!C15 | D21: ='Income Statement'!D15 | E21: ='Income Statement'!E15 | F21: ='Income Statement'!F15
A22: Tax Expense | B22: ='Income Statement'!B16 | C22: ='Income Statement'!C16 | D22: ='Income Statement'!D16 | E22: ='Income Statement'!E16 | F22: ='Income Statement'!F16
A23: Interest Expense | B23: ='Income Statement'!B13 | C23: ='Income Statement'!C13 | D23: ='Income Statement'!D13 | E23: ='Income Statement'!E13 | F23: ='Income Statement'!F13
A24: Interest Income | B24: ='Income Statement'!B14 | C24: ='Income Statement'!C14 | D24: ='Income Statement'!D14 | E24: ='Income Statement'!E14 | F24: ='Income Statement'!F14
A25: Effective Tax Rate | B25: =IF(B21=0,0,-B22/B21) | C25: =IF(C21=0,0,-C22/C21) | D25: =IF(D21=0,0,-D22/D21) | E25: =IF(E21=0,0,-E22/E21) | F25: =IF(F21=0,0,-F22/F21)
A26: Net Interest | B26: =-(B23+B24) | C26: =-(C23+C24) | D26: =-(D23+D24) | E26: =-(E23+E24) | F26: =-(F23+F24)
A27: Net Interest After Tax | B27: =B26*(1-B25) | C27: =C26*(1-C25) | D27: =D26*(1-D25) | E27: =E26*(1-E25) | F27: =F26*(1-F25)
A28: NOPAT | B28: =B20+B27 | C28: =C20+C27 | D28: =D20+D27 | E28: =E20+E27 | F28: =F20+F27
A30: CONDENSED BALANCE SHEET
A31: Operating Working Capital Assets | B31: =SUMIF($B$6:$B$16,"Operating Working Capital Asset",C$6:C$16) | C31: =SUMIF($B$6:$B$16,"Operating Working Capital Asset",D$6:D$16) | D31: =SUMIF($B$6:$B$16,"Operating Working Capital Asset",E$6:E$16) | E31: =SUMIF($B$6:$B$16,"Operating Working Capital Asset",F$6:F$16) | F31: =SUMIF($B$6:$B$16,"Operating Working Capital Asset",G$6:G$16)
A32: Operating Working Capital Liabilities | B32: =SUMIF($B$6:$B$16,"Operating Working Capital Liability",C$6:C$16) | C32: =SUMIF($B$6:$B$16,"Operating Working Capital Liability",D$6:D$16) | D32: =SUMIF($B$6:$B$16,"Operating Working Capital Liability",E$6:E$16) | E32: =SUMIF($B$6:$B$16,"Operating Working Capital Liability",F$6:F$16) | F32: =SUMIF($B$6:$B$16,"Operating Working Capital Liability",G$6:G$16)
A33: NOWC | B33: =B31-B32 | C33: =C31-C32 | D33: =D31-D32 | E33: =E31-E32 | F33: =F31-F32
A34: Operating Long-Term Assets | B34: =SUMIF($B$6:$B$16,"Operating Long-Term Asset",C$6:C$16) | C34: =SUMIF($B$6:$B$16,"Operating Long-Term Asset",D$6:D$16) | D34: =SUMIF($B$6:$B$16,"Operating Long-Term Asset",E$6:E$16) | E34: =SUMIF($B$6:$B$16,"Operating Long-Term Asset",F$6:F$16) | F34: =SUMIF($B$6:$B$16,"Operating Long-Term Asset",G$6:G$16)
A35: Operating Long-Term Liabilities | B35: =SUMIF($B$6:$B$16,"Operating Long-Term Liability",C$6:C$16) | C35: =SUMIF($B$6:$B$16,"Operating Long-Term Liability",D$6:D$16) | D35: =SUMIF($B$6:$B$16,"Operating Long-Term Liability",E$6:E$16) | E35: =SUMIF($B$6:$B$16,"Operating Long-Term Liability",F$6:F$16) | F35: =SUMIF($B$6:$B$16,"Operating Long-Term Liability",G$6:G$16)
A36: NOLA | B36: =B34-B35 | C36: =C34-C35 | D36: =D34-D35 | E36: =E34-E35 | F36: =F34-F35
A37: NOA | B37: =B33+B36 | C37: =C33+C36 | D37: =D33+D36 | E37: =E33+E36 | F37: =F33+F36
A38: Financial Assets | B38: =SUMIF($B$6:$B$16,"Financial Asset",C$6:C$16) | C38: =SUMIF($B$6:$B$16,"Financial Asset",D$6:D$16) | D38: =SUMIF($B$6:$B$16,"Financial Asset",E$6:E$16) | E38: =SUMIF($B$6:$B$16,"Financial Asset",F$6:F$16) | F38: =SUMIF($B$6:$B$16,"Financial Asset",G$6:G$16)
A39: Financial Liabilities | B39: =SUMIF($B$6:$B$16,"Financial Liability",C$6:C$16) | C39: =SUMIF($B$6:$B$16,"Financial Liability",D$6:D$16) | D39: =SUMIF($B$6:$B$16,"Financial Liability",E$6:E$16) | E39: =SUMIF($B$6:$B$16,"Financial Liability",F$6:F$16) | F39: =SUMIF($B$6:$B$16,"Financial Liability",G$6:G$16)
A40: Net Debt | B40: =B39-B38 | C40: =C39-C38 | D40: =D39-D38 | E40: =E39-E38 | F40: =F39-F38
A41: Equity (NOA - Net Debt) | B41: =B37-B40 | C41: =C37-C40 | D41: =D37-D40 | E41: =E37-E40 | F41: =F37-F40
A42: Reported Equity | B42: ='Balance Sheet'!B20 | C42: ='Balance Sheet'!C20 | D42: ='Balance Sheet'!D20 | E42: ='Balance Sheet'!E20 | F42: ='Balance Sheet'!F20
A43: Total Capital | B43: =B40+B41 | C43: =C40+C41 | D43: =D40+D41 | E43: =E40+E41 | F43: =F40+F41
A44: CHECK | B44: =IF(ABS(B41-B42)<1,"OK","CHECK") | C44: =IF(ABS(C41-C42)<1,"OK","CHECK") | D44: =IF(ABS(D41-D42)<1,"OK","CHECK") | E44: =IF(ABS(E41-E42)<1,"OK","CHECK") | F44: =IF(ABS(F41-F42)<1,"OK","CHECK")

Sheet ALT DuPont
A1: Demo Holdings Limited — DuPont Decomposition
A2: ROE = RNOA + FLEV × Spread
A4: Metric | B4: 44561 | C4: 44926 | D4: 45291 | E4: 45657 | F4: 46022
A5: Sales Growth | B5: N/A | C5: =IF('Condensed Financials'!B19=0,0,'Condensed Financials'!C19/'Condensed Financials'!B19-1) | D5: =IF('Condensed Financials'!C19=0,0,'Condensed Financials'!D19/'Condensed Financials'!C19-1) | E5: =IF('Condensed Financials'!D19=0,0,'Condensed Financials'!E19/'Condensed Financials'!D19-1) | F5: =IF('Condensed Financials'!E19=0,0,'Condensed Financials'!F19/'Condensed Financials'!E19-1)
A6: NOPAT Margin | B6: =IF('Condensed Financials'!B19=0,0,'Condensed Financials'!B28/'Condensed Financials'!B19) | C6: =IF('Condensed Financials'!C19=0,0,'Condensed Financials'!C28/'Condensed Financials'!C19) | D6: =IF('Condensed Financials'!D19=0,0,'Condensed Financials'!D28/'Condensed Financials'!D19) | E6: =IF('Condensed Financials'!E19=0,0,'Condensed Financials'!E28/'Condensed Financials'!E19) | F6: =IF('Condensed Financials'!F19=0,0,'Condensed Financials'!F28/'Condensed Financials'!F19)
A7: RNOA | B7: N/A | C7: =IF((('Condensed Financials'!C37+'Condensed Financials'!B37)/2)=0,0,'Condensed Financials'!C28/(('Condensed Financials'!C37+'Condensed Financials'!B37)/2)) | D7: =IF((('Condensed Financials'!D37+'Condensed Financials'!C37)/2)=0,0,'Condensed Financials'!D28/(('Condensed Financials'!D37+'Condensed Financials'!C37)/2)) | E7: =IF((('Condensed Financials'!E37+'Condensed Financials'!D37)/2)=0,0,'Condensed Financials'!E28/(('Condensed Financials'!E37+'Condensed Financials'!D37)/2)) | F7: =IF((('Condensed Financials'!F37+'Condensed Financials'!E37)/2)=0,0,'Condensed Financials'!F28/(('Condensed Financials'!F37+'Condensed Financials'!E37)/2))
A8: After-tax CoD | B8: N/A | C8: =IF((('Condensed Financials'!C40+'Condensed Financials'!B40)/2)=0,0,'Condensed Financials'!C27/(('Condensed Financials'!C40+'Condensed Financials'!B40)/2)) | D8: =IF((('Condensed Financials'!D40+'Condensed Financials'!C40)/2)=0,0,'Condensed Financials'!D27/(('Condensed Financials'!D40+'Condensed Financials'!C40)/2)) | E8: =IF((('Condensed Financials'!E40+'Condensed Financials'!D40)/2)=0,0,'Condensed Financials'!E27/(('Condensed Financials'!E40+'Condensed Financials'!D40)/2)) | F8: =IF((('Condensed Financials'!F40+'Condensed Financials'!E40)/2)=0,0,'Condensed Financials'!F27/(('Condensed Financials'!F40+'Condensed Financials'!E40)/2))
A9: Spread | B9: N/A | C9: =C7-C8 | D9: =D7-D8 | E9: =E7-E8 | F9: =F7-F8
A10: FLEV | B10: N/A | C10: =IF((('Condensed Financials'!C41+'Condensed Financials'!B41)/2)=0,0,(('Condensed Financials'!C40+'Condensed Financials'!B40)/2)/(('Condensed Financials'!C41+'Condensed Financials'!B41)/2)) | D10: =IF((('Condensed Financials'!D41+'Condensed Financials'!C41)/2)=0,0,(('Condensed Financials'!D40+'Condensed Financials'!C40)/2)/(('Condensed Financials'!D41+'Condensed Financials'!C41)/2)) | E10: =IF((('Condensed Financials'!E41+'Condensed Financials'!D41)/2)=0,0,(('Condensed Financials'!E40+'Condensed Financials'!D40)/2)/(('Condensed Financials'!E41+'Condensed Financials'!D41)/2)) | F10: =IF((('Condensed Financials'!F41+'Condensed Financials'!E41)/2)=0,0,(('Condensed Financials'!F40+'Condensed Financials'!E40)/2)/(('Condensed Financials'!F41+'Condensed Financials'!E41)/2))
A11: ROE (decomposed) | B11: N/A | C11: =C7+C10*(C9) | D11: =D7+D10*(D9) | E11: =E7+E10*(E9) | F11: =F7+F10*(F9)
A12: Actual ROE | B12: N/A | C12: =IF((('Condensed Financials'!C41+'Condensed Financials'!B41)/2)=0,0,'Condensed Financials'!C20/(('Condensed Financials'!C41+'Condensed Financials'!B41)/2)) | D12: =IF((('Condensed Financials'!D41+'Condensed Financials'!C41)/2)=0,0,'Condensed Financials'!D20/(('Condensed Financials'!D41+'Condensed Financials'!C41)/2)) | E12: =IF((('Condensed Financials'!E41+'Condensed Financials'!D41)/2)=0,0,'Condensed Financials'!E20/(('Condensed Financials'!E41+'Condensed Financials'!D41)/2)) | F12: =IF((('Condensed Financials'!F41+'Condensed Financials'!E41)/2)=0,0,'Condensed Financials'!F20/(('Condensed Financials'!F41+'Condensed Financials'!E41)/2))

Sheet Accounting Judgment
A1: Accounting Judgment
A2: The supplied treatment is the model's reference treatment, not a universal accounting truth. Compare it with the listed alternative(s), choose the treatment you would defend, and explain the economic consequence.
A3: Choose a treatment in column F only. That choice drives the matching Condensed Financials classification and downstream historical schedules; leaving F blank uses the supplied reference treatment. Columns D:E are display context and must not be edited. Enter your rationale and economic consequence in G:H. Formula Check grades formula cells against the treatment currently selected in F and validates that the generated classification links remain intact; it does not grade the judgment response itself. Do not edit the linked Condensed Financials classification cell directly.
A4: Order | B4: Line item | C4: Topic | D4: Supplied reference treatment | E4: Alternative(s) to evaluate | F4: Treatment to defend | G4: Rationale | H4: Economic consequence
A5: 1 | B5: Operating lease liabilities | C5: Lease liability operating vs financing | D5: Operating Long-Term Liability | E5: Financial Liability | F5: Operating Long-Term Liability | G5: The reference model keeps the liability in operating long-term liabilities under its current lease convention. Treating it as a financial liability is also defensible when the lease obligation is viewed as debt-like financing. | H5: Operating-liability treatment lowers NOLA/NOA; financial-liability treatment raises Net Debt by the same balance. Implied equity is unchanged from this classification switch alone, but RNOA versus FLEV/Spread interpretation changes.

Sheet Normalization Judgment
A1: Normalization Judgment
A2: The supplied treatment is the model's reference convention, not a universal truth. Decide whether each supplied candidate should remain in recurring earnings or be normalized out.
A3: Choose the treatment in column F. Blank F uses the supplied reference treatment. G:H are ungraded reasoning. Do not edit the generated Earnings Normalization treatment link directly.
A4: Order | B4: Line item | C4: Scope | D4: Supplied reference treatment | E4: Alternative to evaluate | F4: Treatment to defend | G4: Rationale | H4: Economic consequence
A5: 1 | B5: Restructuring expense | C5: operating_pretax_effective_tax | D5: Non-recurring | E5: Recurring | F5: Non-recurring | G5: The reference model treats the supplied restructuring charge as non-recurring because the illustrative case identifies it as a discrete restructuring event rather than normal ongoing operations. | H5: Non-recurring treatment removes the signed after-tax effect from normalized earnings; recurring treatment leaves reported earnings unchanged.

Sheet Earnings Normalization
A1: Earnings Normalization
A2: Reported statements stay unchanged. Bridge reported NOPAT / Net Income to normalized earnings using the treatments chosen on Normalization Judgment.
A4: Line item | B4: Treatment | C4: 44561 | D4: 44926 | E4: 45291 | F4: 45657 | G4: 46022
A5: Restructuring expense | B5: =IF('Normalization Judgment'!$F$5="","Non-recurring",'Normalization Judgment'!$F$5) | C5: ='Income Statement'!B11 | D5: ='Income Statement'!C11 | E5: ='Income Statement'!D11 | F5: ='Income Statement'!E11 | G5: ='Income Statement'!F11
A7: Reported NOPAT | C7: ='Condensed Financials'!B28 | D7: ='Condensed Financials'!C28 | E7: ='Condensed Financials'!D28 | F7: ='Condensed Financials'!E28 | G7: ='Condensed Financials'!F28
A8: Reported Net Income | C8: ='Condensed Financials'!B20 | D8: ='Condensed Financials'!C20 | E8: ='Condensed Financials'!D20 | F8: ='Condensed Financials'!E20 | G8: ='Condensed Financials'!F20
A9: Pretax Normalization Adjustment | C9: =-SUMIF($B$5:$B$5,"Non-recurring",C$5:C$5) | D9: =-SUMIF($B$5:$B$5,"Non-recurring",D$5:D$5) | E9: =-SUMIF($B$5:$B$5,"Non-recurring",E$5:E$5) | F9: =-SUMIF($B$5:$B$5,"Non-recurring",F$5:F$5) | G9: =-SUMIF($B$5:$B$5,"Non-recurring",G$5:G$5)
A10: Effective Tax Rate | C10: ='Condensed Financials'!B25 | D10: ='Condensed Financials'!C25 | E10: ='Condensed Financials'!D25 | F10: ='Condensed Financials'!E25 | G10: ='Condensed Financials'!F25
A11: After-tax Normalization Adjustment | C11: =C9*(1-C10) | D11: =D9*(1-D10) | E11: =E9*(1-E10) | F11: =F9*(1-F10) | G11: =G9*(1-G10)
A12: Normalized NOPAT | C12: =C7+C11 | D12: =D7+D11 | E12: =E7+E11 | F12: =F7+F11 | G12: =G7+G11
A13: Normalized Net Income | C13: =C8+C11 | D13: =D8+D11 | E13: =E8+E11 | F13: =F8+F11 | G13: =G8+G11
A14: NORMALIZATION CHECK | C14: =IF(AND(ABS((C12-C7)-C11)<0.01,ABS((C13-C8)-C11)<0.01),"OK","CHECK") | D14: =IF(AND(ABS((D12-D7)-D11)<0.01,ABS((D13-D8)-D11)<0.01),"OK","CHECK") | E14: =IF(AND(ABS((E12-E7)-E11)<0.01,ABS((E13-E8)-E11)<0.01),"OK","CHECK") | F14: =IF(AND(ABS((F12-F7)-F11)<0.01,ABS((F13-F8)-F11)<0.01),"OK","CHECK") | G14: =IF(AND(ABS((G12-G7)-G11)<0.01,ABS((G13-G8)-G11)<0.01),"OK","CHECK")

Sheet Model_Bear
A1: Deferred from historical-only v1

Sheet Model_Base
A1: Deferred from historical-only v1

Sheet Model_Bull
A1: Deferred from historical-only v1

Sheet Scenario_Summary
A1: Deferred from historical-only v1

Sheet _ComponentMap
A1: id | B1: order | C1: title | D1: short_hint | E1: semantic_key | F1: category | G1: tab | H1: cell | I1: formula | J1: expected_value | K1: tolerance | L1: depends_on | M1: hints | N1: related_cells | O1: status | P1: family_id | Q1: family_order | R1: period_index | S1: period_end
A2: revenue_link__20211231 | B2: 1 | C2: Revenue historical source link | D2: Link Revenue from the Income Statement into Condensed Financials. | E2: condensed.revenue_link.2021-12-31 | F2: accounting | G2: Condensed Financials | H2: B19 | I2: ='Income Statement'!B7 | J2: 8500 | K2: 0.01 | M2: Pull the Revenue line from the Income Statement for the same fiscal period. | O2: pending | P2: revenue_link | Q2: 1 | R2: 0 | S2: 2021-12-31
A3: revenue_link__20221231 | B3: 2 | C3: Revenue historical source link | D3: Link Revenue from the Income Statement into Condensed Financials. | E3: condensed.revenue_link.2022-12-31 | F3: accounting | G3: Condensed Financials | H3: C19 | I3: ='Income Statement'!C7 | J3: 9200 | K3: 0.01 | M3: Pull the Revenue line from the Income Statement for the same fiscal period. | O3: pending | P3: revenue_link | Q3: 1 | R3: 1 | S3: 2022-12-31
A4: revenue_link__20231231 | B4: 3 | C4: Revenue historical source link | D4: Link Revenue from the Income Statement into Condensed Financials. | E4: condensed.revenue_link.2023-12-31 | F4: accounting | G4: Condensed Financials | H4: D19 | I4: ='Income Statement'!D7 | J4: 10100 | K4: 0.01 | M4: Pull the Revenue line from the Income Statement for the same fiscal period. | O4: pending | P4: revenue_link | Q4: 1 | R4: 2 | S4: 2023-12-31
A5: revenue_link__20241231 | B5: 4 | C5: Revenue historical source link | D5: Link Revenue from the Income Statement into Condensed Financials. | E5: condensed.revenue_link.2024-12-31 | F5: accounting | G5: Condensed Financials | H5: E19 | I5: ='Income Statement'!E7 | J5: 11200 | K5: 0.01 | M5: Pull the Revenue line from the Income Statement for the same fiscal period. | O5: pending | P5: revenue_link | Q5: 1 | R5: 3 | S5: 2024-12-31
A6: revenue_link__20251231 | B6: 5 | C6: Revenue historical source link | D6: Link Revenue from the Income Statement into Condensed Financials. | E6: condensed.revenue_link.2025-12-31 | F6: accounting | G6: Condensed Financials | H6: F19 | I6: ='Income Statement'!F7 | J6: 12500 | K6: 0.01 | M6: Pull the Revenue line from the Income Statement for the same fiscal period. | O6: pending | P6: revenue_link | Q6: 1 | R6: 4 | S6: 2025-12-31
A7: net_income_link__20211231 | B7: 6 | C7: Net Income historical source link | D7: Link Net Income from the Income Statement into Condensed Financials. | E7: condensed.net_income_link.2021-12-31 | F7: accounting | G7: Condensed Financials | H7: B20 | I7: ='Income Statement'!B17 | J7: 2760 | K7: 0.01 | M7: Pull Net Income from the Income Statement for the same fiscal period. | O7: pending | P7: net_income_link | Q7: 2 | R7: 0 | S7: 2021-12-31
A8: net_income_link__20221231 | B8: 7 | C8: Net Income historical source link | D8: Link Net Income from the Income Statement into Condensed Financials. | E8: condensed.net_income_link.2022-12-31 | F8: accounting | G8: Condensed Financials | H8: C20 | I8: ='Income Statement'!C17 | J8: 2988 | K8: 0.01 | M8: Pull Net Income from the Income Statement for the same fiscal period. | O8: pending | P8: net_income_link | Q8: 2 | R8: 1 | S8: 2022-12-31
A9: net_income_link__20231231 | B9: 8 | C9: Net Income historical source link | D9: Link Net Income from the Income Statement into Condensed Financials. | E9: condensed.net_income_link.2023-12-31 | F9: accounting | G9: Condensed Financials | H9: D20 | I9: ='Income Statement'!D17 | J9: 3283 | K9: 0.01 | M9: Pull Net Income from the Income Statement for the same fiscal period. | O9: pending | P9: net_income_link | Q9: 2 | R9: 2 | S9: 2023-12-31
A10: net_income_link__20241231 | B10: 9 | C10: Net Income historical source link | D10: Link Net Income from the Income Statement into Condensed Financials. | E10: condensed.net_income_link.2024-12-31 | F10: accounting | G10: Condensed Financials | H10: E20 | I10: ='Income Statement'!E17 | J10: 3644 | K10: 0.01 | M10: Pull Net Income from the Income Statement for the same fiscal period. | O10: pending | P10: net_income_link | Q10: 2 | R10: 3 | S10: 2024-12-31
A11: net_income_link__20251231 | B11: 10 | C11: Net Income historical source link | D11: Link Net Income from the Income Statement into Condensed Financials. | E11: condensed.net_income_link.2025-12-31 | F11: accounting | G11: Condensed Financials | H11: F20 | I11: ='Income Statement'!F17 | J11: 4072 | K11: 0.01 | M11: Pull Net Income from the Income Statement for the same fiscal period. | O11: pending | P11: net_income_link | Q11: 2 | R11: 4 | S11: 2025-12-31
A12: effective_tax_rate_fy__20211231 | B12: 11 | C12: Effective tax rate | D12: Relate tax expense to pretax income using the model's sign convention. | E12: condensed.effective_tax_rate.2021-12-31 | F12: accounting | G12: Condensed Financials | H12: B25 | I12: =IF(B21=0,0,-B22/B21) | J12: 0.16992481 | K12: 0.01 | M12: Effective tax rate uses pretax income in the denominator.|Preserve the model's sign convention for tax expense. | O12: pending | P12: effective_tax_rate_fy | Q12: 3 | R12: 0 | S12: 2021-12-31
A13: effective_tax_rate_fy__20221231 | B13: 12 | C13: Effective tax rate | D13: Relate tax expense to pretax income using the model's sign convention. | E13: condensed.effective_tax_rate.2022-12-31 | F13: accounting | G13: Condensed Financials | H13: C25 | I13: =IF(C21=0,0,-C22/C21) | J13: 0.17 | K13: 0.01 | M13: Effective tax rate uses pretax income in the denominator.|Preserve the model's sign convention for tax expense. | O13: pending | P13: effective_tax_rate_fy | Q13: 3 | R13: 1 | S13: 2022-12-31
A14: effective_tax_rate_fy__20231231 | B14: 13 | C14: Effective tax rate | D14: Relate tax expense to pretax income using the model's sign convention. | E14: condensed.effective_tax_rate.2023-12-31 | F14: accounting | G14: Condensed Financials | H14: D25 | I14: =IF(D21=0,0,-D22/D21) | J14: 0.1699115 | K14: 0.01 | M14: Effective tax rate uses pretax income in the denominator.|Preserve the model's sign convention for tax expense. | O14: pending | P14: effective_tax_rate_fy | Q14: 3 | R14: 2 | S14: 2023-12-31
A15: effective_tax_rate_fy__20241231 | B15: 14 | C15: Effective tax rate | D15: Relate tax expense to pretax income using the model's sign convention. | E15: condensed.effective_tax_rate.2024-12-31 | F15: accounting | G15: Condensed Financials | H15: E25 | I15: =IF(E21=0,0,-E22/E21) | J15: 0.16993166 | K15: 0.01 | M15: Effective tax rate uses pretax income in the denominator.|Preserve the model's sign convention for tax expense. | O15: pending | P15: effective_tax_rate_fy | Q15: 3 | R15: 3 | S15: 2024-12-31
A16: effective_tax_rate_fy__20251231 | B16: 15 | C16: Effective tax rate | D16: Relate tax expense to pretax income using the model's sign convention. | E16: condensed.effective_tax_rate.2025-12-31 | F16: accounting | G16: Condensed Financials | H16: F25 | I16: =IF(F21=0,0,-F22/F21) | J16: 0.16982671 | K16: 0.01 | M16: Effective tax rate uses pretax income in the denominator.|Preserve the model's sign convention for tax expense. | O16: pending | P16: effective_tax_rate_fy | Q16: 3 | R16: 4 | S16: 2025-12-31
A17: net_interest_fy__20211231 | B17: 16 | C17: Net interest | D17: Combine interest expense and interest income into the financing result. | E17: condensed.net_interest.2021-12-31 | F17: accounting | G17: Condensed Financials | H17: B26 | I17: =-(B23+B24) | J17: 75 | K17: 0.01 | M17: Net interest consolidates interest expense and interest income.|Missing optional interest lines are treated as zero. | O17: pending | P17: net_interest_fy | Q17: 4 | R17: 0 | S17: 2021-12-31
A18: net_interest_fy__20221231 | B18: 17 | C18: Net interest | D18: Combine interest expense and interest income into the financing result. | E18: condensed.net_interest.2022-12-31 | F18: accounting | G18: Condensed Financials | H18: C26 | I18: =-(C23+C24) | J18: 80 | K18: 0.01 | M18: Net interest consolidates interest expense and interest income.|Missing optional interest lines are treated as zero. | O18: pending | P18: net_interest_fy | Q18: 4 | R18: 1 | S18: 2022-12-31
A19: net_interest_fy__20231231 | B19: 18 | C19: Net interest | D19: Combine interest expense and interest income into the financing result. | E19: condensed.net_interest.2023-12-31 | F19: accounting | G19: Condensed Financials | H19: D26 | I19: =-(D23+D24) | J19: 85 | K19: 0.01 | M19: Net interest consolidates interest expense and interest income.|Missing optional interest lines are treated as zero. | O19: pending | P19: net_interest_fy | Q19: 4 | R19: 2 | S19: 2023-12-31
A20: net_interest_fy__20241231 | B20: 19 | C20: Net interest | D20: Combine interest expense and interest income into the financing result. | E20: condensed.net_interest.2024-12-31 | F20: accounting | G20: Condensed Financials | H20: E26 | I20: =-(E23+E24) | J20: 90 | K20: 0.01 | M20: Net interest consolidates interest expense and interest income.|Missing optional interest lines are treated as zero. | O20: pending | P20: net_interest_fy | Q20: 4 | R20: 3 | S20: 2024-12-31
A21: net_interest_fy__20251231 | B21: 20 | C21: Net interest | D21: Combine interest expense and interest income into the financing result. | E21: condensed.net_interest.2025-12-31 | F21: accounting | G21: Condensed Financials | H21: F26 | I21: =-(F23+F24) | J21: 95 | K21: 0.01 | M21: Net interest consolidates interest expense and interest income.|Missing optional interest lines are treated as zero. | O21: pending | P21: net_interest_fy | Q21: 4 | R21: 4 | S21: 2025-12-31
A22: net_interest_after_tax_fy__20211231 | B22: 21 | C22: Net interest after tax | D22: Apply the effective tax rate once to net interest. | E22: condensed.net_interest_after_tax.2021-12-31 | F22: accounting | G22: Condensed Financials | H22: B27 | I22: =B26*(1-B25) | J22: 62.255639 | K22: 0.01 | L22: effective_tax_rate_fy__20211231,net_interest_fy__20211231 | M22: After-tax net interest = Net Interest × (1 − Effective Tax Rate).|Do not tax-adjust a rate that is already after tax. | O22: pending | P22: net_interest_after_tax_fy | Q22: 5 | R22: 0 | S22: 2021-12-31
A23: net_interest_after_tax_fy__20221231 | B23: 22 | C23: Net interest after tax | D23: Apply the effective tax rate once to net interest. | E23: condensed.net_interest_after_tax.2022-12-31 | F23: accounting | G23: Condensed Financials | H23: C27 | I23: =C26*(1-C25) | J23: 66.4 | K23: 0.01 | L23: effective_tax_rate_fy__20221231,net_interest_fy__20221231 | M23: After-tax net interest = Net Interest × (1 − Effective Tax Rate).|Do not tax-adjust a rate that is already after tax. | O23: pending | P23: net_interest_after_tax_fy | Q23: 5 | R23: 1 | S23: 2022-12-31
A24: net_interest_after_tax_fy__20231231 | B24: 23 | C24: Net interest after tax | D24: Apply the effective tax rate once to net interest. | E24: condensed.net_interest_after_tax.2023-12-31 | F24: accounting | G24: Condensed Financials | H24: D27 | I24: =D26*(1-D25) | J24: 70.557522 | K24: 0.01 | L24: effective_tax_rate_fy__20231231,net_interest_fy__20231231 | M24: After-tax net interest = Net Interest × (1 − Effective Tax Rate).|Do not tax-adjust a rate that is already after tax. | O24: pending | P24: net_interest_after_tax_fy | Q24: 5 | R24: 2 | S24: 2023-12-31
A25: net_interest_after_tax_fy__20241231 | B25: 24 | C25: Net interest after tax | D25: Apply the effective tax rate once to net interest. | E25: condensed.net_interest_after_tax.2024-12-31 | F25: accounting | G25: Condensed Financials | H25: E27 | I25: =E26*(1-E25) | J25: 74.70615 | K25: 0.01 | L25: effective_tax_rate_fy__20241231,net_interest_fy__20241231 | M25: After-tax net interest = Net Interest × (1 − Effective Tax Rate).|Do not tax-adjust a rate that is already after tax. | O25: pending | P25: net_interest_after_tax_fy | Q25: 5 | R25: 3 | S25: 2024-12-31
A26: net_interest_after_tax_fy__20251231 | B26: 25 | C26: Net interest after tax | D26: Apply the effective tax rate once to net interest. | E26: condensed.net_interest_after_tax.2025-12-31 | F26: accounting | G26: Condensed Financials | H26: F27 | I26: =F26*(1-F25) | J26: 78.866463 | K26: 0.01 | L26: effective_tax_rate_fy__20251231,net_interest_fy__20251231 | M26: After-tax net interest = Net Interest × (1 − Effective Tax Rate).|Do not tax-adjust a rate that is already after tax. | O26: pending | P26: net_interest_after_tax_fy | Q26: 5 | R26: 4 | S26: 2025-12-31
A27: nopat_fy__20211231 | B27: 26 | C27: NOPAT | D27: Reformulate net income to operating profit after tax. | E27: condensed.nopat.2021-12-31 | F27: accounting | G27: Condensed Financials | H27: B28 | I27: =B20+B27 | J27: 2822.2556 | K27: 0.01 | L27: net_income_link__20211231,net_interest_after_tax_fy__20211231 | M27: Start from Net Income on the Income Statement.|Add back after-tax net interest: Net Interest × (1 − Tax Rate).|NOPAT = Net Income + Net Interest After Tax. | O27: pending | P27: nopat_fy | Q27: 6 | R27: 0 | S27: 2021-12-31
A28: nopat_fy__20221231 | B28: 27 | C28: NOPAT | D28: Reformulate net income to operating profit after tax. | E28: condensed.nopat.2022-12-31 | F28: accounting | G28: Condensed Financials | H28: C28 | I28: =C20+C27 | J28: 3054.4 | K28: 0.01 | L28: net_income_link__20221231,net_interest_after_tax_fy__20221231 | M28: Start from Net Income on the Income Statement.|Add back after-tax net interest: Net Interest × (1 − Tax Rate).|NOPAT = Net Income + Net Interest After Tax. | O28: pending | P28: nopat_fy | Q28: 6 | R28: 1 | S28: 2022-12-31
A29: nopat_fy__20231231 | B29: 28 | C29: NOPAT | D29: Reformulate net income to operating profit after tax. | E29: condensed.nopat.2023-12-31 | F29: accounting | G29: Condensed Financials | H29: D28 | I29: =D20+D27 | J29: 3353.5575 | K29: 0.01 | L29: net_income_link__20231231,net_interest_after_tax_fy__20231231 | M29: Start from Net Income on the Income Statement.|Add back after-tax net interest: Net Interest × (1 − Tax Rate).|NOPAT = Net Income + Net Interest After Tax. | O29: pending | P29: nopat_fy | Q29: 6 | R29: 2 | S29: 2023-12-31
A30: nopat_fy__20241231 | B30: 29 | C30: NOPAT | D30: Reformulate net income to operating profit after tax. | E30: condensed.nopat.2024-12-31 | F30: accounting | G30: Condensed Financials | H30: E28 | I30: =E20+E27 | J30: 3718.7062 | K30: 0.01 | L30: net_income_link__20241231,net_interest_after_tax_fy__20241231 | M30: Start from Net Income on the Income Statement.|Add back after-tax net interest: Net Interest × (1 − Tax Rate).|NOPAT = Net Income + Net Interest After Tax. | O30: pending | P30: nopat_fy | Q30: 6 | R30: 3 | S30: 2024-12-31
A31: nopat_fy__20251231 | B31: 30 | C31: NOPAT | D31: Reformulate net income to operating profit after tax. | E31: condensed.nopat.2025-12-31 | F31: accounting | G31: Condensed Financials | H31: F28 | I31: =F20+F27 | J31: 4150.8665 | K31: 0.01 | L31: net_income_link__20251231,net_interest_after_tax_fy__20251231 | M31: Start from Net Income on the Income Statement.|Add back after-tax net interest: Net Interest × (1 − Tax Rate).|NOPAT = Net Income + Net Interest After Tax. | O31: pending | P31: nopat_fy | Q31: 6 | R31: 4 | S31: 2025-12-31
A32: owca_agg__20211231 | B32: 31 | C32: Operating working capital assets | D32: Aggregate the classified balance-sheet detail with the classification column. | E32: condensed.owca.2021-12-31 | F32: accounting | G32: Condensed Financials | H32: B31 | I32: =SUMIF($B$6:$B$16,"Operating Working Capital Asset",C$6:C$16) | J32: 1530 | K32: 0.01 | M32: Use SUMIF over the classification column for Operating Working Capital Asset. | O32: pending | P32: owca_agg | Q32: 7 | R32: 0 | S32: 2021-12-31
A33: owca_agg__20221231 | B33: 32 | C33: Operating working capital assets | D33: Aggregate the classified balance-sheet detail with the classification column. | E33: condensed.owca.2022-12-31 | F33: accounting | G33: Condensed Financials | H33: C31 | I33: =SUMIF($B$6:$B$16,"Operating Working Capital Asset",D$6:D$16) | J33: 1656 | K33: 0.01 | M33: Use SUMIF over the classification column for Operating Working Capital Asset. | O33: pending | P33: owca_agg | Q33: 7 | R33: 1 | S33: 2022-12-31
A34: owca_agg__20231231 | B34: 33 | C34: Operating working capital assets | D34: Aggregate the classified balance-sheet detail with the classification column. | E34: condensed.owca.2023-12-31 | F34: accounting | G34: Condensed Financials | H34: D31 | I34: =SUMIF($B$6:$B$16,"Operating Working Capital Asset",E$6:E$16) | J34: 1818 | K34: 0.01 | M34: Use SUMIF over the classification column for Operating Working Capital Asset. | O34: pending | P34: owca_agg | Q34: 7 | R34: 2 | S34: 2023-12-31
A35: owca_agg__20241231 | B35: 34 | C35: Operating working capital assets | D35: Aggregate the classified balance-sheet detail with the classification column. | E35: condensed.owca.2024-12-31 | F35: accounting | G35: Condensed Financials | H35: E31 | I35: =SUMIF($B$6:$B$16,"Operating Working Capital Asset",F$6:F$16) | J35: 2016 | K35: 0.01 | M35: Use SUMIF over the classification column for Operating Working Capital Asset. | O35: pending | P35: owca_agg | Q35: 7 | R35: 3 | S35: 2024-12-31
A36: owca_agg__20251231 | B36: 35 | C36: Operating working capital assets | D36: Aggregate the classified balance-sheet detail with the classification column. | E36: condensed.owca.2025-12-31 | F36: accounting | G36: Condensed Financials | H36: F31 | I36: =SUMIF($B$6:$B$16,"Operating Working Capital Asset",G$6:G$16) | J36: 2250 | K36: 0.01 | M36: Use SUMIF over the classification column for Operating Working Capital Asset. | O36: pending | P36: owca_agg | Q36: 7 | R36: 4 | S36: 2025-12-31
A37: owcl_agg__20211231 | B37: 36 | C37: Operating working capital liabilities | D37: Aggregate the classified balance-sheet detail with the classification column. | E37: condensed.owcl.2021-12-31 | F37: accounting | G37: Condensed Financials | H37: B32 | I37: =SUMIF($B$6:$B$16,"Operating Working Capital Liability",C$6:C$16) | J37: 595 | K37: 0.01 | M37: Use SUMIF over the classification column for Operating Working Capital Liability. | O37: pending | P37: owcl_agg | Q37: 8 | R37: 0 | S37: 2021-12-31
A38: owcl_agg__20221231 | B38: 37 | C38: Operating working capital liabilities | D38: Aggregate the classified balance-sheet detail with the classification column. | E38: condensed.owcl.2022-12-31 | F38: accounting | G38: Condensed Financials | H38: C32 | I38: =SUMIF($B$6:$B$16,"Operating Working Capital Liability",D$6:D$16) | J38: 644 | K38: 0.01 | M38: Use SUMIF over the classification column for Operating Working Capital Liability. | O38: pending | P38: owcl_agg | Q38: 8 | R38: 1 | S38: 2022-12-31
A39: owcl_agg__20231231 | B39: 38 | C39: Operating working capital liabilities | D39: Aggregate the classified balance-sheet detail with the classification column. | E39: condensed.owcl.2023-12-31 | F39: accounting | G39: Condensed Financials | H39: D32 | I39: =SUMIF($B$6:$B$16,"Operating Working Capital Liability",E$6:E$16) | J39: 707 | K39: 0.01 | M39: Use SUMIF over the classification column for Operating Working Capital Liability. | O39: pending | P39: owcl_agg | Q39: 8 | R39: 2 | S39: 2023-12-31
A40: owcl_agg__20241231 | B40: 39 | C40: Operating working capital liabilities | D40: Aggregate the classified balance-sheet detail with the classification column. | E40: condensed.owcl.2024-12-31 | F40: accounting | G40: Condensed Financials | H40: E32 | I40: =SUMIF($B$6:$B$16,"Operating Working Capital Liability",F$6:F$16) | J40: 784 | K40: 0.01 | M40: Use SUMIF over the classification column for Operating Working Capital Liability. | O40: pending | P40: owcl_agg | Q40: 8 | R40: 3 | S40: 2024-12-31
...

Sheet _CheckContext
A1: BAV_CHECK_CONTEXT_V1
A2: {"base_classification_overrides":{},"judgment_bindings":[{"allowed_treatments":["Operating Long-Term Liability","Financial Liability"],"case_id":"classification::concept=lease_liability|label=operating lease liabilities","line_identity":"concept=lease_liability|label=operating lease liabilities","order":1,"override_selector":"concept:lease_liability","reference_treatment":"Operating Long-Term Liability","worksheet_row":5}],"modeled_periods":["2021-12-31","2022-12-31","2023-12-31","2024-12-31","2025-12-31"],"normalization_bindings":[{"allowed_treatments":["Non-recurring","Recurring"],"case_id":"normalization::concept=restructuring_expense|label=restructuring expense","line_identity":"concept=restructuring_expense|label=restructuring expense","order":1,"reference_treatment":"Non-recurring","scope":"operating_pretax_effective_tax","source_selector":"concept:restructuring_expense","worksheet_row":5}],"schema_version":2,"source_payload":{"balance_sheet":[{"concept":"","label":"Cash and cash equivalents","values":{"2021-12-31":1200.0,"2022-12-31":1350.0,"2023-12-31":1500.0,"2024-12-31":1680.0,"2025-12-31":1850.0}},{"concept":"","label":"Trade receivables","values":{"2021-12-31":850.0,"2022-12-31":920.0,"2023-12-31":1010.0,"2024-12-31":1120.0,"2025-12-31":1250.0}},{"concept":"","label":"Inventories","values":{"2021-12-31":680.0,"2022-12-31":736.0,"2023-12-31":808.0,"2024-12-31":896.0,"2025-12-31":1000.0}},{"concept":"","label":"Property, plant and equipment","values":{"2021-12-31":3200.0,"2022-12-31":3400.0,"2023-12-31":3600.0,"2024-12-31":3800.0,"2025-12-31":4000.0}},{"concept":"","label":"Goodwill","values":{"2021-12-31":900.0,"2022-12-31":900.0,"2023-12-31":900.0,"2024-12-31":900.0,"2025-12-31":900.0}},{"concept":"","label":"Other non-current assets","values":{"2021-12-31":1670.0,"2022-12-31":1894.0,"2023-12-31":2282.0,"2024-12-31":2804.0,"2025-12-31":3500.0}},{"concept":"","label":"Total assets","values":{"2021-12-31":8500.0,"2022-12-31":9200.0,"2023-12-31":10100.0,"2024-12-31":11200.0,"2025-12-31":12500.0}},{"concept":"","label":"Trade payables","values":{"2021-12-31":595.0,"2022-12-31":644.0,"2023-12-31":707.0,"2024-12-31":784.0,"2025-12-31":875.0}},{"concept":"","label":"Bank borrowings","values":{"2021-12-31":1500.0,"2022-12-31":1400.0,"2023-12-31":1300.0,"2024-12-31":1200.0,"2025-12-31":1100.0}},{"concept":"lease_liability","label":"Operating lease liabilities","values":{"2021-12-31":300.0,"2022-12-31":320.0,"2023-12-31":340.0,"2024-12-31":360.0,"2025-12-31":380.0}},{"concept":"","label":"Other non-current liabilities","values":{"2021-12-31":1005.0,"2022-12-31":1136.0,"2023-12-31":1253.0,"2024-12-31":1356.0,"2025-12-31":1445.0}},{"concept":"","label":"Total liabilities","values":{"2021-12-31":3400.0,"2022-12-31":3500.0,"2023-12-31":3600.0,"2024-12-31":3700.0,"2025-12-31":3800.0}},{"concept":"","label":"Share capital and reserves","values":{"2021-12-31":5100.0,"2022-12-31":5700.0,"2023-12-31":6500.0,"2024-12-31":7500.0,"2025-12-31":8700.0}},{"concept":"","label":"Total equity","values":{"2021-12-31":5100.0,"2022-12-31":5700.0,"2023-12-31":6500.0,"2024-12-31":7500.0,"2025-12-31":8700.0}}],"cash_flow":[{"concept":"","label":"Profit for the year","values":{"2021-12-31":2760.0,"2022-12-31":2988.0,"2023-12-31":3283.0,"2024-12-31":3644.0,"2025-12-31":4072.0}},{"concept":"","label":"Depreciation and amortisation","values":{"2021-12-31":340.0,"2022-12-31":368.0,"2023-12-31":404.0,"2024-12-31":448.0,"2025-12-31":500.0}},{"concept":"","label":"Net cash from operating activities","values":{"2021-12-31":1450.0,"2022-12-31":1600.0,"2023-12-31":1750.0,"2024-12-31":1930.0,"2025-12-31":2070.0}},{"concept":"","label":"Net cash used in investing activities","values":{"2021-12-31":-800.0,"2022-12-31":-850.0,"2023-12-31":-900.0,"2024-12-31":-950.0,"2025-12-31":-1000.0}},{"concept":"","label":"Net cash from financing activities","values":{"2021-12-31":-500.0,"2022-12-31":-600.0,"2023-12-31":-700.0,"2024-12-31":-800.0,"2025-12-31":-900.0}},{"concept":"","label":"Net change in cash and cash equivalents","values":{"2021-12-31":150.0,"2022-12-31":150.0,"2023-12-31":150.0,"2024-12-31":180.0,"2025-12-31":170.0}}],"company_name":"Demo Holdings Limited","currency":"HKD","income_statement":[{"concept":"","label":"Revenue","values":{"2021-12-31":8500.0,"2022-12-31":9200.0,"2023-12-31":10100.0,"2024-12-31":11200.0,"2025-12-31":12500.0}},{"concept":"","label":"Cost of sales","values":{"2021-12-31":-3400.0,"2022-12-31":-3680.0,"2023-12-31":-4040.0,"2024-12-31":-4480.0,"2025-12-31":-5000.0}},{"concept":"","label":"Gross profit","values":{"2021-12-31":5100.0,"2022-12-31":5520.0,"2023-12-31":6060.0,"2024-12-31":6720.0,"2025-12-31":7500.0}},{"concept":"","label":"Administrative expenses","values":{"2021-12-31":-1700.0,"2022-12-31":-1840.0,"2023-12-31":-1820.0,"2024-12-31":-2240.0,"2025-12-31":-2500.0}},{"concept":"restructuring_expense","label":"Restructuring expense","values":{"2021-12-31":0.0,"2022-12-31":0.0,"2023-12-31":-200.0,"2024-12-31":0.0,"2025-12-31":0.0}},{"concept":"","label":"Operating profit","values":{"2021-12-31":3400.0,"2022-12-31":3680.0,"2023-12-31":4040.0,"2024-12-31":4480.0,"2025-12-31":5000.0}},{"concept":"","label":"Finance costs","values":{"2021-12-31":-120.0,"2022-12-31":-130.0,"2023-12-31":-140.0,"2024-12-31":-150.0,"2025-12-31":-160.0}},{"concept":"","label":"Finance income","values":{"2021-12-31":45.0,"2022-12-31":50.0,"2023-12-31":55.0,"2024-12-31":60.0,"2025-12-31":65.0}},{"concept":"","label":"Profit before tax","values":{"2021-12-31":3325.0,"2022-12-31":3600.0,"2023-12-31":3955.0,"2024-12-31":4390.0,"2025-12-31":4905.0}},{"concept":"","label":"Income tax expense","values":{"2021-12-31":-565.0,"2022-12-31":-612.0,"2023-12-31":-672.0,"2024-12-31":-746.0,"2025-12-31":-833.0}},{"concept":"","label":"Profit for the year","values":{"2021-12-31":2760.0,"2022-12-31":2988.0,"2023-12-31":3283.0,"2024-12-31":3644.0,"2025-12-31":4072.0}}],"jurisdiction":"HK","periods":[{"end_date":"2021-12-31","is_interim":false,"label":"FY2021"},{"end_date":"2022-12-31","is_interim":false,"label":"FY2022"},{"end_date":"2023-12-31","is_interim":false,"label":"FY2023"},{"end_date":"2024-12-31","is_interim":false,"label":"FY2024"},{"end_date":"2025-12-31","is_interim":false,"label":"FY2025"}],"stock_code":"1234.HK","ticker":"DEMO","units":"HKD in Millions"}}
