Workbook

Sheet Trainer
A1: BAV Excel Trainer
A2: Complete each historical model-construction and earnings-quality diagnostic formula schedule left-to-right in dependency order. Run Check to validate the yellow formula cells against the treatment currently selected in Accounting Judgment column F (blank F uses the supplied reference treatment). Generated Condensed Financials classification links are system-controlled and validated by Check—do not edit them or columns D:E. When Normalization Judgment is present, choose Recurring vs Non-recurring in column F (blank uses the supplied reference); Earnings Normalization formulas are checked against that choice. Also complete Accounting Judgment and Normalization Judgment rationale/consequence when cases are present; those responses are not graded by Check. Compare them with the matching Answer Key.
A4: Order | B4: Schedule | C4: Period scope | D4: Tab | E4: Practice cells | F4: Depends on
A5: 1 | B5: Revenue historical source link | C5: 2021–2025 (5 cells) | D5: Condensed Financials | E5: B44:F44 | F5: —
A6: 2 | B6: Net Income historical source link | C6: 2021–2025 (5 cells) | D6: Condensed Financials | E6: B45:F45 | F6: —
A7: 3 | B7: Effective tax rate | C7: 2021–2025 (5 cells) | D7: Condensed Financials | E7: B51:F51 | F7: —
A8: 4 | B8: Net interest | C8: 2021–2025 (5 cells) | D8: Condensed Financials | E8: B52:F52 | F8: —
A9: 5 | B9: Net interest after tax | C9: 2021–2025 (5 cells) | D9: Condensed Financials | E9: B53:F53 | F9: effective_tax_rate_fy, net_interest_fy
A10: 6 | B10: NOPAT | C10: 2021–2025 (5 cells) | D10: Condensed Financials | E10: B54:F54 | F10: net_income_link, net_interest_after_tax_fy
A11: 7 | B11: Operating working capital assets | C11: 2021–2025 (5 cells) | D11: Condensed Financials | E11: B57:F57 | F11: —
A12: 8 | B12: Operating working capital liabilities | C12: 2021–2025 (5 cells) | D12: Condensed Financials | E12: B58:F58 | F12: —
A13: 9 | B13: Net Operating Working Capital (NOWC) | C13: 2021–2025 (5 cells) | D13: Condensed Financials | E13: B59:F59 | F13: owca_agg, owcl_agg
A14: 10 | B14: Operating long-term assets | C14: 2021–2025 (5 cells) | D14: Condensed Financials | E14: B60:F60 | F14: —
A15: 11 | B15: Operating long-term liabilities | C15: 2021–2025 (5 cells) | D15: Condensed Financials | E15: B61:F61 | F15: —
A16: 12 | B16: Net operating long-term assets (NOLA) | C16: 2021–2025 (5 cells) | D16: Condensed Financials | E16: B62:F62 | F16: olta_agg, oltl_agg
... A136: 149 | B136: Reconstructed change in inventory | C136: 2022–2025 (4 cells) | D136: ALT DuPont | E136: C121:F121 | F136: inventory_revenue_scale_effect, inventory_intensity_effect

Sheet Income Statement
A1: Company: FAST RETAILING CO., LTD. (6288.HK)
A2: Statement: Income Statement
A3: Units: JPY in Millions
A4: Source: manual ingestion (JP)
A6: Line Item | B6: 44439 | C6: 44804 | D6: 45169 | E6: 45535 | F6: 45900
A7: Basic (yen, dollar) | B7: 1663.12 | C7: 891.77 | D7: 966.09 | E7: 1212.88 | F7: 1411.44
A8: Cost of sales | B8: -1059036 | C8: -1094263 | D8: -1330196 | E8: -1430764 | F8: -1571681
A9: Diluted (yen, dollar) | B9: 1660.44 | C9: 890.43 | D9: 964.48 | E9: 1210.81 | F9: 1409.32
A10: Finance costs | B10: -6998 | C10: -7560 | D10: -9888 | E10: -11101 | F10: -12834
A11: Finance income | B11: 23859 | C11: 123820 | D11: 66716 | E11: 67399 | F11: 99143
A12: Gross profit | B12: 1073955 | C12: 1206859 | D12: 1436360 | E12: 1673071 | F12: 1828858
A13: Income tax expense | B13: -90188 | C13: -128834 | D13: -122746 | E13: -163596 | F13: -191421
A14: Non-controlling interests | B14: 5836 | C14: 11415 | D14: 18941 | E14: 21605 | F14: 26143
A15: Operating profit | B15: 249011 | C15: 297325 | D15: 381090 | E15: 500904 | F15: 564265
A16: Other expenses | B16: -25315 | C16: -27391 | D16: -14238 | E16: -6256 | F16: -8087
A17: Other income | B17: 18238 | C17: 16951 | D17: 12197 | E17: 20384 | F17: 19491
... A23: Share of profit of associates accounted for using the equity method | B23: 561 | C23: 1059 | D23: 1139 | E23: 1417 | F23: 1704
A25: SUPPLEMENTAL DISCLOSURES
A26: Lease interest expense (reported note) | B26: 4847 | C26: 4757 | D26: 5187 | E26: 6507 | F26: 8464

Sheet Balance Sheet
A1: Company: FAST RETAILING CO., LTD. (6288.HK)
A2: Statement: Balance Sheet
A3: Units: JPY in Millions
A4: Source: manual ingestion (JP)
A6: Line Item | B6: 44439 | C6: 44804 | D6: 45169 | E6: 45535 | F6: 45900
A7: Total assets | B7: 2509976 | C7: 3183762 | D7: 3303694 | E7: 3587565 | F7: 3859353
A8: Cash and cash equivalents | B8: 1177736 | C8: 1358292 | D8: 903280 | E8: 1193560 | F8: 893239
A9: Derivative financial assets | B9: 27103 | C9: 124551 | D9: 132101 | E9: 111658 | F9: 94803
A10: Income taxes receivable | B10: 2992 | C10: 2612 | D10: 23660 | E10: 2210 | F10: 8042
A11: Inventories | B11: 394868 | C11: 485928 | D11: 449254 | E11: 474460 | F11: 510958
A12: Other assets | B12: 15270 | C12: 23835 | D12: 25372 | E12: 26897 | F12: 24662
A13: Other financial assets | B13: 56157 | C13: 123446 | D13: 576194 | E13: 470554 | F13: 899701
A14: Total current assets | B14: 1724674 | C14: 2178851 | D14: 2176695 | E14: 2363271 | F14: 2527815
A15: Trade and other receivables | B15: 50546 | C15: 60184 | D15: 66831 | E15: 83929 | F15: 96407
A16: Current tax liabilities | B16: 38606 | C16: 77162 | D16: 65428 | E16: 65525 | F16: 73072
A17: Derivative financial liabilities | B17: 2493 | C17: 1513 | D17: 3600 | E17: 12716 | F17: 19250
... A50: Total non-current liabilities | B50: 766665 | C50: 692117 | D50: 701072 | E50: 666920 | F50: 620561

Sheet Cash Flow Statement
A1: Company: FAST RETAILING CO., LTD. (6288.HK)
A2: Statement: Cash Flow Statement
A3: Units: JPY in Millions
A4: Source: manual ingestion (JP)
A6: Line Item | B6: 44439 | C6: 44804 | D6: 45169 | E6: 45535 | F6: 45900
A7: (Increase)/decrease in inventories | B7: 36749 | C7: -50896 | D7: 46908 | E7: -23540 | F7: -29855
A8: (Increase)/decrease in other assets | B8: 3494 | C8: -7125 | D8: 8354 | E8: -876 | F8: -2479
A9: (Increase)/decrease in trade and other receivables | B9: 15334 | C9: -2651 | D9: -7535 | E9: -17394 | F9: -12718
A10: Amounts deposited into bank deposits with original maturities of three months or longer | B10: -102307 | C10: -143517 | D10: -387720 | E10: -441156 | F10: -1008113
A11: Amounts withdrawn from bank deposits with original maturities of three months or longer | B11: 99943 | C11: 126774 | D11: 182882 | E11: 460241 | F11: 798490
A12: Cash and cash equivalents at the beginning of year | B12: 1093531 | C12: 1177736 | D12: 1358292 | E12: 903280 | F12: 1193560
A13: Cash and cash equivalents at the end of year | B13: 1177736 | C13: 1358292 | D13: 903280 | E13: 1193560 | F13: 893239
A14: Cash generated from operations | B14: 509672 | C14: 518010 | D14: 610338 | E14: 739726 | F14: 728879
A15: Depreciation and amortization | B15: 177910 | C15: 180275 | D15: 186872 | E15: 204388 | F15: 216492
A16: Dividends paid to non-controlling interests | B16: -2342 | C16: -11623 | D16: -20460 | E16: -18369 | F16: -26428
A17: Dividends paid to owners of the Parent | B17: -48993 | C17: -53091 | D17: -73064 | E17: -104263 | F17: -142630
... A48: Share of (profit)/loss of associates accounted for using the equity method | B48: -561 | C48: -1059 | D48: -1139 | E48: -1417 | F48: -1704

Sheet Condensed Financials
A1: FAST RETAILING CO., LTD. (6288.HK) — Condensed Financials
A4: BALANCE SHEET CLASSIFICATION
A5: Line Item | B5: Classification | C5: 44439 | D5: 44804 | E5: 45169 | F5: 45535 | G5: 45900 | H5: Notes
A6: Cash and cash equivalents | B6: Financial Asset | C6: 1177736 | D6: 1358292 | E6: 903280 | F6: 1193560 | G6: 893239
A7: Derivative financial assets | B7: =IF('Accounting Judgment'!$F$5="","Financial Asset",'Accounting Judgment'!$F$5) | C7: 27103 | D7: 124551 | E7: 132101 | F7: 111658 | G7: 94803 | H7: ⚠ Review: Generic financial-asset concept — financial vs operating purpose/hedging judgment
A8: Income taxes receivable | B8: Operating Working Capital Asset | C8: 2992 | D8: 2612 | E8: 23660 | F8: 2210 | G8: 8042
A9: Inventories | B9: Operating Working Capital Asset | C9: 394868 | D9: 485928 | E9: 449254 | F9: 474460 | G9: 510958
A10: Other assets | B10: =IF('Accounting Judgment'!$F$6="","Operating Working Capital Asset",'Accounting Judgment'!$F$6) | C10: 15270 | D10: 23835 | E10: 25372 | F10: 26897 | G10: 24662 | H10: ⚠ Review: Explicit residual balance-sheet concept identifies side/horizon but not economic nature — operating vs financial judgment
A11: Other financial assets | B11: =IF('Accounting Judgment'!$F$7="","Financial Asset",'Accounting Judgment'!$F$7) | C11: 56157 | D11: 123446 | E11: 576194 | F11: 470554 | G11: 899701 | H11: ⚠ Review: Generic financial-asset concept — financial vs operating purpose/hedging judgment
A12: Trade and other receivables | B12: Operating Working Capital Asset | C12: 50546 | D12: 60184 | E12: 66831 | F12: 83929 | G12: 96407
A13: Current tax liabilities | B13: Operating Working Capital Liability | C13: 38606 | D13: 77162 | E13: 65428 | F13: 65525 | G13: 73072
A14: Derivative financial liabilities | B14: =IF('Accounting Judgment'!$F$8="","Financial Liability",'Accounting Judgment'!$F$8) | C14: 2493 | D14: 1513 | E14: 3600 | F14: 12716 | G14: 19250 | H14: ⚠ Review: Generic financial-liability concept — financial vs operating purpose/hedging judgment
A15: Lease liabilities | B15: =IF('Accounting Judgment'!$F$9="","Operating Long-Term Liability",'Accounting Judgment'!$F$9) | C15: 117083 | D15: 123885 | E15: 126992 | F15: 130744 | G15: 126830 | H15: ⚠ Review: Lease liability concept — operating vs financial judgment
A16: Other financial liabilities | B16: =IF('Accounting Judgment'!$F$10="","Financial Liability",'Accounting Judgment'!$F$10) | C16: 104969 | D16: 209286 | E16: 61913 | F16: 104770 | G16: 150942 | H16: ⚠ Review: Generic financial-liability concept — financial vs operating purpose/hedging judgment
A17: Other liabilities | B17: =IF('Accounting Judgment'!$F$11="","Operating Working Capital Liability",'Accounting Judgment'!$F$11) | C17: 95652 | D17: 111519 | E17: 129782 | F17: 148201 | G17: 149394 | H17: ⚠ Review: Explicit residual balance-sheet concept identifies side/horizon but not economic nature — operating vs financial judgment
A18: Provisions | B18: Operating Working Capital Liability | C18: 2149 | D18: 2581 | E18: 2642 | F18: 1774 | G18: 1651
A19: Trade and other payables | B19: Operating Working Capital Liability | C19: 220057 | D19: 350294 | E19: 338901 | F19: 388656 | G19: 390149
A20: Capital stock | B20: Equity | C20: 10273 | D20: 10273 | E20: 10273 | F20: 10273 | G20: 10273
A21: Capital surplus | B21: Equity | C21: 25360 | D21: 27834 | E21: 28531 | F21: 29712 | G21: 30998
A22: Equity attributable to owners of the Parent | B22: Equity | C22: 1116484 | D22: 1561652 | E22: 1821405 | F22: 2016535 | G22: 2273115
A23: Non-controlling interests | B23: Equity | C23: 45813 | D23: 53750 | E23: 51955 | F23: 51718 | G23: 54385
A24: Other components of equity | B24: Equity | C24: 41031 | D24: 263255 | E24: 298965 | F24: 225104 | G24: 189936
A25: Retained earnings | B25: Equity | C25: 1054791 | D25: 1275102 | E25: 1498348 | F25: 1766073 | G25: 2056437
A26: Treasury stock, at cost | B26: Equity | C26: -14973 | D26: -14813 | E26: -14714 | F26: -14628 | G26: -14529
A27: Deferred tax assets | B27: Operating Long-Term Asset | C27: 37125 | D27: 8506 | E27: 38208 | F27: 32432 | G27: 40889 | H27: ⚠ Review: Deferred tax asset concept — operating vs exclude judgment
A28: Derivative financial assets | B28: =IF('Accounting Judgment'!$F$12="","Financial Asset",'Accounting Judgment'!$F$12) | C28: 22552 | D28: 134240 | E28: 114151 | F28: 66995 | G28: 33882 | H28: ⚠ Review: Generic financial-asset concept — financial vs operating purpose/hedging judgment
A29: Financial assets | B29: =IF('Accounting Judgment'!$F$13="","Financial Asset",'Accounting Judgment'!$F$13) | C29: 67122 | D29: 164340 | E29: 240363 | F29: 336302 | G29: 312438 | H29: ⚠ Review: Generic financial-asset concept — financial vs operating purpose/hedging judgment
A30: Goodwill | B30: Operating Long-Term Asset | C30: 8092 | D30: 8092 | E30: 8092 | F30: 8092 | G30: 8092
A31: Intangible assets | B31: Operating Long-Term Asset | C31: 66939 | D31: 76621 | E31: 87300 | F31: 92568 | G31: 91606
A32: Investments in associates accounted for using the equity method | B32: =IF('Accounting Judgment'!$F$14="","Operating Long-Term Asset",'Accounting Judgment'!$F$14) | C32: 18236 | D32: 18557 | E32: 18974 | F32: 19559 | G32: 31361 | H32: ⚠ Review: Equity-method investment concept — operating vs financial judgment
A33: Other assets | B33: =IF('Accounting Judgment'!$F$15="","Operating Long-Term Asset",'Accounting Judgment'!$F$15) | C33: 6520 | D33: 3690 | E33: 8846 | F33: 5888 | G33: 3803 | H33: ⚠ Review: Explicit residual balance-sheet concept identifies side/horizon but not economic nature — operating vs financial judgment
A34: Property, plant and equipment | B34: Operating Long-Term Asset | C34: 168177 | D34: 195226 | E34: 221877 | F34: 245742 | G34: 332351
A35: Right-of-use assets | B35: Operating Long-Term Asset | C35: 390537 | D35: 395634 | E35: 389183 | F35: 416712 | G35: 477111 | H35: ⚠ Review: Lease/ROU asset concept — operating vs financial judgment
A36: Deferred tax liabilities | B36: Operating Long-Term Liability | C36: 9860 | D36: 44258 | E36: 67039 | F36: 31896 | G36: 22539 | H36: ⚠ Review: Deferred tax liability concept — operating vs exclude judgment
A37: Derivative financial liabilities | B37: =IF('Accounting Judgment'!$F$16="","Financial Liability",'Accounting Judgment'!$F$16) | C37: 1042 | D37: 44 | E37: 1410 | F37: 21385 | G37: 12110 | H37: ⚠ Review: Generic financial-liability concept — financial vs operating purpose/hedging judgment
A38: Financial liabilities | B38: =IF('Accounting Judgment'!$F$17="","Financial Liability",'Accounting Judgment'!$F$17) | C38: 370799 | D38: 241022 | E38: 241068 | F38: 211147 | G38: 141071 | H38: ⚠ Review: Generic financial-liability concept — financial vs operating purpose/hedging judgment
A39: Lease liabilities | B39: =IF('Accounting Judgment'!$F$18="","Operating Long-Term Liability",'Accounting Judgment'!$F$18) | C39: 343574 | D39: 356840 | E39: 338657 | F39: 347318 | G39: 386670 | H39: ⚠ Review: Lease liability concept — operating vs financial judgment
A40: Other liabilities | B40: =IF('Accounting Judgment'!$F$19="","Operating Long-Term Liability",'Accounting Judgment'!$F$19) | C40: 2342 | D40: 2171 | E40: 2007 | F40: 2521 | G40: 2457 | H40: ⚠ Review: Explicit residual balance-sheet concept identifies side/horizon but not economic nature — operating vs financial judgment
A41: Provisions | B41: Operating Long-Term Liability | C41: 39046 | D41: 47780 | E41: 50888 | F41: 52652 | G41: 55711
A43: CONDENSED INCOME STATEMENT | B43: 44439 | C43: 44804 | D43: 45169 | E43: 45535 | F43: 45900
...

Sheet ALT DuPont
A1: FAST RETAILING CO., LTD. — DuPont Decomposition
A2: ROE = RNOA + FLEV × Spread
A4: Metric | B4: 44439 | C4: 44804 | D4: 45169 | E4: 45535 | F4: 45900
A5: Sales Growth | B5: N/A
A6: NOPAT Margin
A7: RNOA | B7: N/A
A8: After-tax CoD | B8: N/A
A9: Spread | B9: N/A
A10: FLEV | B10: N/A
A11: ROE (decomposed) | B11: N/A
A12: Actual ROE | B12: N/A
A14: RNOA DRIVER DECOMPOSITION
A15: Average NOA | B15: N/A
A16: NOA Turnover | B16: N/A
A17: NOA Intensity | B17: N/A
A18: RNOA from Margin × Turnover | B18: N/A
A19: RNOA DRIVER CHECK | B19: N/A | C19: =IF(ISNA(C18),"N/A",IF(ISNA(C7),"CHECK",IF(ABS(C18-C7)<0.0000001,"OK","CHECK"))) | D19: =IF(ISNA(D18),"N/A",IF(ISNA(D7),"CHECK",IF(ABS(D18-D7)<0.0000001,"OK","CHECK"))) | E19: =IF(ISNA(E18),"N/A",IF(ISNA(E7),"CHECK",IF(ABS(E18-E7)<0.0000001,"OK","CHECK"))) | F19: =IF(ISNA(F18),"N/A",IF(ISNA(F7),"CHECK",IF(ABS(F18-F7)<0.0000001,"OK","CHECK")))
A21: RNOA CHANGE ATTRIBUTION
A22: Change in NOPAT Margin | B22: N/A | C22: N/A
A23: Change in NOA Turnover | B23: N/A | C23: N/A
A24: Direct Change in RNOA | B24: N/A | C24: N/A
A25: Margin Effect on RNOA Change | B25: N/A | C25: N/A
A26: Turnover Effect on RNOA Change | B26: N/A | C26: N/A
A27: RNOA Change from Drivers | B27: N/A | C27: N/A
A28: RNOA CHANGE DRIVER CHECK | B28: N/A | C28: N/A | D28: =IF(OR(ISNA(D27),ISNA(D24)),"N/A",IF(ABS(D27-D24)<0.0000001,"OK","CHECK")) | E28: =IF(OR(ISNA(E27),ISNA(E24)),"N/A",IF(ABS(E27-E24)<0.0000001,"OK","CHECK")) | F28: =IF(OR(ISNA(F27),ISNA(F24)),"N/A",IF(ABS(F27-F24)<0.0000001,"OK","CHECK"))
A30: ROE OPERATING / FINANCING ATTRIBUTION
A31: Financing Contribution to ROE | B31: N/A
A32: ROE LEVEL ATTRIBUTION CHECK | B32: N/A | C32: =IF(OR(ISNA(C7),ISNA(C31),ISNA(C11)),"N/A",IF(ABS(C7+C31-C11)<0.0000001,"OK","CHECK")) | D32: =IF(OR(ISNA(D7),ISNA(D31),ISNA(D11)),"N/A",IF(ABS(D7+D31-D11)<0.0000001,"OK","CHECK")) | E32: =IF(OR(ISNA(E7),ISNA(E31),ISNA(E11)),"N/A",IF(ABS(E7+E31-E11)<0.0000001,"OK","CHECK")) | F32: =IF(OR(ISNA(F7),ISNA(F31),ISNA(F11)),"N/A",IF(ABS(F7+F31-F11)<0.0000001,"OK","CHECK"))
A34: ROE CHANGE ATTRIBUTION
A35: Direct Change in Decomposed ROE | B35: N/A | C35: N/A
A36: Operating Effect on Change in ROE | B36: N/A | C36: N/A
A37: Leverage Effect on Change in ROE | B37: N/A | C37: N/A
A38: Spread Effect on Change in ROE | B38: N/A | C38: N/A
A39: Financing Effect on Change in ROE | B39: N/A | C39: N/A
A40: Change in ROE from Drivers | B40: N/A | C40: N/A
A41: ROE CHANGE ATTRIBUTION CHECK | B41: N/A | C41: N/A | D41: =IF(OR(ISNA(D40),ISNA(D35)),"N/A",IF(ABS(D40-D35)<0.0000001,"OK","CHECK")) | E41: =IF(OR(ISNA(E40),ISNA(E35)),"N/A",IF(ABS(E40-E35)<0.0000001,"OK","CHECK")) | F41: =IF(OR(ISNA(F40),ISNA(F35)),"N/A",IF(ABS(F40-F35)<0.0000001,"OK","CHECK"))
A43: FIXED-ASSET INTENSITY CONTEXT
A44: Property, Plant & Equipment
A45: Depreciation & Amortisation
A46: Average PP&E | B46: N/A
...

Sheet Accounting Judgment
A1: Accounting Judgment
A2: The supplied treatment is the model's reference treatment, not a universal accounting truth. Compare it with the listed alternative(s), choose the treatment you would defend, and explain the economic consequence.
A3: Choose a treatment in column F only. That choice drives the matching Condensed Financials classification and downstream historical schedules; leaving F blank uses the supplied reference treatment. Columns D:E are display context and must not be edited. Enter your rationale and economic consequence in G:H. Formula Check grades formula cells against the treatment currently selected in F and validates that the generated classification links remain intact; it does not grade the judgment response itself. Do not edit the linked Condensed Financials classification cell directly.
A4: Order | B4: Line item | C4: Topic | D4: Supplied reference treatment | E4: Alternative(s) to evaluate | F4: Treatment to defend | G4: Rationale | H4: Economic consequence
A5: 1 | B5: Derivative financial assets | C5: Current financial asset: financial vs operating | D5: Financial Asset | E5: Operating Working Capital Asset
A6: 2 | B6: Other assets | C6: Other current asset: operating vs financial | D6: Operating Working Capital Asset | E6: Financial Asset
A7: 3 | B7: Other financial assets | C7: Current financial asset: financial vs operating | D7: Financial Asset | E7: Operating Working Capital Asset
A8: 4 | B8: Derivative financial liabilities | C8: Current financial liability: financial vs operating | D8: Financial Liability | E8: Operating Working Capital Liability
A9: 5 | B9: Lease liabilities | C9: Lease liability operating vs financing | D9: Operating Long-Term Liability | E9: Financial Liability
A10: 6 | B10: Other financial liabilities | C10: Current financial liability: financial vs operating | D10: Financial Liability | E10: Operating Working Capital Liability
A11: 7 | B11: Other liabilities | C11: Other current liability: operating vs financial | D11: Operating Working Capital Liability | E11: Financial Liability
A12: 8 | B12: Derivative financial assets | C12: Non-current financial asset: financial vs operating | D12: Financial Asset | E12: Operating Long-Term Asset
A13: 9 | B13: Financial assets | C13: Non-current financial asset: financial vs operating | D13: Financial Asset | E13: Operating Long-Term Asset
A14: 10 | B14: Investments in associates accounted for using the equity method | C14: Equity-method investment operating vs financing | D14: Operating Long-Term Asset | E14: Financial Asset
A15: 11 | B15: Other assets | C15: Other non-current asset: operating vs financial | D15: Operating Long-Term Asset | E15: Financial Asset
A16: 12 | B16: Derivative financial liabilities | C16: Non-current financial liability: financial vs operating | D16: Financial Liability | E16: Operating Long-Term Liability
... A19: 15 | B19: Other liabilities | C19: Other non-current liability: operating vs financial | D19: Operating Long-Term Liability | E19: Financial Liability

Sheet Ownership Attribution
A1: FAST RETAILING CO., LTD. — Ownership Attribution
A2: Parent / NCI profit and equity bridges and parent ROE. Consolidated DuPont / NOA / Net Debt remain unchanged; parent ROE is a separate shareholder-attribution diagnostic.
A4: Metric | B4: 44439 | C4: 44804 | D4: 45169 | E4: 45535 | F4: 45900
A5: Parent Profit
A6: NCI Profit
A7: Total Profit | B7: ='Income Statement'!B20 | C7: ='Income Statement'!C20 | D7: ='Income Statement'!D20 | E7: ='Income Statement'!E20 | F7: ='Income Statement'!F20
A8: Profit Attribution Gap
A10: Parent Equity
A11: NCI Equity
A12: Total Equity | B12: ='Balance Sheet'!B30 | C12: ='Balance Sheet'!C30 | D12: ='Balance Sheet'!D30 | E12: ='Balance Sheet'!E30 | F12: ='Balance Sheet'!F30
A13: Equity Attribution Gap
A15: Parent ROE | B15: N/A

Sheet Earnings Quality
A1: FAST RETAILING CO., LTD. — Earnings Quality
A2: Historical cash-conversion and accrual diagnostics. These are mechanical diagnostics, not an automatic quality score.
A4: Metric | B4: 44439 | C4: 44804 | D4: 45169 | E4: 45535 | F4: 45900
A5: Operating Cash Flow
A6: Reported Net Income | B6: ='Condensed Financials'!B45 | C6: ='Condensed Financials'!C45 | D6: ='Condensed Financials'!D45 | E6: ='Condensed Financials'!E45 | F6: ='Condensed Financials'!F45
A7: Cash Conversion Ratio
A8: Total Accruals (Net Income - CFO)
A10: Total Assets | B10: ='Balance Sheet'!B7 | C10: ='Balance Sheet'!C7 | D10: ='Balance Sheet'!D7 | E10: ='Balance Sheet'!E7 | F10: ='Balance Sheet'!F7
A11: Average Total Assets
A12: Accrual Ratio
A14: EARNINGS QUALITY TREND DIAGNOSTICS
A15: Change in Operating Cash Flow | B15: N/A
A16: Change in Cash Conversion Ratio | B16: N/A
A17: Change in Total Accruals | B17: N/A
A18: Change in Accrual Ratio | B18: N/A | C18: N/A
A19: EARNINGS QUALITY CHANGE CHECK | B19: N/A | C19: =IF(ABS(C17-((C6-B6)-C15))<0.01,"OK","CHECK") | D19: =IF(ABS(D17-((D6-C6)-D15))<0.01,"OK","CHECK") | E19: =IF(ABS(E17-((E6-D6)-E15))<0.01,"OK","CHECK") | F19: =IF(ABS(F17-((F6-E6)-F15))<0.01,"OK","CHECK")

Sheet Working Capital Analysis
A1: Working Capital Analysis
A2: Relate classified operating working capital to Revenue and identify how much incremental NOWC accompanies changes in sales.
A3: These are diagnostics, not automatic judgments. Positive Change in NOWC is an operating cash use; negative Change in NOWC is a release. Annual data alone does not prove seasonality or deterioration.
A5: Metric | B5: 44439 | C5: 44804 | D5: 45169 | E5: 45535 | F5: 45900
A6: Revenue | B6: ='Condensed Financials'!B44 | C6: ='Condensed Financials'!C44 | D6: ='Condensed Financials'!D44 | E6: ='Condensed Financials'!E44 | F6: ='Condensed Financials'!F44
A7: Operating Working Capital Assets | B7: ='Condensed Financials'!B57 | C7: ='Condensed Financials'!C57 | D7: ='Condensed Financials'!D57 | E7: ='Condensed Financials'!E57 | F7: ='Condensed Financials'!F57
A8: Operating Working Capital Liabilities | B8: ='Condensed Financials'!B58 | C8: ='Condensed Financials'!C58 | D8: ='Condensed Financials'!D58 | E8: ='Condensed Financials'!E58 | F8: ='Condensed Financials'!F58
A9: NOWC | B9: ='Condensed Financials'!B59 | C9: ='Condensed Financials'!C59 | D9: ='Condensed Financials'!D59 | E9: ='Condensed Financials'!E59 | F9: ='Condensed Financials'!F59
A11: OWCA / Revenue
A12: OWCL / Revenue
A13: NOWC / Revenue
A14: Change in Revenue | B14: N/A
A15: Change in NOWC | B15: N/A
A16: Incremental NOWC / Change in Revenue | B16: N/A
A18: WORKING-CAPITAL DRIVER DECOMPOSITION
A19: Change in OWCA | B19: N/A
A20: Change in OWCL | B20: N/A
A21: Change in NOWC from Components | B21: N/A
A22: Incremental OWCA / Change in Revenue | B22: N/A
A23: Incremental OWCL / Change in Revenue | B23: N/A
A24: DRIVER DECOMPOSITION CHECK | B24: N/A | C24: =IF(ABS(C21-C15)<0.01,"OK","CHECK") | D24: =IF(ABS(D21-D15)<0.01,"OK","CHECK") | E24: =IF(ABS(E21-E15)<0.01,"OK","CHECK") | F24: =IF(ABS(F21-F15)<0.01,"OK","CHECK")

Sheet Per Share Analysis
A1: FAST RETAILING CO., LTD. — Per Share Analysis
A2: Historical per-share diagnostics using supplied diluted weighted-average shares. Share counts are source inputs, not practice cells.
A4: Metric | B4: 44439 | C4: 44804 | D4: 45169 | E4: 45535 | F4: 45900
A5: Parent-Attributable Profit | B5: ='Income Statement'!B18 | C5: ='Income Statement'!C18 | D5: ='Income Statement'!D18 | E5: ='Income Statement'!E18 | F5: ='Income Statement'!F18
A6: NOPAT | B6: ='Condensed Financials'!B54 | C6: ='Condensed Financials'!C54 | D6: ='Condensed Financials'!D54 | E6: ='Condensed Financials'!E54 | F6: ='Condensed Financials'!F54
A7: Diluted Weighted-Average Shares | B7: 306.87178 | C7: 306.96962 | D7: 307.13887 | E7: 307.2318 | F7: 307.2478
A8: Share Basis: Split-adjusted comparable basis
A9: Diluted EPS (Comparable Basis)
A10: NOPAT per Diluted Share
A12: Change in Diluted EPS | B12: N/A
A13: Change in Diluted Weighted-Average Shares | B13: N/A
A15: DILUTED EPS CHANGE ATTRIBUTION
A16: Change in Per-Share Earnings Numerator | B16: N/A
A17: Earnings Effect on Change in Diluted EPS | B17: N/A
A18: Share-Count Effect on Change in Diluted EPS | B18: N/A
A19: Diluted EPS Change from Drivers | B19: N/A
A20: DILUTED EPS CHANGE ATTRIBUTION CHECK | B20: N/A | C20: =IF(ABS(C19-C12)<0.0000001,"OK","CHECK") | D20: =IF(ABS(D19-D12)<0.0000001,"OK","CHECK") | E20: =IF(ABS(E19-E12)<0.0000001,"OK","CHECK") | F20: =IF(ABS(F19-F12)<0.0000001,"OK","CHECK")

Sheet Model_Bear
A1: Deferred from historical-only v1

Sheet Model_Base
A1: Deferred from historical-only v1

Sheet Model_Bull
A1: Deferred from historical-only v1

Sheet Scenario_Summary
A1: Deferred from historical-only v1
