Workbook

Sheet Trainer
A1: BAV Excel Trainer
A2: Complete each historical model-construction and earnings-quality diagnostic formula schedule left-to-right in dependency order. Run Check to validate the yellow formula cells against the treatment currently selected in Accounting Judgment column F (blank F uses the supplied reference treatment). Generated Condensed Financials classification links are system-controlled and validated by Check—do not edit them or columns D:E. When Normalization Judgment is present, choose Recurring vs Non-recurring in column F (blank uses the supplied reference); Earnings Normalization formulas are checked against that choice. Also complete Accounting Judgment and Normalization Judgment rationale/consequence when cases are present; those responses are not graded by Check. Compare them with the matching Answer Key.
A4: Order | B4: Schedule | C4: Period scope | D4: Tab | E4: Practice cells | F4: Depends on
A5: 1 | B5: Revenue historical source link | C5: 2021–2025 (5 cells) | D5: Condensed Financials | E5: B44:F44 | F5: —
A6: 2 | B6: Net Income historical source link | C6: 2021–2025 (5 cells) | D6: Condensed Financials | E6: B45:F45 | F6: —
A7: 3 | B7: Effective tax rate | C7: 2021–2025 (5 cells) | D7: Condensed Financials | E7: B51:F51 | F7: —
A8: 4 | B8: Net interest | C8: 2021–2025 (5 cells) | D8: Condensed Financials | E8: B52:F52 | F8: —
A9: 5 | B9: Net interest after tax | C9: 2021–2025 (5 cells) | D9: Condensed Financials | E9: B53:F53 | F9: effective_tax_rate_fy, net_interest_fy
A10: 6 | B10: NOPAT | C10: 2021–2025 (5 cells) | D10: Condensed Financials | E10: B54:F54 | F10: net_income_link, net_interest_after_tax_fy
A11: 7 | B11: Operating working capital assets | C11: 2021–2025 (5 cells) | D11: Condensed Financials | E11: B57:F57 | F11: —
A12: 8 | B12: Operating working capital liabilities | C12: 2021–2025 (5 cells) | D12: Condensed Financials | E12: B58:F58 | F12: —
A13: 9 | B13: Net Operating Working Capital (NOWC) | C13: 2021–2025 (5 cells) | D13: Condensed Financials | E13: B59:F59 | F13: owca_agg, owcl_agg
A14: 10 | B14: Operating long-term assets | C14: 2021–2025 (5 cells) | D14: Condensed Financials | E14: B60:F60 | F14: —
A15: 11 | B15: Operating long-term liabilities | C15: 2021–2025 (5 cells) | D15: Condensed Financials | E15: B61:F61 | F15: —
A16: 12 | B16: Net operating long-term assets (NOLA) | C16: 2021–2025 (5 cells) | D16: Condensed Financials | E16: B62:F62 | F16: olta_agg, oltl_agg
... A119: 123 | B119: Lease Repayments / Revenue | C119: 2021–2025 (5 cells) | D119: ALT DuPont | E119: B83:F83 | F119: lease_repayments, revenue_link

Sheet Income Statement
A1: Company: FAST RETAILING CO., LTD. (6288.HK)
A2: Statement: Income Statement
A3: Units: JPY in Millions
A4: Source: manual ingestion (JP)
A6: Line Item | B6: 44439 | C6: 44804 | D6: 45169 | E6: 45535 | F6: 45900
A7: Basic (yen, dollar) | B7: 1663.12 | C7: 891.77 | D7: 966.09 | E7: 1212.88 | F7: 1411.44
A8: Cost of sales | B8: -1059036 | C8: -1094263 | D8: -1330196 | E8: -1430764 | F8: -1571681
A9: Diluted (yen, dollar) | B9: 1660.44 | C9: 890.43 | D9: 964.48 | E9: 1210.81 | F9: 1409.32
A10: Finance costs | B10: -6998 | C10: -7560 | D10: -9888 | E10: -11101 | F10: -12834
A11: Finance income | B11: 23859 | C11: 123820 | D11: 66716 | E11: 67399 | F11: 99143
A12: Gross profit | B12: 1073955 | C12: 1206859 | D12: 1436360 | E12: 1673071 | F12: 1828858
A13: Income tax expense | B13: -90188 | C13: -128834 | D13: -122746 | E13: -163596 | F13: -191421
A14: Non-controlling interests | B14: 5836 | C14: 11415 | D14: 18941 | E14: 21605 | F14: 26143
A15: Operating profit | B15: 249011 | C15: 297325 | D15: 381090 | E15: 500904 | F15: 564265
A16: Other expenses | B16: -25315 | C16: -27391 | D16: -14238 | E16: -6256 | F16: -8087
A17: Other income | B17: 18238 | C17: 16951 | D17: 12197 | E17: 20384 | F17: 19491
... A23: Share of profit of associates accounted for using the equity method | B23: 561 | C23: 1059 | D23: 1139 | E23: 1417 | F23: 1704
A25: SUPPLEMENTAL DISCLOSURES
A26: Lease interest expense (reported note) | B26: 4847 | C26: 4757 | D26: 5187 | E26: 6507 | F26: 8464

Sheet Balance Sheet
A1: Company: FAST RETAILING CO., LTD. (6288.HK)
A2: Statement: Balance Sheet
A3: Units: JPY in Millions
A4: Source: manual ingestion (JP)
A6: Line Item | B6: 44439 | C6: 44804 | D6: 45169 | E6: 45535 | F6: 45900
A7: Total assets | B7: 2509976 | C7: 3183762 | D7: 3303694 | E7: 3587565 | F7: 3859353
A8: Cash and cash equivalents | B8: 1177736 | C8: 1358292 | D8: 903280 | E8: 1193560 | F8: 893239
A9: Derivative financial assets | B9: 27103 | C9: 124551 | D9: 132101 | E9: 111658 | F9: 94803
A10: Income taxes receivable | B10: 2992 | C10: 2612 | D10: 23660 | E10: 2210 | F10: 8042
A11: Inventories | B11: 394868 | C11: 485928 | D11: 449254 | E11: 474460 | F11: 510958
A12: Other assets | B12: 15270 | C12: 23835 | D12: 25372 | E12: 26897 | F12: 24662
A13: Other financial assets | B13: 56157 | C13: 123446 | D13: 576194 | E13: 470554 | F13: 899701
A14: Total current assets | B14: 1724674 | C14: 2178851 | D14: 2176695 | E14: 2363271 | F14: 2527815
A15: Trade and other receivables | B15: 50546 | C15: 60184 | D15: 66831 | E15: 83929 | F15: 96407
A16: Current tax liabilities | B16: 38606 | C16: 77162 | D16: 65428 | E16: 65525 | F16: 73072
A17: Derivative financial liabilities | B17: 2493 | C17: 1513 | D17: 3600 | E17: 12716 | F17: 19250
... A50: Total non-current liabilities | B50: 766665 | C50: 692117 | D50: 701072 | E50: 666920 | F50: 620561

Sheet Cash Flow Statement
A1: Company: FAST RETAILING CO., LTD. (6288.HK)
A2: Statement: Cash Flow Statement
A3: Units: JPY in Millions
A4: Source: manual ingestion (JP)
A6: Line Item | B6: 44439 | C6: 44804 | D6: 45169 | E6: 45535 | F6: 45900
A7: (Increase)/decrease in inventories | B7: 36749 | C7: -50896 | D7: 46908 | E7: -23540 | F7: -29855
A8: (Increase)/decrease in other assets | B8: 3494 | C8: -7125 | D8: 8354 | E8: -876 | F8: -2479
A9: (Increase)/decrease in trade and other receivables | B9: 15334 | C9: -2651 | D9: -7535 | E9: -17394 | F9: -12718
A10: Amounts deposited into bank deposits with original maturities of three months or longer | B10: -102307 | C10: -143517 | D10: -387720 | E10: -441156 | F10: -1008113
A11: Amounts withdrawn from bank deposits with original maturities of three months or longer | B11: 99943 | C11: 126774 | D11: 182882 | E11: 460241 | F11: 798490
A12: Cash and cash equivalents at the beginning of year | B12: 1093531 | C12: 1177736 | D12: 1358292 | E12: 903280 | F12: 1193560
A13: Cash and cash equivalents at the end of year | B13: 1177736 | C13: 1358292 | D13: 903280 | E13: 1193560 | F13: 893239
A14: Cash generated from operations | B14: 509672 | C14: 518010 | D14: 610338 | E14: 739726 | F14: 728879
A15: Depreciation and amortization | B15: 177910 | C15: 180275 | D15: 186872 | E15: 204388 | F15: 216492
A16: Dividends paid to non-controlling interests | B16: -2342 | C16: -11623 | D16: -20460 | E16: -18369 | F16: -26428
A17: Dividends paid to owners of the Parent | B17: -48993 | C17: -53091 | D17: -73064 | E17: -104263 | F17: -142630
... A48: Share of (profit)/loss of associates accounted for using the equity method | B48: -561 | C48: -1059 | D48: -1139 | E48: -1417 | F48: -1704

Sheet Condensed Financials
A1: FAST RETAILING CO., LTD. (6288.HK) — Condensed Financials
A4: BALANCE SHEET CLASSIFICATION
A5: Line Item | B5: Classification | C5: 44439 | D5: 44804 | E5: 45169 | F5: 45535 | G5: 45900 | H5: Notes
A6: Cash and cash equivalents | B6: Financial Asset | C6: 1177736 | D6: 1358292 | E6: 903280 | F6: 1193560 | G6: 893239
A7: Derivative financial assets | B7: =IF('Accounting Judgment'!$F$5="","Financial Asset",'Accounting Judgment'!$F$5) | C7: 27103 | D7: 124551 | E7: 132101 | F7: 111658 | G7: 94803 | H7: ⚠ Review: Generic financial-asset concept — financial vs operating purpose/hedging judgment
A8: Income taxes receivable | B8: Operating Working Capital Asset | C8: 2992 | D8: 2612 | E8: 23660 | F8: 2210 | G8: 8042
A9: Inventories | B9: Operating Working Capital Asset | C9: 394868 | D9: 485928 | E9: 449254 | F9: 474460 | G9: 510958
A10: Other assets | B10: =IF('Accounting Judgment'!$F$6="","Operating Working Capital Asset",'Accounting Judgment'!$F$6) | C10: 15270 | D10: 23835 | E10: 25372 | F10: 26897 | G10: 24662 | H10: ⚠ Review: Explicit residual balance-sheet concept identifies side/horizon but not economic nature — operating vs financial judgment
A11: Other financial assets | B11: =IF('Accounting Judgment'!$F$7="","Financial Asset",'Accounting Judgment'!$F$7) | C11: 56157 | D11: 123446 | E11: 576194 | F11: 470554 | G11: 899701 | H11: ⚠ Review: Generic financial-asset concept — financial vs operating purpose/hedging judgment
A12: Trade and other receivables | B12: Operating Working Capital Asset | C12: 50546 | D12: 60184 | E12: 66831 | F12: 83929 | G12: 96407
A13: Current tax liabilities | B13: Operating Working Capital Liability | C13: 38606 | D13: 77162 | E13: 65428 | F13: 65525 | G13: 73072
A14: Derivative financial liabilities | B14: =IF('Accounting Judgment'!$F$8="","Financial Liability",'Accounting Judgment'!$F$8) | C14: 2493 | D14: 1513 | E14: 3600 | F14: 12716 | G14: 19250 | H14: ⚠ Review: Generic financial-liability concept — financial vs operating purpose/hedging judgment
A15: Lease liabilities | B15: =IF('Accounting Judgment'!$F$9="","Operating Long-Term Liability",'Accounting Judgment'!$F$9) | C15: 117083 | D15: 123885 | E15: 126992 | F15: 130744 | G15: 126830 | H15: ⚠ Review: Lease liability concept — operating vs financial judgment
A16: Other financial liabilities | B16: =IF('Accounting Judgment'!$F$10="","Financial Liability",'Accounting Judgment'!$F$10) | C16: 104969 | D16: 209286 | E16: 61913 | F16: 104770 | G16: 150942 | H16: ⚠ Review: Generic financial-liability concept — financial vs operating purpose/hedging judgment
A17: Other liabilities | B17: =IF('Accounting Judgment'!$F$11="","Operating Working Capital Liability",'Accounting Judgment'!$F$11) | C17: 95652 | D17: 111519 | E17: 129782 | F17: 148201 | G17: 149394 | H17: ⚠ Review: Explicit residual balance-sheet concept identifies side/horizon but not economic nature — operating vs financial judgment
A18: Provisions | B18: Operating Working Capital Liability | C18: 2149 | D18: 2581 | E18: 2642 | F18: 1774 | G18: 1651
A19: Trade and other payables | B19: Operating Working Capital Liability | C19: 220057 | D19: 350294 | E19: 338901 | F19: 388656 | G19: 390149
A20: Capital stock | B20: Equity | C20: 10273 | D20: 10273 | E20: 10273 | F20: 10273 | G20: 10273
A21: Capital surplus | B21: Equity | C21: 25360 | D21: 27834 | E21: 28531 | F21: 29712 | G21: 30998
A22: Equity attributable to owners of the Parent | B22: Equity | C22: 1116484 | D22: 1561652 | E22: 1821405 | F22: 2016535 | G22: 2273115
A23: Non-controlling interests | B23: Equity | C23: 45813 | D23: 53750 | E23: 51955 | F23: 51718 | G23: 54385
A24: Other components of equity | B24: Equity | C24: 41031 | D24: 263255 | E24: 298965 | F24: 225104 | G24: 189936
A25: Retained earnings | B25: Equity | C25: 1054791 | D25: 1275102 | E25: 1498348 | F25: 1766073 | G25: 2056437
A26: Treasury stock, at cost | B26: Equity | C26: -14973 | D26: -14813 | E26: -14714 | F26: -14628 | G26: -14529
A27: Deferred tax assets | B27: Operating Long-Term Asset | C27: 37125 | D27: 8506 | E27: 38208 | F27: 32432 | G27: 40889 | H27: ⚠ Review: Deferred tax asset concept — operating vs exclude judgment
A28: Derivative financial assets | B28: =IF('Accounting Judgment'!$F$12="","Financial Asset",'Accounting Judgment'!$F$12) | C28: 22552 | D28: 134240 | E28: 114151 | F28: 66995 | G28: 33882 | H28: ⚠ Review: Generic financial-asset concept — financial vs operating purpose/hedging judgment
A29: Financial assets | B29: =IF('Accounting Judgment'!$F$13="","Financial Asset",'Accounting Judgment'!$F$13) | C29: 67122 | D29: 164340 | E29: 240363 | F29: 336302 | G29: 312438 | H29: ⚠ Review: Generic financial-asset concept — financial vs operating purpose/hedging judgment
A30: Goodwill | B30: Operating Long-Term Asset | C30: 8092 | D30: 8092 | E30: 8092 | F30: 8092 | G30: 8092
A31: Intangible assets | B31: Operating Long-Term Asset | C31: 66939 | D31: 76621 | E31: 87300 | F31: 92568 | G31: 91606
A32: Investments in associates accounted for using the equity method | B32: =IF('Accounting Judgment'!$F$14="","Operating Long-Term Asset",'Accounting Judgment'!$F$14) | C32: 18236 | D32: 18557 | E32: 18974 | F32: 19559 | G32: 31361 | H32: ⚠ Review: Equity-method investment concept — operating vs financial judgment
A33: Other assets | B33: =IF('Accounting Judgment'!$F$15="","Operating Long-Term Asset",'Accounting Judgment'!$F$15) | C33: 6520 | D33: 3690 | E33: 8846 | F33: 5888 | G33: 3803 | H33: ⚠ Review: Explicit residual balance-sheet concept identifies side/horizon but not economic nature — operating vs financial judgment
A34: Property, plant and equipment | B34: Operating Long-Term Asset | C34: 168177 | D34: 195226 | E34: 221877 | F34: 245742 | G34: 332351
A35: Right-of-use assets | B35: Operating Long-Term Asset | C35: 390537 | D35: 395634 | E35: 389183 | F35: 416712 | G35: 477111 | H35: ⚠ Review: Lease/ROU asset concept — operating vs financial judgment
A36: Deferred tax liabilities | B36: Operating Long-Term Liability | C36: 9860 | D36: 44258 | E36: 67039 | F36: 31896 | G36: 22539 | H36: ⚠ Review: Deferred tax liability concept — operating vs exclude judgment
A37: Derivative financial liabilities | B37: =IF('Accounting Judgment'!$F$16="","Financial Liability",'Accounting Judgment'!$F$16) | C37: 1042 | D37: 44 | E37: 1410 | F37: 21385 | G37: 12110 | H37: ⚠ Review: Generic financial-liability concept — financial vs operating purpose/hedging judgment
A38: Financial liabilities | B38: =IF('Accounting Judgment'!$F$17="","Financial Liability",'Accounting Judgment'!$F$17) | C38: 370799 | D38: 241022 | E38: 241068 | F38: 211147 | G38: 141071 | H38: ⚠ Review: Generic financial-liability concept — financial vs operating purpose/hedging judgment
A39: Lease liabilities | B39: =IF('Accounting Judgment'!$F$18="","Operating Long-Term Liability",'Accounting Judgment'!$F$18) | C39: 343574 | D39: 356840 | E39: 338657 | F39: 347318 | G39: 386670 | H39: ⚠ Review: Lease liability concept — operating vs financial judgment
A40: Other liabilities | B40: =IF('Accounting Judgment'!$F$19="","Operating Long-Term Liability",'Accounting Judgment'!$F$19) | C40: 2342 | D40: 2171 | E40: 2007 | F40: 2521 | G40: 2457 | H40: ⚠ Review: Explicit residual balance-sheet concept identifies side/horizon but not economic nature — operating vs financial judgment
A41: Provisions | B41: Operating Long-Term Liability | C41: 39046 | D41: 47780 | E41: 50888 | F41: 52652 | G41: 55711
A43: CONDENSED INCOME STATEMENT | B43: 44439 | C43: 44804 | D43: 45169 | E43: 45535 | F43: 45900
...

Sheet ALT DuPont
A1: FAST RETAILING CO., LTD. — DuPont Decomposition
A2: ROE = RNOA + FLEV × Spread
A4: Metric | B4: 44439 | C4: 44804 | D4: 45169 | E4: 45535 | F4: 45900
A5: Sales Growth | B5: N/A | C5: =IF('Condensed Financials'!B44=0,NA(),'Condensed Financials'!C44/'Condensed Financials'!B44-1) | D5: =IF('Condensed Financials'!C44=0,NA(),'Condensed Financials'!D44/'Condensed Financials'!C44-1) | E5: =IF('Condensed Financials'!D44=0,NA(),'Condensed Financials'!E44/'Condensed Financials'!D44-1) | F5: =IF('Condensed Financials'!E44=0,NA(),'Condensed Financials'!F44/'Condensed Financials'!E44-1)
A6: NOPAT Margin | B6: =IF('Condensed Financials'!B44=0,NA(),'Condensed Financials'!B54/'Condensed Financials'!B44) | C6: =IF('Condensed Financials'!C44=0,NA(),'Condensed Financials'!C54/'Condensed Financials'!C44) | D6: =IF('Condensed Financials'!D44=0,NA(),'Condensed Financials'!D54/'Condensed Financials'!D44) | E6: =IF('Condensed Financials'!E44=0,NA(),'Condensed Financials'!E54/'Condensed Financials'!E44) | F6: =IF('Condensed Financials'!F44=0,NA(),'Condensed Financials'!F54/'Condensed Financials'!F44)
A7: RNOA | B7: N/A | C7: =IF((('Condensed Financials'!C63+'Condensed Financials'!B63)/2)=0,NA(),'Condensed Financials'!C54/(('Condensed Financials'!C63+'Condensed Financials'!B63)/2)) | D7: =IF((('Condensed Financials'!D63+'Condensed Financials'!C63)/2)=0,NA(),'Condensed Financials'!D54/(('Condensed Financials'!D63+'Condensed Financials'!C63)/2)) | E7: =IF((('Condensed Financials'!E63+'Condensed Financials'!D63)/2)=0,NA(),'Condensed Financials'!E54/(('Condensed Financials'!E63+'Condensed Financials'!D63)/2)) | F7: =IF((('Condensed Financials'!F63+'Condensed Financials'!E63)/2)=0,NA(),'Condensed Financials'!F54/(('Condensed Financials'!F63+'Condensed Financials'!E63)/2))
A8: After-tax CoD | B8: N/A | C8: =IF((('Condensed Financials'!C66+'Condensed Financials'!B66)/2)=0,NA(),'Condensed Financials'!C53/(('Condensed Financials'!C66+'Condensed Financials'!B66)/2)) | D8: =IF((('Condensed Financials'!D66+'Condensed Financials'!C66)/2)=0,NA(),'Condensed Financials'!D53/(('Condensed Financials'!D66+'Condensed Financials'!C66)/2)) | E8: =IF((('Condensed Financials'!E66+'Condensed Financials'!D66)/2)=0,NA(),'Condensed Financials'!E53/(('Condensed Financials'!E66+'Condensed Financials'!D66)/2)) | F8: =IF((('Condensed Financials'!F66+'Condensed Financials'!E66)/2)=0,NA(),'Condensed Financials'!F53/(('Condensed Financials'!F66+'Condensed Financials'!E66)/2))
A9: Spread | B9: N/A | C9: =C7-C8 | D9: =D7-D8 | E9: =E7-E8 | F9: =F7-F8
A10: FLEV | B10: N/A | C10: =IF((('Condensed Financials'!C67+'Condensed Financials'!B67)/2)=0,NA(),(('Condensed Financials'!C66+'Condensed Financials'!B66)/2)/(('Condensed Financials'!C67+'Condensed Financials'!B67)/2)) | D10: =IF((('Condensed Financials'!D67+'Condensed Financials'!C67)/2)=0,NA(),(('Condensed Financials'!D66+'Condensed Financials'!C66)/2)/(('Condensed Financials'!D67+'Condensed Financials'!C67)/2)) | E10: =IF((('Condensed Financials'!E67+'Condensed Financials'!D67)/2)=0,NA(),(('Condensed Financials'!E66+'Condensed Financials'!D66)/2)/(('Condensed Financials'!E67+'Condensed Financials'!D67)/2)) | F10: =IF((('Condensed Financials'!F67+'Condensed Financials'!E67)/2)=0,NA(),(('Condensed Financials'!F66+'Condensed Financials'!E66)/2)/(('Condensed Financials'!F67+'Condensed Financials'!E67)/2))
A11: ROE (decomposed) | B11: N/A | C11: =C7+C10*(C9) | D11: =D7+D10*(D9) | E11: =E7+E10*(E9) | F11: =F7+F10*(F9)
A12: Actual ROE | B12: N/A | C12: =IF((('Condensed Financials'!C67+'Condensed Financials'!B67)/2)=0,NA(),'Condensed Financials'!C45/(('Condensed Financials'!C67+'Condensed Financials'!B67)/2)) | D12: =IF((('Condensed Financials'!D67+'Condensed Financials'!C67)/2)=0,NA(),'Condensed Financials'!D45/(('Condensed Financials'!D67+'Condensed Financials'!C67)/2)) | E12: =IF((('Condensed Financials'!E67+'Condensed Financials'!D67)/2)=0,NA(),'Condensed Financials'!E45/(('Condensed Financials'!E67+'Condensed Financials'!D67)/2)) | F12: =IF((('Condensed Financials'!F67+'Condensed Financials'!E67)/2)=0,NA(),'Condensed Financials'!F45/(('Condensed Financials'!F67+'Condensed Financials'!E67)/2))
A14: RNOA DRIVER DECOMPOSITION
A15: Average NOA | B15: N/A | C15: =('Condensed Financials'!B63+'Condensed Financials'!C63)/2 | D15: =('Condensed Financials'!C63+'Condensed Financials'!D63)/2 | E15: =('Condensed Financials'!D63+'Condensed Financials'!E63)/2 | F15: =('Condensed Financials'!E63+'Condensed Financials'!F63)/2
A16: NOA Turnover | B16: N/A | C16: =IF(C15=0,NA(),'Condensed Financials'!C44/C15) | D16: =IF(D15=0,NA(),'Condensed Financials'!D44/D15) | E16: =IF(E15=0,NA(),'Condensed Financials'!E44/E15) | F16: =IF(F15=0,NA(),'Condensed Financials'!F44/F15)
A17: NOA Intensity | B17: N/A | C17: =IF('Condensed Financials'!C44=0,NA(),C15/'Condensed Financials'!C44) | D17: =IF('Condensed Financials'!D44=0,NA(),D15/'Condensed Financials'!D44) | E17: =IF('Condensed Financials'!E44=0,NA(),E15/'Condensed Financials'!E44) | F17: =IF('Condensed Financials'!F44=0,NA(),F15/'Condensed Financials'!F44)
A18: RNOA from Margin × Turnover | B18: N/A | C18: =C6*C16 | D18: =D6*D16 | E18: =E6*E16 | F18: =F6*F16
A19: RNOA DRIVER CHECK | B19: N/A | C19: =IF(ISNA(C18),"N/A",IF(ISNA(C7),"CHECK",IF(ABS(C18-C7)<0.0000001,"OK","CHECK"))) | D19: =IF(ISNA(D18),"N/A",IF(ISNA(D7),"CHECK",IF(ABS(D18-D7)<0.0000001,"OK","CHECK"))) | E19: =IF(ISNA(E18),"N/A",IF(ISNA(E7),"CHECK",IF(ABS(E18-E7)<0.0000001,"OK","CHECK"))) | F19: =IF(ISNA(F18),"N/A",IF(ISNA(F7),"CHECK",IF(ABS(F18-F7)<0.0000001,"OK","CHECK")))
A21: RNOA CHANGE ATTRIBUTION
A22: Change in NOPAT Margin | B22: N/A | C22: N/A | D22: =D6-C6 | E22: =E6-D6 | F22: =F6-E6
A23: Change in NOA Turnover | B23: N/A | C23: N/A | D23: =D16-C16 | E23: =E16-D16 | F23: =F16-E16
A24: Direct Change in RNOA | B24: N/A | C24: N/A | D24: =D7-C7 | E24: =E7-D7 | F24: =F7-E7
A25: Margin Effect on RNOA Change | B25: N/A | C25: N/A | D25: =D22*((D16+C16)/2) | E25: =E22*((E16+D16)/2) | F25: =F22*((F16+E16)/2)
A26: Turnover Effect on RNOA Change | B26: N/A | C26: N/A | D26: =D23*((D6+C6)/2) | E26: =E23*((E6+D6)/2) | F26: =F23*((F6+E6)/2)
A27: RNOA Change from Drivers | B27: N/A | C27: N/A | D27: =D25+D26 | E27: =E25+E26 | F27: =F25+F26
A28: RNOA CHANGE DRIVER CHECK | B28: N/A | C28: N/A | D28: =IF(OR(ISNA(D27),ISNA(D24)),"N/A",IF(ABS(D27-D24)<0.0000001,"OK","CHECK")) | E28: =IF(OR(ISNA(E27),ISNA(E24)),"N/A",IF(ABS(E27-E24)<0.0000001,"OK","CHECK")) | F28: =IF(OR(ISNA(F27),ISNA(F24)),"N/A",IF(ABS(F27-F24)<0.0000001,"OK","CHECK"))
A30: ROE OPERATING / FINANCING ATTRIBUTION
A31: Financing Contribution to ROE | B31: N/A | C31: =C10*C9 | D31: =D10*D9 | E31: =E10*E9 | F31: =F10*F9
A32: ROE LEVEL ATTRIBUTION CHECK | B32: N/A | C32: =IF(OR(ISNA(C7),ISNA(C31),ISNA(C11)),"N/A",IF(ABS(C7+C31-C11)<0.0000001,"OK","CHECK")) | D32: =IF(OR(ISNA(D7),ISNA(D31),ISNA(D11)),"N/A",IF(ABS(D7+D31-D11)<0.0000001,"OK","CHECK")) | E32: =IF(OR(ISNA(E7),ISNA(E31),ISNA(E11)),"N/A",IF(ABS(E7+E31-E11)<0.0000001,"OK","CHECK")) | F32: =IF(OR(ISNA(F7),ISNA(F31),ISNA(F11)),"N/A",IF(ABS(F7+F31-F11)<0.0000001,"OK","CHECK"))
A34: ROE CHANGE ATTRIBUTION
A35: Direct Change in Decomposed ROE | B35: N/A | C35: N/A | D35: =D11-C11 | E35: =E11-D11 | F35: =F11-E11
A36: Operating Effect on Change in ROE | B36: N/A | C36: N/A | D36: =D24 | E36: =E24 | F36: =F24
A37: Leverage Effect on Change in ROE | B37: N/A | C37: N/A | D37: =(D10-C10)*((D9+C9)/2) | E37: =(E10-D10)*((E9+D9)/2) | F37: =(F10-E10)*((F9+E9)/2)
A38: Spread Effect on Change in ROE | B38: N/A | C38: N/A | D38: =(D9-C9)*((D10+C10)/2) | E38: =(E9-D9)*((E10+D10)/2) | F38: =(F9-E9)*((F10+E10)/2)
A39: Financing Effect on Change in ROE | B39: N/A | C39: N/A | D39: =D37+D38 | E39: =E37+E38 | F39: =F37+F38
A40: Change in ROE from Drivers | B40: N/A | C40: N/A | D40: =D36+D39 | E40: =E36+E39 | F40: =F36+F39
A41: ROE CHANGE ATTRIBUTION CHECK | B41: N/A | C41: N/A | D41: =IF(OR(ISNA(D40),ISNA(D35)),"N/A",IF(ABS(D40-D35)<0.0000001,"OK","CHECK")) | E41: =IF(OR(ISNA(E40),ISNA(E35)),"N/A",IF(ABS(E40-E35)<0.0000001,"OK","CHECK")) | F41: =IF(OR(ISNA(F40),ISNA(F35)),"N/A",IF(ABS(F40-F35)<0.0000001,"OK","CHECK"))
A43: FIXED-ASSET INTENSITY CONTEXT
A44: Property, Plant & Equipment | B44: ='Balance Sheet'!B41 | C44: ='Balance Sheet'!C41 | D44: ='Balance Sheet'!D41 | E44: ='Balance Sheet'!E41 | F44: ='Balance Sheet'!F41
A45: Depreciation & Amortisation | B45: ='Cash Flow Statement'!B15 | C45: ='Cash Flow Statement'!C15 | D45: ='Cash Flow Statement'!D15 | E45: ='Cash Flow Statement'!E15 | F45: ='Cash Flow Statement'!F15
A46: Average PP&E | B46: N/A | C46: =(B44+C44)/2 | D46: =(C44+D44)/2 | E46: =(D44+E44)/2 | F46: =(E44+F44)/2
...

Sheet Accounting Judgment
A1: Accounting Judgment
A2: The supplied treatment is the model's reference treatment, not a universal accounting truth. Compare it with the listed alternative(s), choose the treatment you would defend, and explain the economic consequence.
A3: Choose a treatment in column F only. That choice drives the matching Condensed Financials classification and downstream historical schedules; leaving F blank uses the supplied reference treatment. Columns D:E are display context and must not be edited. Enter your rationale and economic consequence in G:H. Formula Check grades formula cells against the treatment currently selected in F and validates that the generated classification links remain intact; it does not grade the judgment response itself. Do not edit the linked Condensed Financials classification cell directly.
A4: Order | B4: Line item | C4: Topic | D4: Supplied reference treatment | E4: Alternative(s) to evaluate | F4: Treatment to defend | G4: Rationale | H4: Economic consequence
A5: 1 | B5: Derivative financial assets | C5: Current financial asset: financial vs operating | D5: Financial Asset | E5: Operating Working Capital Asset | F5: Financial Asset | G5: The reference model treats a generically disclosed current financial instrument as a financial asset absent evidence that it is integral to normal operations or an operating hedge. | H5: Financial-asset treatment lowers Net Debt; operating-WC treatment raises NOWC/NOA by the same balance. Implied equity is unchanged by the classification switch alone.
A6: 2 | B6: Other assets | C6: Other current asset: operating vs financial | D6: Operating Working Capital Asset | E6: Financial Asset | F6: Operating Working Capital Asset | G6: The residual current-asset concept proves balance-sheet side and horizon but not whether the balance is operating working capital or a financial asset in economic substance. | H6: Operating-WC treatment raises NOWC/NOA; financial-asset treatment lowers Net Debt by the same balance. Implied equity is unchanged by the classification switch alone.
A7: 3 | B7: Other financial assets | C7: Current financial asset: financial vs operating | D7: Financial Asset | E7: Operating Working Capital Asset | F7: Financial Asset | G7: The reference model treats a generically disclosed current financial instrument as a financial asset absent evidence that it is integral to normal operations or an operating hedge. | H7: Financial-asset treatment lowers Net Debt; operating-WC treatment raises NOWC/NOA by the same balance. Implied equity is unchanged by the classification switch alone.
A8: 4 | B8: Derivative financial liabilities | C8: Current financial liability: financial vs operating | D8: Financial Liability | E8: Operating Working Capital Liability | F8: Financial Liability | G8: The reference model treats a generically disclosed current financial instrument as a financial liability absent evidence that it is an operating payable or operating hedge. | H8: Financial-liability treatment raises Net Debt; operating-WC-liability treatment lowers NOWC/NOA by the same balance. Implied equity is unchanged by the classification switch alone.
A9: 5 | B9: Lease liabilities | C9: Lease liability operating vs financing | D9: Operating Long-Term Liability | E9: Financial Liability | F9: Operating Long-Term Liability | G9: The reference model keeps the liability in operating long-term liabilities under its current lease convention. Treating it as a financial liability is also defensible when the lease obligation is viewed as debt-like financing. | H9: Operating-liability treatment lowers NOLA/NOA; financial-liability treatment raises Net Debt by the same balance. Implied equity is unchanged from this classification switch alone, but RNOA versus FLEV/Spread interpretation changes.
A10: 6 | B10: Other financial liabilities | C10: Current financial liability: financial vs operating | D10: Financial Liability | E10: Operating Working Capital Liability | F10: Financial Liability | G10: The reference model treats a generically disclosed current financial instrument as a financial liability absent evidence that it is an operating payable or operating hedge. | H10: Financial-liability treatment raises Net Debt; operating-WC-liability treatment lowers NOWC/NOA by the same balance. Implied equity is unchanged by the classification switch alone.
A11: 7 | B11: Other liabilities | C11: Other current liability: operating vs financial | D11: Operating Working Capital Liability | E11: Financial Liability | F11: Operating Working Capital Liability | G11: The residual current-liability concept proves balance-sheet side and horizon but not whether the balance is an operating working-capital liability or a financial liability in economic substance. | H11: Operating-WC-liability treatment lowers NOWC/NOA; financial-liability treatment raises Net Debt by the same balance. Implied equity is unchanged by the classification switch alone.
A12: 8 | B12: Derivative financial assets | C12: Non-current financial asset: financial vs operating | D12: Financial Asset | E12: Operating Long-Term Asset | F12: Financial Asset | G12: The reference model treats a generically disclosed non-current financial instrument as a financial asset absent evidence that it is strategically or operationally required. | H12: Financial-asset treatment lowers Net Debt; operating-LT treatment raises NOLA/NOA by the same balance. Implied equity is unchanged by the classification switch alone.
A13: 9 | B13: Financial assets | C13: Non-current financial asset: financial vs operating | D13: Financial Asset | E13: Operating Long-Term Asset | F13: Financial Asset | G13: The reference model treats a generically disclosed non-current financial instrument as a financial asset absent evidence that it is strategically or operationally required. | H13: Financial-asset treatment lowers Net Debt; operating-LT treatment raises NOLA/NOA by the same balance. Implied equity is unchanged by the classification switch alone.
A14: 10 | B14: Investments in associates accounted for using the equity method | C14: Equity-method investment operating vs financing | D14: Operating Long-Term Asset | E14: Financial Asset | F14: Operating Long-Term Asset | G14: The reference model treats the investment as an operating long-term asset when it is viewed as strategically tied to the operating business. Financial-asset treatment is defensible when the holding is primarily non-operating/investment in nature. | H14: Operating-asset treatment raises NOLA/NOA; financial-asset treatment lowers Net Debt by the same balance. Implied equity is unchanged from this classification switch alone, but RNOA and leverage interpretation change.
A15: 11 | B15: Other assets | C15: Other non-current asset: operating vs financial | D15: Operating Long-Term Asset | E15: Financial Asset | F15: Operating Long-Term Asset | G15: The residual non-current-asset concept proves balance-sheet side and horizon but not whether the balance is an operating long-term asset or a financial asset in economic substance. | H15: Operating-LT treatment raises NOLA/NOA; financial-asset treatment lowers Net Debt by the same balance. Implied equity is unchanged by the classification switch alone.
A16: 12 | B16: Derivative financial liabilities | C16: Non-current financial liability: financial vs operating | D16: Financial Liability | E16: Operating Long-Term Liability | F16: Financial Liability | G16: The reference model treats a generically disclosed non-current financial instrument as a financial liability absent evidence that it is an operating long-term obligation or operating hedge. | H16: Financial-liability treatment raises Net Debt; operating-LT-liability treatment lowers NOLA/NOA by the same balance. Implied equity is unchanged by the classification switch alone.
... A19: 15 | B19: Other liabilities | C19: Other non-current liability: operating vs financial | D19: Operating Long-Term Liability | E19: Financial Liability | F19: Operating Long-Term Liability | G19: The residual non-current-liability concept proves balance-sheet side and horizon but not whether the balance is an operating long-term liability or a financial liability in economic substance. | H19: Operating-LT-liability treatment lowers NOLA/NOA; financial-liability treatment raises Net Debt by the same balance. Implied equity is unchanged by the classification switch alone.

Sheet Ownership Attribution
A1: FAST RETAILING CO., LTD. — Ownership Attribution
A2: Parent / NCI profit and equity bridges and parent ROE. Consolidated DuPont / NOA / Net Debt remain unchanged; parent ROE is a separate shareholder-attribution diagnostic.
A4: Metric | B4: 44439 | C4: 44804 | D4: 45169 | E4: 45535 | F4: 45900
A5: Parent Profit | B5: ='Income Statement'!B18 | C5: ='Income Statement'!C18 | D5: ='Income Statement'!D18 | E5: ='Income Statement'!E18 | F5: ='Income Statement'!F18
A6: NCI Profit | B6: ='Income Statement'!B14 | C6: ='Income Statement'!C14 | D6: ='Income Statement'!D14 | E6: ='Income Statement'!E14 | F6: ='Income Statement'!F14
A7: Total Profit | B7: ='Income Statement'!B20 | C7: ='Income Statement'!C20 | D7: ='Income Statement'!D20 | E7: ='Income Statement'!E20 | F7: ='Income Statement'!F20
A8: Profit Attribution Gap | B8: =B5+B6-B7 | C8: =C5+C6-C7 | D8: =D5+D6-D7 | E8: =E5+E6-E7 | F8: =F5+F6-F7
A10: Parent Equity | B10: ='Balance Sheet'!B26 | C10: ='Balance Sheet'!C26 | D10: ='Balance Sheet'!D26 | E10: ='Balance Sheet'!E26 | F10: ='Balance Sheet'!F26
A11: NCI Equity | B11: ='Balance Sheet'!B27 | C11: ='Balance Sheet'!C27 | D11: ='Balance Sheet'!D27 | E11: ='Balance Sheet'!E27 | F11: ='Balance Sheet'!F27
A12: Total Equity | B12: ='Balance Sheet'!B30 | C12: ='Balance Sheet'!C30 | D12: ='Balance Sheet'!D30 | E12: ='Balance Sheet'!E30 | F12: ='Balance Sheet'!F30
A13: Equity Attribution Gap | B13: =B10+B11-B12 | C13: =C10+C11-C12 | D13: =D10+D11-D12 | E13: =E10+E11-E12 | F13: =F10+F11-F12
A15: Parent ROE | B15: N/A | C15: =IF((C10+B10)=0,NA(),C5/((C10+B10)/2)) | D15: =IF((D10+C10)=0,NA(),D5/((D10+C10)/2)) | E15: =IF((E10+D10)=0,NA(),E5/((E10+D10)/2)) | F15: =IF((F10+E10)=0,NA(),F5/((F10+E10)/2))

Sheet Earnings Quality
A1: FAST RETAILING CO., LTD. — Earnings Quality
A2: Historical cash-conversion and accrual diagnostics. These are mechanical diagnostics, not an automatic quality score.
A4: Metric | B4: 44439 | C4: 44804 | D4: 45169 | E4: 45535 | F4: 45900
A5: Operating Cash Flow | B5: ='Cash Flow Statement'!B30 | C5: ='Cash Flow Statement'!C30 | D5: ='Cash Flow Statement'!D30 | E5: ='Cash Flow Statement'!E30 | F5: ='Cash Flow Statement'!F30
A6: Reported Net Income | B6: ='Condensed Financials'!B45 | C6: ='Condensed Financials'!C45 | D6: ='Condensed Financials'!D45 | E6: ='Condensed Financials'!E45 | F6: ='Condensed Financials'!F45
A7: Cash Conversion Ratio | B7: =IF(B6=0,NA(),B5/B6) | C7: =IF(C6=0,NA(),C5/C6) | D7: =IF(D6=0,NA(),D5/D6) | E7: =IF(E6=0,NA(),E5/E6) | F7: =IF(F6=0,NA(),F5/F6)
A8: Total Accruals (Net Income - CFO) | B8: =B6-B5 | C8: =C6-C5 | D8: =D6-D5 | E8: =E6-E5 | F8: =F6-F5
A10: Total Assets | B10: ='Balance Sheet'!B7 | C10: ='Balance Sheet'!C7 | D10: ='Balance Sheet'!D7 | E10: ='Balance Sheet'!E7 | F10: ='Balance Sheet'!F7
A11: Average Total Assets | C11: =(B10+C10)/2 | D11: =(C10+D10)/2 | E11: =(D10+E10)/2 | F11: =(E10+F10)/2
A12: Accrual Ratio | C12: =IF(C11=0,NA(),C8/C11) | D12: =IF(D11=0,NA(),D8/D11) | E12: =IF(E11=0,NA(),E8/E11) | F12: =IF(F11=0,NA(),F8/F11)
A14: EARNINGS QUALITY TREND DIAGNOSTICS
A15: Change in Operating Cash Flow | B15: N/A | C15: =C5-B5 | D15: =D5-C5 | E15: =E5-D5 | F15: =F5-E5
A16: Change in Cash Conversion Ratio | B16: N/A | C16: =C7-B7 | D16: =D7-C7 | E16: =E7-D7 | F16: =F7-E7
A17: Change in Total Accruals | B17: N/A | C17: =C8-B8 | D17: =D8-C8 | E17: =E8-D8 | F17: =F8-E8
A18: Change in Accrual Ratio | B18: N/A | C18: N/A | D18: =D12-C12 | E18: =E12-D12 | F18: =F12-E12
A19: EARNINGS QUALITY CHANGE CHECK | B19: N/A | C19: =IF(ABS(C17-((C6-B6)-C15))<0.01,"OK","CHECK") | D19: =IF(ABS(D17-((D6-C6)-D15))<0.01,"OK","CHECK") | E19: =IF(ABS(E17-((E6-D6)-E15))<0.01,"OK","CHECK") | F19: =IF(ABS(F17-((F6-E6)-F15))<0.01,"OK","CHECK")

Sheet Working Capital Analysis
A1: Working Capital Analysis
A2: Relate classified operating working capital to Revenue and identify how much incremental NOWC accompanies changes in sales.
A3: These are diagnostics, not automatic judgments. Positive Change in NOWC is an operating cash use; negative Change in NOWC is a release. Annual data alone does not prove seasonality or deterioration.
A5: Metric | B5: 44439 | C5: 44804 | D5: 45169 | E5: 45535 | F5: 45900
A6: Revenue | B6: ='Condensed Financials'!B44 | C6: ='Condensed Financials'!C44 | D6: ='Condensed Financials'!D44 | E6: ='Condensed Financials'!E44 | F6: ='Condensed Financials'!F44
A7: Operating Working Capital Assets | B7: ='Condensed Financials'!B57 | C7: ='Condensed Financials'!C57 | D7: ='Condensed Financials'!D57 | E7: ='Condensed Financials'!E57 | F7: ='Condensed Financials'!F57
A8: Operating Working Capital Liabilities | B8: ='Condensed Financials'!B58 | C8: ='Condensed Financials'!C58 | D8: ='Condensed Financials'!D58 | E8: ='Condensed Financials'!E58 | F8: ='Condensed Financials'!F58
A9: NOWC | B9: ='Condensed Financials'!B59 | C9: ='Condensed Financials'!C59 | D9: ='Condensed Financials'!D59 | E9: ='Condensed Financials'!E59 | F9: ='Condensed Financials'!F59
A11: OWCA / Revenue | B11: =IF(B6=0,NA(),B7/B6) | C11: =IF(C6=0,NA(),C7/C6) | D11: =IF(D6=0,NA(),D7/D6) | E11: =IF(E6=0,NA(),E7/E6) | F11: =IF(F6=0,NA(),F7/F6)
A12: OWCL / Revenue | B12: =IF(B6=0,NA(),B8/B6) | C12: =IF(C6=0,NA(),C8/C6) | D12: =IF(D6=0,NA(),D8/D6) | E12: =IF(E6=0,NA(),E8/E6) | F12: =IF(F6=0,NA(),F8/F6)
A13: NOWC / Revenue | B13: =IF(B6=0,NA(),B9/B6) | C13: =IF(C6=0,NA(),C9/C6) | D13: =IF(D6=0,NA(),D9/D6) | E13: =IF(E6=0,NA(),E9/E6) | F13: =IF(F6=0,NA(),F9/F6)
A14: Change in Revenue | B14: N/A | C14: =C6-B6 | D14: =D6-C6 | E14: =E6-D6 | F14: =F6-E6
A15: Change in NOWC | B15: N/A | C15: =C9-B9 | D15: =D9-C9 | E15: =E9-D9 | F15: =F9-E9
A16: Incremental NOWC / Change in Revenue | B16: N/A | C16: =IF(C14=0,NA(),C15/C14) | D16: =IF(D14=0,NA(),D15/D14) | E16: =IF(E14=0,NA(),E15/E14) | F16: =IF(F14=0,NA(),F15/F14)
A18: WORKING-CAPITAL DRIVER DECOMPOSITION
A19: Change in OWCA | B19: N/A | C19: =C7-B7 | D19: =D7-C7 | E19: =E7-D7 | F19: =F7-E7
A20: Change in OWCL | B20: N/A | C20: =C8-B8 | D20: =D8-C8 | E20: =E8-D8 | F20: =F8-E8
A21: Change in NOWC from Components | B21: N/A | C21: =C19-C20 | D21: =D19-D20 | E21: =E19-E20 | F21: =F19-F20
A22: Incremental OWCA / Change in Revenue | B22: N/A | C22: =IF(C14=0,NA(),C19/C14) | D22: =IF(D14=0,NA(),D19/D14) | E22: =IF(E14=0,NA(),E19/E14) | F22: =IF(F14=0,NA(),F19/F14)
A23: Incremental OWCL / Change in Revenue | B23: N/A | C23: =IF(C14=0,NA(),C20/C14) | D23: =IF(D14=0,NA(),D20/D14) | E23: =IF(E14=0,NA(),E20/E14) | F23: =IF(F14=0,NA(),F20/F14)
A24: DRIVER DECOMPOSITION CHECK | B24: N/A | C24: =IF(ABS(C21-C15)<0.01,"OK","CHECK") | D24: =IF(ABS(D21-D15)<0.01,"OK","CHECK") | E24: =IF(ABS(E21-E15)<0.01,"OK","CHECK") | F24: =IF(ABS(F21-F15)<0.01,"OK","CHECK")

Sheet Per Share Analysis
A1: FAST RETAILING CO., LTD. — Per Share Analysis
A2: Historical per-share diagnostics using supplied diluted weighted-average shares. Share counts are source inputs, not practice cells.
A4: Metric | B4: 44439 | C4: 44804 | D4: 45169 | E4: 45535 | F4: 45900
A5: Parent-Attributable Profit | B5: ='Income Statement'!B18 | C5: ='Income Statement'!C18 | D5: ='Income Statement'!D18 | E5: ='Income Statement'!E18 | F5: ='Income Statement'!F18
A6: NOPAT | B6: ='Condensed Financials'!B54 | C6: ='Condensed Financials'!C54 | D6: ='Condensed Financials'!D54 | E6: ='Condensed Financials'!E54 | F6: ='Condensed Financials'!F54
A7: Diluted Weighted-Average Shares | B7: 306.87178 | C7: 306.96962 | D7: 307.13887 | E7: 307.2318 | F7: 307.2478
A8: Share Basis: Split-adjusted comparable basis
A9: Diluted EPS (Comparable Basis) | B9: =IF(B7<=0,NA(),B5/B7) | C9: =IF(C7<=0,NA(),C5/C7) | D9: =IF(D7<=0,NA(),D5/D7) | E9: =IF(E7<=0,NA(),E5/E7) | F9: =IF(F7<=0,NA(),F5/F7)
A10: NOPAT per Diluted Share | B10: =IF(B7<=0,NA(),B6/B7) | C10: =IF(C7<=0,NA(),C6/C7) | D10: =IF(D7<=0,NA(),D6/D7) | E10: =IF(E7<=0,NA(),E6/E7) | F10: =IF(F7<=0,NA(),F6/F7)
A12: Change in Diluted EPS | B12: N/A | C12: =C9-B9 | D12: =D9-C9 | E12: =E9-D9 | F12: =F9-E9
A13: Change in Diluted Weighted-Average Shares | B13: N/A | C13: =C7-B7 | D13: =D7-C7 | E13: =E7-D7 | F13: =F7-E7
A15: DILUTED EPS CHANGE ATTRIBUTION
A16: Change in Per-Share Earnings Numerator | B16: N/A | C16: =C5-B5 | D16: =D5-C5 | E16: =E5-D5 | F16: =F5-E5
A17: Earnings Effect on Change in Diluted EPS | B17: N/A | C17: =C16*((1/C7+1/B7)/2) | D17: =D16*((1/D7+1/C7)/2) | E17: =E16*((1/E7+1/D7)/2) | F17: =F16*((1/F7+1/E7)/2)
A18: Share-Count Effect on Change in Diluted EPS | B18: N/A | C18: =((1/C7)-(1/B7))*((C5+B5)/2) | D18: =((1/D7)-(1/C7))*((D5+C5)/2) | E18: =((1/E7)-(1/D7))*((E5+D5)/2) | F18: =((1/F7)-(1/E7))*((F5+E5)/2)
A19: Diluted EPS Change from Drivers | B19: N/A | C19: =C17+C18 | D19: =D17+D18 | E19: =E17+E18 | F19: =F17+F18
A20: DILUTED EPS CHANGE ATTRIBUTION CHECK | B20: N/A | C20: =IF(ABS(C19-C12)<0.0000001,"OK","CHECK") | D20: =IF(ABS(D19-D12)<0.0000001,"OK","CHECK") | E20: =IF(ABS(E19-E12)<0.0000001,"OK","CHECK") | F20: =IF(ABS(F19-F12)<0.0000001,"OK","CHECK")

Sheet Model_Bear
A1: Deferred from historical-only v1

Sheet Model_Base
A1: Deferred from historical-only v1

Sheet Model_Bull
A1: Deferred from historical-only v1

Sheet Scenario_Summary
A1: Deferred from historical-only v1

Sheet _ComponentMap
A1: id | B1: order | C1: title | D1: short_hint | E1: semantic_key | F1: category | G1: tab | H1: cell | I1: formula | J1: expected_value | K1: tolerance | L1: depends_on | M1: hints | N1: related_cells | O1: status | P1: family_id | Q1: family_order | R1: period_index | S1: period_end
A2: revenue_link__20210831 | B2: 1 | C2: Revenue historical source link | D2: Link Revenue from the Income Statement into Condensed Financials. | E2: condensed.revenue_link.2021-08-31 | F2: accounting | G2: Condensed Financials | H2: B44 | I2: ='Income Statement'!B21 | J2: 2132992 | K2: 0.01 | M2: Pull the Revenue line from the Income Statement for the same fiscal period. | O2: pending | P2: revenue_link | Q2: 1 | R2: 0 | S2: 2021-08-31
A3: revenue_link__20220831 | B3: 2 | C3: Revenue historical source link | D3: Link Revenue from the Income Statement into Condensed Financials. | E3: condensed.revenue_link.2022-08-31 | F3: accounting | G3: Condensed Financials | H3: C44 | I3: ='Income Statement'!C21 | J3: 2301122 | K3: 0.01 | M3: Pull the Revenue line from the Income Statement for the same fiscal period. | O3: pending | P3: revenue_link | Q3: 1 | R3: 1 | S3: 2022-08-31
A4: revenue_link__20230831 | B4: 3 | C4: Revenue historical source link | D4: Link Revenue from the Income Statement into Condensed Financials. | E4: condensed.revenue_link.2023-08-31 | F4: accounting | G4: Condensed Financials | H4: D44 | I4: ='Income Statement'!D21 | J4: 2766557 | K4: 0.01 | M4: Pull the Revenue line from the Income Statement for the same fiscal period. | O4: pending | P4: revenue_link | Q4: 1 | R4: 2 | S4: 2023-08-31
A5: revenue_link__20240831 | B5: 4 | C5: Revenue historical source link | D5: Link Revenue from the Income Statement into Condensed Financials. | E5: condensed.revenue_link.2024-08-31 | F5: accounting | G5: Condensed Financials | H5: E44 | I5: ='Income Statement'!E21 | J5: 3103836 | K5: 0.01 | M5: Pull the Revenue line from the Income Statement for the same fiscal period. | O5: pending | P5: revenue_link | Q5: 1 | R5: 3 | S5: 2024-08-31
A6: revenue_link__20250831 | B6: 5 | C6: Revenue historical source link | D6: Link Revenue from the Income Statement into Condensed Financials. | E6: condensed.revenue_link.2025-08-31 | F6: accounting | G6: Condensed Financials | H6: F44 | I6: ='Income Statement'!F21 | J6: 3400539 | K6: 0.01 | M6: Pull the Revenue line from the Income Statement for the same fiscal period. | O6: pending | P6: revenue_link | Q6: 1 | R6: 4 | S6: 2025-08-31
A7: net_income_link__20210831 | B7: 6 | C7: Net Income historical source link | D7: Link Net Income from the Income Statement into Condensed Financials. | E7: condensed.net_income_link.2021-08-31 | F7: accounting | G7: Condensed Financials | H7: B45 | I7: ='Income Statement'!B20 | J7: 175684 | K7: 0.01 | M7: Pull Net Income from the Income Statement for the same fiscal period. | O7: pending | P7: net_income_link | Q7: 2 | R7: 0 | S7: 2021-08-31
A8: net_income_link__20220831 | B8: 7 | C8: Net Income historical source link | D8: Link Net Income from the Income Statement into Condensed Financials. | E8: condensed.net_income_link.2022-08-31 | F8: accounting | G8: Condensed Financials | H8: C45 | I8: ='Income Statement'!C20 | J8: 284750 | K8: 0.01 | M8: Pull Net Income from the Income Statement for the same fiscal period. | O8: pending | P8: net_income_link | Q8: 2 | R8: 1 | S8: 2022-08-31
A9: net_income_link__20230831 | B9: 8 | C9: Net Income historical source link | D9: Link Net Income from the Income Statement into Condensed Financials. | E9: condensed.net_income_link.2023-08-31 | F9: accounting | G9: Condensed Financials | H9: D45 | I9: ='Income Statement'!D20 | J9: 315171 | K9: 0.01 | M9: Pull Net Income from the Income Statement for the same fiscal period. | O9: pending | P9: net_income_link | Q9: 2 | R9: 2 | S9: 2023-08-31
A10: net_income_link__20240831 | B10: 9 | C10: Net Income historical source link | D10: Link Net Income from the Income Statement into Condensed Financials. | E10: condensed.net_income_link.2024-08-31 | F10: accounting | G10: Condensed Financials | H10: E45 | I10: ='Income Statement'!E20 | J10: 393605 | K10: 0.01 | M10: Pull Net Income from the Income Statement for the same fiscal period. | O10: pending | P10: net_income_link | Q10: 2 | R10: 3 | S10: 2024-08-31
A11: net_income_link__20250831 | B11: 10 | C11: Net Income historical source link | D11: Link Net Income from the Income Statement into Condensed Financials. | E11: condensed.net_income_link.2025-08-31 | F11: accounting | G11: Condensed Financials | H11: F45 | I11: ='Income Statement'!F20 | J11: 459153 | K11: 0.01 | M11: Pull Net Income from the Income Statement for the same fiscal period. | O11: pending | P11: net_income_link | Q11: 2 | R11: 4 | S11: 2025-08-31
A12: effective_tax_rate_fy__20210831 | B12: 11 | C12: Effective tax rate | D12: Relate tax expense to pretax income using the model's sign convention. | E12: condensed.effective_tax_rate.2021-08-31 | F12: accounting | G12: Condensed Financials | H12: B51 | I12: =IF(B46=0,NA(),-B47/B46) | J12: 0.33921586 | K12: 0.01 | M12: Effective tax rate uses pretax income in the denominator.|Preserve the model's sign convention for tax expense.|A zero Pretax Income makes Effective Tax Rate undefined (#N/A). | O12: pending | P12: effective_tax_rate_fy | Q12: 3 | R12: 0 | S12: 2021-08-31
A13: effective_tax_rate_fy__20220831 | B13: 12 | C13: Effective tax rate | D13: Relate tax expense to pretax income using the model's sign convention. | E13: condensed.effective_tax_rate.2022-08-31 | F13: accounting | G13: Condensed Financials | H13: C51 | I13: =IF(C46=0,NA(),-C47/C46) | J13: 0.31150625 | K13: 0.01 | M13: Effective tax rate uses pretax income in the denominator.|Preserve the model's sign convention for tax expense.|A zero Pretax Income makes Effective Tax Rate undefined (#N/A). | O13: pending | P13: effective_tax_rate_fy | Q13: 3 | R13: 1 | S13: 2022-08-31
A14: effective_tax_rate_fy__20230831 | B14: 13 | C14: Effective tax rate | D14: Relate tax expense to pretax income using the model's sign convention. | E14: condensed.effective_tax_rate.2023-08-31 | F14: accounting | G14: Condensed Financials | H14: D51 | I14: =IF(D46=0,NA(),-D47/D46) | J14: 0.28029448 | K14: 0.01 | M14: Effective tax rate uses pretax income in the denominator.|Preserve the model's sign convention for tax expense.|A zero Pretax Income makes Effective Tax Rate undefined (#N/A). | O14: pending | P14: effective_tax_rate_fy | Q14: 3 | R14: 2 | S14: 2023-08-31
A15: effective_tax_rate_fy__20240831 | B15: 14 | C15: Effective tax rate | D15: Relate tax expense to pretax income using the model's sign convention. | E15: condensed.effective_tax_rate.2024-08-31 | F15: accounting | G15: Condensed Financials | H15: E51 | I15: =IF(E46=0,NA(),-E47/E46) | J15: 0.29360321 | K15: 0.01 | M15: Effective tax rate uses pretax income in the denominator.|Preserve the model's sign convention for tax expense.|A zero Pretax Income makes Effective Tax Rate undefined (#N/A). | O15: pending | P15: effective_tax_rate_fy | Q15: 3 | R15: 3 | S15: 2024-08-31
A16: effective_tax_rate_fy__20250831 | B16: 15 | C16: Effective tax rate | D16: Relate tax expense to pretax income using the model's sign convention. | E16: condensed.effective_tax_rate.2025-08-31 | F16: accounting | G16: Condensed Financials | H16: F51 | I16: =IF(F46=0,NA(),-F47/F46) | J16: 0.29423401 | K16: 0.01 | M16: Effective tax rate uses pretax income in the denominator.|Preserve the model's sign convention for tax expense.|A zero Pretax Income makes Effective Tax Rate undefined (#N/A). | O16: pending | P16: effective_tax_rate_fy | Q16: 3 | R16: 4 | S16: 2025-08-31
A17: net_interest_fy__20210831 | B17: 16 | C17: Net interest | D17: Combine interest expense and interest income into the financing result. | E17: condensed.net_interest.2021-08-31 | F17: accounting | G17: Condensed Financials | H17: B52 | I17: =-(B48+B49)-IF(AND($B$15="Operating Long-Term Liability",$B$39="Operating Long-Term Liability"),B50,IF(AND($B$15="Financial Liability",$B$39="Financial Liability"),0,NA())) | J17: -21708 | K17: 0.01 | M17: Net interest consolidates interest expense and interest income.|Use the explicitly supplied Interest Expense and Interest Income lines with the model's sign convention. | O17: pending | P17: net_interest_fy | Q17: 4 | R17: 0 | S17: 2021-08-31
A18: net_interest_fy__20220831 | B18: 17 | C18: Net interest | D18: Combine interest expense and interest income into the financing result. | E18: condensed.net_interest.2022-08-31 | F18: accounting | G18: Condensed Financials | H18: C52 | I18: =-(C48+C49)-IF(AND($B$15="Operating Long-Term Liability",$B$39="Operating Long-Term Liability"),C50,IF(AND($B$15="Financial Liability",$B$39="Financial Liability"),0,NA())) | J18: -121017 | K18: 0.01 | M18: Net interest consolidates interest expense and interest income.|Use the explicitly supplied Interest Expense and Interest Income lines with the model's sign convention. | O18: pending | P18: net_interest_fy | Q18: 4 | R18: 1 | S18: 2022-08-31
A19: net_interest_fy__20230831 | B19: 18 | C19: Net interest | D19: Combine interest expense and interest income into the financing result. | E19: condensed.net_interest.2023-08-31 | F19: accounting | G19: Condensed Financials | H19: D52 | I19: =-(D48+D49)-IF(AND($B$15="Operating Long-Term Liability",$B$39="Operating Long-Term Liability"),D50,IF(AND($B$15="Financial Liability",$B$39="Financial Liability"),0,NA())) | J19: -62015 | K19: 0.01 | M19: Net interest consolidates interest expense and interest income.|Use the explicitly supplied Interest Expense and Interest Income lines with the model's sign convention. | O19: pending | P19: net_interest_fy | Q19: 4 | R19: 2 | S19: 2023-08-31
A20: net_interest_fy__20240831 | B20: 19 | C20: Net interest | D20: Combine interest expense and interest income into the financing result. | E20: condensed.net_interest.2024-08-31 | F20: accounting | G20: Condensed Financials | H20: E52 | I20: =-(E48+E49)-IF(AND($B$15="Operating Long-Term Liability",$B$39="Operating Long-Term Liability"),E50,IF(AND($B$15="Financial Liability",$B$39="Financial Liability"),0,NA())) | J20: -62805 | K20: 0.01 | M20: Net interest consolidates interest expense and interest income.|Use the explicitly supplied Interest Expense and Interest Income lines with the model's sign convention. | O20: pending | P20: net_interest_fy | Q20: 4 | R20: 3 | S20: 2024-08-31
A21: net_interest_fy__20250831 | B21: 20 | C21: Net interest | D21: Combine interest expense and interest income into the financing result. | E21: condensed.net_interest.2025-08-31 | F21: accounting | G21: Condensed Financials | H21: F52 | I21: =-(F48+F49)-IF(AND($B$15="Operating Long-Term Liability",$B$39="Operating Long-Term Liability"),F50,IF(AND($B$15="Financial Liability",$B$39="Financial Liability"),0,NA())) | J21: -94773 | K21: 0.01 | M21: Net interest consolidates interest expense and interest income.|Use the explicitly supplied Interest Expense and Interest Income lines with the model's sign convention. | O21: pending | P21: net_interest_fy | Q21: 4 | R21: 4 | S21: 2025-08-31
A22: net_interest_after_tax_fy__20210831 | B22: 21 | C22: Net interest after tax | D22: Apply the effective tax rate once to net interest. | E22: condensed.net_interest_after_tax.2021-08-31 | F22: accounting | G22: Condensed Financials | H22: B53 | I22: =IF(B52=0,0,IF(ISNA(B51),NA(),B52*(1-B51))) | J22: -14344.302 | K22: 0.01 | L22: effective_tax_rate_fy__20210831,net_interest_fy__20210831 | M22: After-tax net interest = Net Interest × (1 − Effective Tax Rate).|Do not tax-adjust a rate that is already after tax.|A zero Net Interest amount remains zero even if ETR is undefined; otherwise undefined ETR propagates. | O22: pending | P22: net_interest_after_tax_fy | Q22: 5 | R22: 0 | S22: 2021-08-31
A23: net_interest_after_tax_fy__20220831 | B23: 22 | C23: Net interest after tax | D23: Apply the effective tax rate once to net interest. | E23: condensed.net_interest_after_tax.2022-08-31 | F23: accounting | G23: Condensed Financials | H23: C53 | I23: =IF(C52=0,0,IF(ISNA(C51),NA(),C52*(1-C51))) | J23: -83319.448 | K23: 0.01 | L23: effective_tax_rate_fy__20220831,net_interest_fy__20220831 | M23: After-tax net interest = Net Interest × (1 − Effective Tax Rate).|Do not tax-adjust a rate that is already after tax.|A zero Net Interest amount remains zero even if ETR is undefined; otherwise undefined ETR propagates. | O23: pending | P23: net_interest_after_tax_fy | Q23: 5 | R23: 1 | S23: 2022-08-31
A24: net_interest_after_tax_fy__20230831 | B24: 23 | C24: Net interest after tax | D24: Apply the effective tax rate once to net interest. | E24: condensed.net_interest_after_tax.2023-08-31 | F24: accounting | G24: Condensed Financials | H24: D53 | I24: =IF(D52=0,0,IF(ISNA(D51),NA(),D52*(1-D51))) | J24: -44632.538 | K24: 0.01 | L24: effective_tax_rate_fy__20230831,net_interest_fy__20230831 | M24: After-tax net interest = Net Interest × (1 − Effective Tax Rate).|Do not tax-adjust a rate that is already after tax.|A zero Net Interest amount remains zero even if ETR is undefined; otherwise undefined ETR propagates. | O24: pending | P24: net_interest_after_tax_fy | Q24: 5 | R24: 2 | S24: 2023-08-31
A25: net_interest_after_tax_fy__20240831 | B25: 24 | C25: Net interest after tax | D25: Apply the effective tax rate once to net interest. | E25: condensed.net_interest_after_tax.2024-08-31 | F25: accounting | G25: Condensed Financials | H25: E53 | I25: =IF(E52=0,0,IF(ISNA(E51),NA(),E52*(1-E51))) | J25: -44365.251 | K25: 0.01 | L25: effective_tax_rate_fy__20240831,net_interest_fy__20240831 | M25: After-tax net interest = Net Interest × (1 − Effective Tax Rate).|Do not tax-adjust a rate that is already after tax.|A zero Net Interest amount remains zero even if ETR is undefined; otherwise undefined ETR propagates. | O25: pending | P25: net_interest_after_tax_fy | Q25: 5 | R25: 3 | S25: 2024-08-31
A26: net_interest_after_tax_fy__20250831 | B26: 25 | C26: Net interest after tax | D26: Apply the effective tax rate once to net interest. | E26: condensed.net_interest_after_tax.2025-08-31 | F26: accounting | G26: Condensed Financials | H26: F53 | I26: =IF(F52=0,0,IF(ISNA(F51),NA(),F52*(1-F51))) | J26: -66887.56 | K26: 0.01 | L26: effective_tax_rate_fy__20250831,net_interest_fy__20250831 | M26: After-tax net interest = Net Interest × (1 − Effective Tax Rate).|Do not tax-adjust a rate that is already after tax.|A zero Net Interest amount remains zero even if ETR is undefined; otherwise undefined ETR propagates. | O26: pending | P26: net_interest_after_tax_fy | Q26: 5 | R26: 4 | S26: 2025-08-31
A27: nopat_fy__20210831 | B27: 26 | C27: NOPAT | D27: Reformulate net income to operating profit after tax. | E27: condensed.nopat.2021-08-31 | F27: accounting | G27: Condensed Financials | H27: B54 | I27: =B45+B53 | J27: 161339.7 | K27: 0.01 | L27: net_income_link__20210831,net_interest_after_tax_fy__20210831 | M27: Start from Net Income on the Income Statement.|Add back after-tax net interest: Net Interest × (1 − Tax Rate).|NOPAT = Net Income + Net Interest After Tax.|Undefined tax-effected Net Interest propagates to NOPAT. | O27: pending | P27: nopat_fy | Q27: 6 | R27: 0 | S27: 2021-08-31
A28: nopat_fy__20220831 | B28: 27 | C28: NOPAT | D28: Reformulate net income to operating profit after tax. | E28: condensed.nopat.2022-08-31 | F28: accounting | G28: Condensed Financials | H28: C54 | I28: =C45+C53 | J28: 201430.55 | K28: 0.01 | L28: net_income_link__20220831,net_interest_after_tax_fy__20220831 | M28: Start from Net Income on the Income Statement.|Add back after-tax net interest: Net Interest × (1 − Tax Rate).|NOPAT = Net Income + Net Interest After Tax.|Undefined tax-effected Net Interest propagates to NOPAT. | O28: pending | P28: nopat_fy | Q28: 6 | R28: 1 | S28: 2022-08-31
A29: nopat_fy__20230831 | B29: 28 | C29: NOPAT | D29: Reformulate net income to operating profit after tax. | E29: condensed.nopat.2023-08-31 | F29: accounting | G29: Condensed Financials | H29: D54 | I29: =D45+D53 | J29: 270538.46 | K29: 0.01 | L29: net_income_link__20230831,net_interest_after_tax_fy__20230831 | M29: Start from Net Income on the Income Statement.|Add back after-tax net interest: Net Interest × (1 − Tax Rate).|NOPAT = Net Income + Net Interest After Tax.|Undefined tax-effected Net Interest propagates to NOPAT. | O29: pending | P29: nopat_fy | Q29: 6 | R29: 2 | S29: 2023-08-31
A30: nopat_fy__20240831 | B30: 29 | C30: NOPAT | D30: Reformulate net income to operating profit after tax. | E30: condensed.nopat.2024-08-31 | F30: accounting | G30: Condensed Financials | H30: E54 | I30: =E45+E53 | J30: 349239.75 | K30: 0.01 | L30: net_income_link__20240831,net_interest_after_tax_fy__20240831 | M30: Start from Net Income on the Income Statement.|Add back after-tax net interest: Net Interest × (1 − Tax Rate).|NOPAT = Net Income + Net Interest After Tax.|Undefined tax-effected Net Interest propagates to NOPAT. | O30: pending | P30: nopat_fy | Q30: 6 | R30: 3 | S30: 2024-08-31
A31: nopat_fy__20250831 | B31: 30 | C31: NOPAT | D31: Reformulate net income to operating profit after tax. | E31: condensed.nopat.2025-08-31 | F31: accounting | G31: Condensed Financials | H31: F54 | I31: =F45+F53 | J31: 392265.44 | K31: 0.01 | L31: net_income_link__20250831,net_interest_after_tax_fy__20250831 | M31: Start from Net Income on the Income Statement.|Add back after-tax net interest: Net Interest × (1 − Tax Rate).|NOPAT = Net Income + Net Interest After Tax.|Undefined tax-effected Net Interest propagates to NOPAT. | O31: pending | P31: nopat_fy | Q31: 6 | R31: 4 | S31: 2025-08-31
A32: owca_agg__20210831 | B32: 31 | C32: Operating working capital assets | D32: Aggregate the classified balance-sheet detail with the classification column. | E32: condensed.owca.2021-08-31 | F32: accounting | G32: Condensed Financials | H32: B57 | I32: =SUMIF($B$6:$B$41,"Operating Working Capital Asset",C$6:C$41) | J32: 463676 | K32: 0.01 | M32: Use SUMIF over the classification column for Operating Working Capital Asset. | O32: pending | P32: owca_agg | Q32: 7 | R32: 0 | S32: 2021-08-31
A33: owca_agg__20220831 | B33: 32 | C33: Operating working capital assets | D33: Aggregate the classified balance-sheet detail with the classification column. | E33: condensed.owca.2022-08-31 | F33: accounting | G33: Condensed Financials | H33: C57 | I33: =SUMIF($B$6:$B$41,"Operating Working Capital Asset",D$6:D$41) | J33: 572559 | K33: 0.01 | M33: Use SUMIF over the classification column for Operating Working Capital Asset. | O33: pending | P33: owca_agg | Q33: 7 | R33: 1 | S33: 2022-08-31
