Workbook

Sheet Trainer
A1: BAV Excel Trainer
A2: Complete each historical model-construction and earnings-quality diagnostic formula schedule left-to-right in dependency order. Run Check to validate the yellow formula cells against the treatment currently selected in Accounting Judgment column F (blank F uses the supplied reference treatment). Generated Condensed Financials classification links are system-controlled and validated by Check—do not edit them or columns D:E. When Normalization Judgment is present, choose Recurring vs Non-recurring in column F (blank uses the supplied reference); Earnings Normalization formulas are checked against that choice. Also complete Accounting Judgment and Normalization Judgment rationale/consequence when cases are present; those responses are not graded by Check. Compare them with the matching Answer Key.
A4: Order | B4: Schedule | C4: Period scope | D4: Tab | E4: Practice cells | F4: Depends on
A5: 1 | B5: Revenue historical source link | C5: 2023–2026 (4 cells) | D5: Condensed Financials | E5: B34:E34 | F5: —
A6: 2 | B6: Net Income historical source link | C6: 2023–2026 (4 cells) | D6: Condensed Financials | E6: B35:E35 | F6: —
A7: 3 | B7: Effective tax rate | C7: 2023–2026 (4 cells) | D7: Condensed Financials | E7: B38:E38 | F7: —
A8: 7 | B8: Operating working capital assets | C8: 2023–2026 (4 cells) | D8: Condensed Financials | E8: B44:E44 | F8: —
A9: 8 | B9: Operating working capital liabilities | C9: 2023–2026 (4 cells) | D9: Condensed Financials | E9: B45:E45 | F9: —
A10: 9 | B10: Net Operating Working Capital (NOWC) | C10: 2023–2026 (4 cells) | D10: Condensed Financials | E10: B46:E46 | F10: owca_agg, owcl_agg
A11: 10 | B11: Operating long-term assets | C11: 2023–2026 (4 cells) | D11: Condensed Financials | E11: B47:E47 | F11: —
A12: 11 | B12: Operating long-term liabilities | C12: 2023–2026 (4 cells) | D12: Condensed Financials | E12: B48:E48 | F12: —
A13: 12 | B13: Net operating long-term assets (NOLA) | C13: 2023–2026 (4 cells) | D13: Condensed Financials | E13: B49:E49 | F13: olta_agg, oltl_agg
A14: 13 | B14: Net Operating Assets (NOA) | C14: 2023–2026 (4 cells) | D14: Condensed Financials | E14: B50:E50 | F14: nowc_agg, nola_agg
A15: 14 | B15: Financial assets | C15: 2023–2026 (4 cells) | D15: Condensed Financials | E15: B51:E51 | F15: —
A16: 15 | B16: Financial liabilities | C16: 2023–2026 (4 cells) | D16: Condensed Financials | E16: B52:E52 | F16: —
... A78: 121 | B78: PP&E Capex / Revenue | C78: 2023–2026 (4 cells) | D78: ALT DuPont | E78: B63:E63 | F78: ppe_capex, revenue_link

Sheet Income Statement
A1: Company: lululemon athletica inc. (LULU)
A2: Statement: Income Statement
A3: Units: USD in Thousands
A4: Source: manual ingestion (US)
A6: Line Item | B6: 44955 | C6: 45319 | D6: 45690 | E6: 46054
A7: Foreign currency translation adjustment | B7: -65571 | C7: -23077 | D7: -253209 | E7: 253160
A8: Net investment hedge gains (losses) | B8: 8904 | C8: 11405 | D8: 93024 | E8: -59409
A9: Amortization of intangible assets | B9: 8752 | C9: 5010 | D9: 2735 | E9: 6961
A10: Basic earnings per share | B10: 6.7 | C10: 12.23 | D10: 14.67 | E10: 13.27
A11: Comprehensive income | B11: 798133 | C11: 1538518 | D11: 1654431 | E11: 1772934
A12: Cost of goods sold | B12: 3618178 | C12: 4009873 | D12: 4317315 | E12: 4818468
A13: Diluted earnings per share | B13: 6.68 | C13: 12.2 | D13: 14.64 | E13: 13.26
A14: Gross profit | B14: 4492340 | C14: 5609405 | D14: 6270811 | E14: 6284132
A15: Income before income tax expense | B15: 1332571 | C15: 2175735 | D15: 2576077 | E15: 2238967
A16: Income from operations | B16: 1328408 | C16: 2132676 | D16: 2505697 | E16: 2210615
A17: Income tax expense | B17: 477771 | C17: 625545 | D17: 761461 | E17: 659784
... A22: Selling, general and administrative expenses | B22: 2757447 | C22: 3397218 | D22: 3762379 | E22: 4066556

Sheet Balance Sheet
A1: Company: lululemon athletica inc. (LULU)
A2: Statement: Balance Sheet
A3: Units: USD in Thousands
A4: Source: manual ingestion (US)
A6: Line Item | B6: 44955 | C6: 45319 | D6: 45690 | E6: 46054
A7: Accounts receivable, net | B7: 132906 | C7: 124769 | D7: 120173 | E7: 190657
A8: Cash and cash equivalents | B8: 1154867 | C8: 2243971 | D8: 1984336 | E8: 1807202
A9: Inventories | B9: 1447367 | C9: 1323602 | D9: 1442081 | E9: 1700753
A10: Prepaid and receivable income taxes | B10: 185641 | C10: 183733 | D10: 182253 | E10: 352469
A11: Prepaid expenses and other current assets | B11: 238672 | C11: 184502 | D11: 251459 | E11: 211620
A12: Total current assets | B12: 3159453 | C12: 4060577 | D12: 3980302 | E12: 4262701
A13: Accounts payable | B13: 172732 | C13: 348441 | D13: 271406 | E13: 331421
A14: Accrued compensation and related expenses | B14: 248167 | C14: 326110 | D14: 204543 | E14: 187887
A15: Accrued liabilities and other | B15: 399223 | C15: 348555 | D15: 559463 | E15: 662982
A16: Current income taxes payable | B16: 174221 | C16: 12098 | D16: 183126 | E16: 43948
A17: Current lease liabilities | B17: 207972 | C17: 249270 | D17: 275154 | E17: 298724
... A27: Deferred income tax liabilities | B27: 55084 | C27: 29522 | D27: 98188 | E27: 52278
A28: Non-current income taxes payable | B28: 28555 | C28: 15864 | D28: 0
A29: Non-current lease liabilities | B29: 862362 | C29: 1154012 | D29: 1300637 | E29: 1499717
A30: Other non-current liabilities | B30: 20040 | C30: 29201 | D30: 40790 | E30: 55360
A31: Accumulated other comprehensive loss | B31: -252584 | C31: -264256 | D31: -424441 | E31: -230690
A32: Additional paid-in capital | B32: 474645 | C32: 575369 | D32: 638190 | E32: 669392
A33: Common stock | B33: 611 | C33: 606 | D33: 581 | E33: 557
A34: Retained earnings | B34: 2926127 | C34: 3920362 | D34: 4109717 | E34: 4522581
A35: Total stockholders' equity | B35: 3148799 | C35: 4232081 | D35: 4324047 | E35: 4961840
A36: Total assets | B36: 5607038 | C36: 7091941 | D36: 7603292 | E36: 8456743
A37: Total liabilities and stockholders' equity | B37: 5607038 | C37: 7091941 | D37: 7603292 | E37: 8456743
A38: Total liabilities | B38: 2458239 | C38: 2859860 | D38: 3279245 | E38: 3494903

Sheet Cash Flow Statement
A1: Company: lululemon athletica inc. (LULU)
A2: Statement: Cash Flow Statement
A3: Units: USD in Thousands
A4: Source: manual ingestion (US)
A6: Line Item | B6: 44955 | C6: 45319 | D6: 45690 | E6: 46054
A7: Net cash used in financing activities | B7: -467487 | C7: -548828 | D7: -1652508 | E7: -1208656
A8: Other financing activities | B8: -32 | C8: -32 | D8: -32 | E8: -11312
A9: Proceeds from settlement of stock-based compensation | B9: 11704 | C9: 42430 | D9: 19813 | E9: 8377
A10: Repurchase of common stock | B10: -444001 | C10: -558652 | D10: -1636879 | E10: -1178349
A11: Shares withheld related to net share settlement of stock-based compensation | B11: -35158 | C11: -32574 | D11: -35410 | E11: -27372
A12: Acquisition, net of cash acquired | B12: 0 | C12: 0 | D12: -154146 | E12: 0
A13: Net cash used in investing activities | B13: -569937 | C13: -654132 | D13: -798174 | E13: -662118
A14: Other investing activities | B14: 20916 | C14: -658 | D14: -5009 | E14: -8521
A15: Purchase of property and equipment | B15: -638657 | C15: -651865 | D15: -689232 | E15: -680802
A16: Settlement of net investment hedges | B16: 47804 | C16: -1609 | D16: 50213 | E16: 27205
A17: Accounts payable | B17: -107280 | C17: 177367 | D17: -57044 | E17: 45856
... A40: Increase (decrease) in cash and cash equivalents | B40: -105004 | C40: 1089104 | D40: -259635 | E40: -177134

Sheet Condensed Financials
A1: lululemon athletica inc. (LULU) — Condensed Financials
A4: BALANCE SHEET CLASSIFICATION
A5: Line Item | B5: Classification | C5: 44955 | D5: 45319 | E5: 45690 | F5: 46054 | G5: Notes
A6: Accounts receivable, net | B6: Operating Working Capital Asset | C6: 132906 | D6: 124769 | E6: 120173 | F6: 190657
A7: Cash and cash equivalents | B7: Financial Asset | C7: 1154867 | D7: 2243971 | E7: 1984336 | F7: 1807202
A8: Inventories | B8: Operating Working Capital Asset | C8: 1447367 | D8: 1323602 | E8: 1442081 | F8: 1700753
A9: Prepaid and receivable income taxes | B9: Operating Working Capital Asset | C9: 185641 | D9: 183733 | E9: 182253 | F9: 352469
A10: Prepaid expenses and other current assets | B10: Operating Working Capital Asset | C10: 238672 | D10: 184502 | E10: 251459 | F10: 211620
A11: Accounts payable | B11: Operating Working Capital Liability | C11: 172732 | D11: 348441 | E11: 271406 | F11: 331421
A12: Accrued compensation and related expenses | B12: Operating Working Capital Liability | C12: 248167 | D12: 326110 | E12: 204543 | F12: 187887
A13: Accrued liabilities and other | B13: Operating Working Capital Liability | C13: 399223 | D13: 348555 | E13: 559463 | F13: 662982
A14: Current income taxes payable | B14: Operating Working Capital Liability | C14: 174221 | D14: 12098 | E14: 183126 | F14: 43948
A15: Current lease liabilities | B15: =IF('Accounting Judgment'!$F$5="","Operating Long-Term Liability",'Accounting Judgment'!$F$5) | C15: 207972 | D15: 249270 | E15: 275154 | F15: 298724 | G15: ⚠ Review: Lease liability concept — operating vs financial judgment
A16: Other current liabilities | B16: =IF('Accounting Judgment'!$F$6="","Operating Working Capital Liability",'Accounting Judgment'!$F$6) | C16: 38405 | D16: 40308 | E16: 37586 | F16: 45954 | G16: ⚠ Review: Explicit residual balance-sheet concept identifies side/horizon but not economic nature — operating vs financial judgment
A17: Unredeemed gift card liability | B17: Operating Working Capital Liability | C17: 251478 | D17: 306479 | E17: 308352 | F17: 316632
A18: Deferred income tax assets | B18: Operating Long-Term Asset | C18: 6402 | D18: 9176 | E18: 17085 | F18: 24037 | G18: ⚠ Review: Deferred tax asset concept — operating vs exclude judgment
A19: Goodwill | B19: Operating Long-Term Asset | C19: 24144 | D19: 24083 | E19: 159518 | F19: 184911
A20: Intangible assets, net | B20: Operating Long-Term Asset | C20: 21961 | D20: 0 | E20: 11673 | F20: 6283
A21: Other non-current assets | B21: =IF('Accounting Judgment'!$F$7="","Operating Long-Term Asset",'Accounting Judgment'!$F$7) | C21: 156045 | D21: 186684 | E21: 237841 | F21: 314910 | G21: ⚠ Review: Explicit residual balance-sheet concept identifies side/horizon but not economic nature — operating vs financial judgment
A22: Property and equipment, net | B22: Operating Long-Term Asset | C22: 1269614 | D22: 1545811 | E22: 1780617 | F22: 2033720
A23: Right-of-use lease assets | B23: Operating Long-Term Asset | C23: 969419 | D23: 1265610 | E23: 1416256 | F23: 1630181 | G23: ⚠ Review: Lease/ROU asset concept — operating vs financial judgment
A24: Deferred income tax liabilities | B24: Operating Long-Term Liability | C24: 55084 | D24: 29522 | E24: 98188 | F24: 52278 | G24: ⚠ Review: Deferred tax liability concept — operating vs exclude judgment
A25: Non-current income taxes payable | B25: Operating Working Capital Liability | C25: 28555 | D25: 15864 | E25: 0
A26: Non-current lease liabilities | B26: =IF('Accounting Judgment'!$F$8="","Operating Long-Term Liability",'Accounting Judgment'!$F$8) | C26: 862362 | D26: 1154012 | E26: 1300637 | F26: 1499717 | G26: ⚠ Review: Lease liability concept — operating vs financial judgment
A27: Other non-current liabilities | B27: =IF('Accounting Judgment'!$F$9="","Operating Long-Term Liability",'Accounting Judgment'!$F$9) | C27: 20040 | D27: 29201 | E27: 40790 | F27: 55360 | G27: ⚠ Review: Explicit residual balance-sheet concept identifies side/horizon but not economic nature — operating vs financial judgment
A28: Accumulated other comprehensive loss | B28: Equity | C28: -252584 | D28: -264256 | E28: -424441 | F28: -230690
A29: Additional paid-in capital | B29: Equity | C29: 474645 | D29: 575369 | E29: 638190 | F29: 669392
A30: Common stock | B30: Equity | C30: 611 | D30: 606 | E30: 581 | F30: 557
A31: Retained earnings | B31: Equity | C31: 2926127 | D31: 3920362 | E31: 4109717 | F31: 4522581
A33: CONDENSED INCOME STATEMENT | B33: 44955 | C33: 45319 | D33: 45690 | E33: 46054
A34: Revenue | B34: ='Income Statement'!B19 | C34: ='Income Statement'!C19 | D34: ='Income Statement'!D19 | E34: ='Income Statement'!E19
A35: Net Income | B35: ='Income Statement'!B18 | C35: ='Income Statement'!C18 | D35: ='Income Statement'!D18 | E35: ='Income Statement'!E18
A36: Pretax Income | B36: ='Income Statement'!B15 | C36: ='Income Statement'!C15 | D36: ='Income Statement'!D15 | E36: ='Income Statement'!E15
A37: Tax Expense | B37: ='Income Statement'!B17 | C37: ='Income Statement'!C17 | D37: ='Income Statement'!D17 | E37: ='Income Statement'!E17
A38: Effective Tax Rate | B38: =IF(B36=0,NA(),-B37/B36) | C38: =IF(C36=0,NA(),-C37/C36) | D38: =IF(D36=0,NA(),-D37/D36) | E38: =IF(E36=0,NA(),-E37/E36)
A39: Net Interest | B39: Source unavailable | C39: Source unavailable | D39: Source unavailable | E39: Source unavailable
A40: Net Interest After Tax | B40: Source unavailable | C40: Source unavailable | D40: Source unavailable | E40: Source unavailable
A41: NOPAT | B41: Source unavailable | C41: Source unavailable | D41: Source unavailable | E41: Source unavailable
A43: CONDENSED BALANCE SHEET
A44: Operating Working Capital Assets | B44: =SUMIF($B$6:$B$31,"Operating Working Capital Asset",C$6:C$31) | C44: =SUMIF($B$6:$B$31,"Operating Working Capital Asset",D$6:D$31) | D44: =SUMIF($B$6:$B$31,"Operating Working Capital Asset",E$6:E$31) | E44: =SUMIF($B$6:$B$31,"Operating Working Capital Asset",F$6:F$31)
...

Sheet ALT DuPont
A1: lululemon athletica inc. — DuPont Decomposition
A2: ROE = RNOA + FLEV × Spread
A4: Metric | B4: 44955 | C4: 45319 | D4: 45690 | E4: 46054
A5: Sales Growth | B5: N/A | C5: =IF('Condensed Financials'!B34=0,NA(),'Condensed Financials'!C34/'Condensed Financials'!B34-1) | D5: =IF('Condensed Financials'!C34=0,NA(),'Condensed Financials'!D34/'Condensed Financials'!C34-1) | E5: =IF('Condensed Financials'!D34=0,NA(),'Condensed Financials'!E34/'Condensed Financials'!D34-1)
A6: NOPAT Margin | B6: Source unavailable | C6: Source unavailable | D6: Source unavailable | E6: Source unavailable
A7: RNOA | B7: N/A | C7: Source unavailable | D7: Source unavailable | E7: Source unavailable
A8: After-tax CoD | B8: N/A | C8: Source unavailable | D8: Source unavailable | E8: Source unavailable
A9: Spread | B9: N/A | C9: Source unavailable | D9: Source unavailable | E9: Source unavailable
A10: FLEV | B10: N/A | C10: =IF((('Condensed Financials'!C54+'Condensed Financials'!B54)/2)=0,NA(),(('Condensed Financials'!C53+'Condensed Financials'!B53)/2)/(('Condensed Financials'!C54+'Condensed Financials'!B54)/2)) | D10: =IF((('Condensed Financials'!D54+'Condensed Financials'!C54)/2)=0,NA(),(('Condensed Financials'!D53+'Condensed Financials'!C53)/2)/(('Condensed Financials'!D54+'Condensed Financials'!C54)/2)) | E10: =IF((('Condensed Financials'!E54+'Condensed Financials'!D54)/2)=0,NA(),(('Condensed Financials'!E53+'Condensed Financials'!D53)/2)/(('Condensed Financials'!E54+'Condensed Financials'!D54)/2))
A11: ROE (decomposed) | B11: N/A | C11: Source unavailable | D11: Source unavailable | E11: Source unavailable
A12: Actual ROE | B12: N/A | C12: =IF((('Condensed Financials'!C54+'Condensed Financials'!B54)/2)=0,NA(),'Condensed Financials'!C35/(('Condensed Financials'!C54+'Condensed Financials'!B54)/2)) | D12: =IF((('Condensed Financials'!D54+'Condensed Financials'!C54)/2)=0,NA(),'Condensed Financials'!D35/(('Condensed Financials'!D54+'Condensed Financials'!C54)/2)) | E12: =IF((('Condensed Financials'!E54+'Condensed Financials'!D54)/2)=0,NA(),'Condensed Financials'!E35/(('Condensed Financials'!E54+'Condensed Financials'!D54)/2))
A14: RNOA DRIVER DECOMPOSITION
A15: Average NOA | B15: N/A | C15: =('Condensed Financials'!B50+'Condensed Financials'!C50)/2 | D15: =('Condensed Financials'!C50+'Condensed Financials'!D50)/2 | E15: =('Condensed Financials'!D50+'Condensed Financials'!E50)/2
A16: NOA Turnover | B16: N/A | C16: =IF(C15=0,NA(),'Condensed Financials'!C34/C15) | D16: =IF(D15=0,NA(),'Condensed Financials'!D34/D15) | E16: =IF(E15=0,NA(),'Condensed Financials'!E34/E15)
A17: NOA Intensity | B17: N/A | C17: =IF('Condensed Financials'!C34=0,NA(),C15/'Condensed Financials'!C34) | D17: =IF('Condensed Financials'!D34=0,NA(),D15/'Condensed Financials'!D34) | E17: =IF('Condensed Financials'!E34=0,NA(),E15/'Condensed Financials'!E34)
A18: RNOA from Margin × Turnover | B18: N/A | C18: Source unavailable | D18: Source unavailable | E18: Source unavailable
A19: RNOA DRIVER CHECK | B19: N/A | C19: Source unavailable | D19: Source unavailable | E19: Source unavailable
A21: RNOA CHANGE ATTRIBUTION
A22: Change in NOPAT Margin | B22: N/A | C22: N/A | D22: Source unavailable | E22: Source unavailable
A23: Change in NOA Turnover | B23: N/A | C23: N/A | D23: =D16-C16 | E23: =E16-D16
A24: Direct Change in RNOA | B24: N/A | C24: N/A | D24: Source unavailable | E24: Source unavailable
A25: Margin Effect on RNOA Change | B25: N/A | C25: N/A | D25: Source unavailable | E25: Source unavailable
A26: Turnover Effect on RNOA Change | B26: N/A | C26: N/A | D26: Source unavailable | E26: Source unavailable
A27: RNOA Change from Drivers | B27: N/A | C27: N/A | D27: Source unavailable | E27: Source unavailable
A28: RNOA CHANGE DRIVER CHECK | B28: N/A | C28: N/A | D28: Source unavailable | E28: Source unavailable
A30: ROE OPERATING / FINANCING ATTRIBUTION
A31: Financing Contribution to ROE | B31: N/A | C31: Source unavailable | D31: Source unavailable | E31: Source unavailable
A32: ROE LEVEL ATTRIBUTION CHECK | B32: N/A | C32: Source unavailable | D32: Source unavailable | E32: Source unavailable
A34: ROE CHANGE ATTRIBUTION
A35: Direct Change in Decomposed ROE | B35: N/A | C35: N/A | D35: Source unavailable | E35: Source unavailable
A36: Operating Effect on Change in ROE | B36: N/A | C36: N/A | D36: Source unavailable | E36: Source unavailable
A37: Leverage Effect on Change in ROE | B37: N/A | C37: N/A | D37: Source unavailable | E37: Source unavailable
A38: Spread Effect on Change in ROE | B38: N/A | C38: N/A | D38: Source unavailable | E38: Source unavailable
A39: Financing Effect on Change in ROE | B39: N/A | C39: N/A | D39: Source unavailable | E39: Source unavailable
A40: Change in ROE from Drivers | B40: N/A | C40: N/A | D40: Source unavailable | E40: Source unavailable
A41: ROE CHANGE ATTRIBUTION CHECK | B41: N/A | C41: N/A | D41: Source unavailable | E41: Source unavailable
A43: FIXED-ASSET INTENSITY CONTEXT
A44: Property, Plant & Equipment | B44: ='Balance Sheet'!B25 | C44: ='Balance Sheet'!C25 | D44: ='Balance Sheet'!D25 | E44: ='Balance Sheet'!E25
A45: Depreciation & Amortisation | B45: ='Cash Flow Statement'!B23 | C45: ='Cash Flow Statement'!C23 | D45: ='Cash Flow Statement'!D23 | E45: ='Cash Flow Statement'!E23
A46: Average PP&E | B46: N/A | C46: =(B44+C44)/2 | D46: =(C44+D44)/2 | E46: =(D44+E44)/2
...

Sheet Accounting Judgment
A1: Accounting Judgment
A2: The supplied treatment is the model's reference treatment, not a universal accounting truth. Compare it with the listed alternative(s), choose the treatment you would defend, and explain the economic consequence.
A3: Choose a treatment in column F only. That choice drives the matching Condensed Financials classification and downstream historical schedules; leaving F blank uses the supplied reference treatment. Columns D:E are display context and must not be edited. Enter your rationale and economic consequence in G:H. Formula Check grades formula cells against the treatment currently selected in F and validates that the generated classification links remain intact; it does not grade the judgment response itself. Do not edit the linked Condensed Financials classification cell directly.
A4: Order | B4: Line item | C4: Topic | D4: Supplied reference treatment | E4: Alternative(s) to evaluate | F4: Treatment to defend | G4: Rationale | H4: Economic consequence
A5: 1 | B5: Current lease liabilities | C5: Lease liability operating vs financing | D5: Operating Long-Term Liability | E5: Financial Liability | F5: Operating Long-Term Liability | G5: The reference model keeps the liability in operating long-term liabilities under its current lease convention. Treating it as a financial liability is also defensible when the lease obligation is viewed as debt-like financing. | H5: Operating-liability treatment lowers NOLA/NOA; financial-liability treatment raises Net Debt by the same balance. Implied equity is unchanged from this classification switch alone, but RNOA versus FLEV/Spread interpretation changes.
A6: 2 | B6: Other current liabilities | C6: Other current liability: operating vs financial | D6: Operating Working Capital Liability | E6: Financial Liability | F6: Operating Working Capital Liability | G6: The residual current-liability concept proves balance-sheet side and horizon but not whether the balance is an operating working-capital liability or a financial liability in economic substance. | H6: Operating-WC-liability treatment lowers NOWC/NOA; financial-liability treatment raises Net Debt by the same balance. Implied equity is unchanged by the classification switch alone.
A7: 3 | B7: Other non-current assets | C7: Other non-current asset: operating vs financial | D7: Operating Long-Term Asset | E7: Financial Asset | F7: Operating Long-Term Asset | G7: The residual non-current-asset concept proves balance-sheet side and horizon but not whether the balance is an operating long-term asset or a financial asset in economic substance. | H7: Operating-LT treatment raises NOLA/NOA; financial-asset treatment lowers Net Debt by the same balance. Implied equity is unchanged by the classification switch alone.
A8: 4 | B8: Non-current lease liabilities | C8: Lease liability operating vs financing | D8: Operating Long-Term Liability | E8: Financial Liability | F8: Operating Long-Term Liability | G8: The reference model keeps the liability in operating long-term liabilities under its current lease convention. Treating it as a financial liability is also defensible when the lease obligation is viewed as debt-like financing. | H8: Operating-liability treatment lowers NOLA/NOA; financial-liability treatment raises Net Debt by the same balance. Implied equity is unchanged from this classification switch alone, but RNOA versus FLEV/Spread interpretation changes.
A9: 5 | B9: Other non-current liabilities | C9: Other non-current liability: operating vs financial | D9: Operating Long-Term Liability | E9: Financial Liability | F9: Operating Long-Term Liability | G9: The residual non-current-liability concept proves balance-sheet side and horizon but not whether the balance is an operating long-term liability or a financial liability in economic substance. | H9: Operating-LT-liability treatment lowers NOLA/NOA; financial-liability treatment raises Net Debt by the same balance. Implied equity is unchanged by the classification switch alone.

Sheet Earnings Quality
A1: lululemon athletica inc. — Earnings Quality
A2: Historical cash-conversion and accrual diagnostics. These are mechanical diagnostics, not an automatic quality score.
A4: Metric | B4: 44955 | C4: 45319 | D4: 45690 | E4: 46054
A5: Operating Cash Flow | B5: ='Cash Flow Statement'!B27 | C5: ='Cash Flow Statement'!C27 | D5: ='Cash Flow Statement'!D27 | E5: ='Cash Flow Statement'!E27
A6: Reported Net Income | B6: ='Condensed Financials'!B35 | C6: ='Condensed Financials'!C35 | D6: ='Condensed Financials'!D35 | E6: ='Condensed Financials'!E35
A7: Cash Conversion Ratio | B7: =IF(B6=0,NA(),B5/B6) | C7: =IF(C6=0,NA(),C5/C6) | D7: =IF(D6=0,NA(),D5/D6) | E7: =IF(E6=0,NA(),E5/E6)
A8: Total Accruals (Net Income - CFO) | B8: =B6-B5 | C8: =C6-C5 | D8: =D6-D5 | E8: =E6-E5
A10: Total Assets | B10: ='Balance Sheet'!B36 | C10: ='Balance Sheet'!C36 | D10: ='Balance Sheet'!D36 | E10: ='Balance Sheet'!E36
A11: Average Total Assets | C11: =(B10+C10)/2 | D11: =(C10+D10)/2 | E11: =(D10+E10)/2
A12: Accrual Ratio | C12: =IF(C11=0,NA(),C8/C11) | D12: =IF(D11=0,NA(),D8/D11) | E12: =IF(E11=0,NA(),E8/E11)
A14: EARNINGS QUALITY TREND DIAGNOSTICS
A15: Change in Operating Cash Flow | B15: N/A | C15: =C5-B5 | D15: =D5-C5 | E15: =E5-D5
A16: Change in Cash Conversion Ratio | B16: N/A | C16: =C7-B7 | D16: =D7-C7 | E16: =E7-D7
A17: Change in Total Accruals | B17: N/A | C17: =C8-B8 | D17: =D8-C8 | E17: =E8-D8
A18: Change in Accrual Ratio | B18: N/A | C18: N/A | D18: =D12-C12 | E18: =E12-D12
A19: EARNINGS QUALITY CHANGE CHECK | B19: N/A | C19: =IF(ABS(C17-((C6-B6)-C15))<0.01,"OK","CHECK") | D19: =IF(ABS(D17-((D6-C6)-D15))<0.01,"OK","CHECK") | E19: =IF(ABS(E17-((E6-D6)-E15))<0.01,"OK","CHECK")

Sheet Working Capital Analysis
A1: Working Capital Analysis
A2: Relate classified operating working capital to Revenue and identify how much incremental NOWC accompanies changes in sales.
A3: These are diagnostics, not automatic judgments. Positive Change in NOWC is an operating cash use; negative Change in NOWC is a release. Annual data alone does not prove seasonality or deterioration.
A5: Metric | B5: 44955 | C5: 45319 | D5: 45690 | E5: 46054
A6: Revenue | B6: ='Condensed Financials'!B34 | C6: ='Condensed Financials'!C34 | D6: ='Condensed Financials'!D34 | E6: ='Condensed Financials'!E34
A7: Operating Working Capital Assets | B7: ='Condensed Financials'!B44 | C7: ='Condensed Financials'!C44 | D7: ='Condensed Financials'!D44 | E7: ='Condensed Financials'!E44
A8: Operating Working Capital Liabilities | B8: ='Condensed Financials'!B45 | C8: ='Condensed Financials'!C45 | D8: ='Condensed Financials'!D45 | E8: ='Condensed Financials'!E45
A9: NOWC | B9: ='Condensed Financials'!B46 | C9: ='Condensed Financials'!C46 | D9: ='Condensed Financials'!D46 | E9: ='Condensed Financials'!E46
A11: OWCA / Revenue | B11: =IF(B6=0,NA(),B7/B6) | C11: =IF(C6=0,NA(),C7/C6) | D11: =IF(D6=0,NA(),D7/D6) | E11: =IF(E6=0,NA(),E7/E6)
A12: OWCL / Revenue | B12: =IF(B6=0,NA(),B8/B6) | C12: =IF(C6=0,NA(),C8/C6) | D12: =IF(D6=0,NA(),D8/D6) | E12: =IF(E6=0,NA(),E8/E6)
A13: NOWC / Revenue | B13: =IF(B6=0,NA(),B9/B6) | C13: =IF(C6=0,NA(),C9/C6) | D13: =IF(D6=0,NA(),D9/D6) | E13: =IF(E6=0,NA(),E9/E6)
A14: Change in Revenue | B14: N/A | C14: =C6-B6 | D14: =D6-C6 | E14: =E6-D6
A15: Change in NOWC | B15: N/A | C15: =C9-B9 | D15: =D9-C9 | E15: =E9-D9
A16: Incremental NOWC / Change in Revenue | B16: N/A | C16: =IF(C14=0,NA(),C15/C14) | D16: =IF(D14=0,NA(),D15/D14) | E16: =IF(E14=0,NA(),E15/E14)
A18: WORKING-CAPITAL DRIVER DECOMPOSITION
A19: Change in OWCA | B19: N/A | C19: =C7-B7 | D19: =D7-C7 | E19: =E7-D7
A20: Change in OWCL | B20: N/A | C20: =C8-B8 | D20: =D8-C8 | E20: =E8-D8
A21: Change in NOWC from Components | B21: N/A | C21: =C19-C20 | D21: =D19-D20 | E21: =E19-E20
A22: Incremental OWCA / Change in Revenue | B22: N/A | C22: =IF(C14=0,NA(),C19/C14) | D22: =IF(D14=0,NA(),D19/D14) | E22: =IF(E14=0,NA(),E19/E14)
A23: Incremental OWCL / Change in Revenue | B23: N/A | C23: =IF(C14=0,NA(),C20/C14) | D23: =IF(D14=0,NA(),D20/D14) | E23: =IF(E14=0,NA(),E20/E14)
A24: DRIVER DECOMPOSITION CHECK | B24: N/A | C24: =IF(ABS(C21-C15)<0.01,"OK","CHECK") | D24: =IF(ABS(D21-D15)<0.01,"OK","CHECK") | E24: =IF(ABS(E21-E15)<0.01,"OK","CHECK")

Sheet Per Share Analysis
A1: lululemon athletica inc. — Per Share Analysis
A2: Historical per-share diagnostics using supplied diluted weighted-average shares. Share counts are source inputs, not practice cells.
A4: Metric | B4: 44955 | C4: 45319 | D4: 45690 | E4: 46054
A5: Reported Net Income | B5: ='Condensed Financials'!B35 | C5: ='Condensed Financials'!C35 | D5: ='Condensed Financials'!D35 | E5: ='Condensed Financials'!E35
A6: NOPAT | B6: Source unavailable | C6: Source unavailable | D6: Source unavailable | E6: Source unavailable
A7: Diluted Weighted-Average Shares | B7: 128017 | C7: 127060 | D7: 123935 | E7: 119068
A8: Share Basis: Reported basis
A9: Diluted EPS (Comparable Basis) | B9: =IF(B7<=0,NA(),B5/B7) | C9: =IF(C7<=0,NA(),C5/C7) | D9: =IF(D7<=0,NA(),D5/D7) | E9: =IF(E7<=0,NA(),E5/E7)
A10: NOPAT per Diluted Share | B10: Source unavailable | C10: Source unavailable | D10: Source unavailable | E10: Source unavailable
A12: Change in Diluted EPS | B12: N/A | C12: =C9-B9 | D12: =D9-C9 | E12: =E9-D9
A13: Change in Diluted Weighted-Average Shares | B13: N/A | C13: =C7-B7 | D13: =D7-C7 | E13: =E7-D7
A15: DILUTED EPS CHANGE ATTRIBUTION
A16: Change in Per-Share Earnings Numerator | B16: N/A | C16: =C5-B5 | D16: =D5-C5 | E16: =E5-D5
A17: Earnings Effect on Change in Diluted EPS | B17: N/A | C17: =C16*((1/C7+1/B7)/2) | D17: =D16*((1/D7+1/C7)/2) | E17: =E16*((1/E7+1/D7)/2)
A18: Share-Count Effect on Change in Diluted EPS | B18: N/A | C18: =((1/C7)-(1/B7))*((C5+B5)/2) | D18: =((1/D7)-(1/C7))*((D5+C5)/2) | E18: =((1/E7)-(1/D7))*((E5+D5)/2)
A19: Diluted EPS Change from Drivers | B19: N/A | C19: =C17+C18 | D19: =D17+D18 | E19: =E17+E18
A20: DILUTED EPS CHANGE ATTRIBUTION CHECK | B20: N/A | C20: =IF(ABS(C19-C12)<0.0000001,"OK","CHECK") | D20: =IF(ABS(D19-D12)<0.0000001,"OK","CHECK") | E20: =IF(ABS(E19-E12)<0.0000001,"OK","CHECK")

Sheet Model_Bear
A1: Deferred from historical-only v1

Sheet Model_Base
A1: Deferred from historical-only v1

Sheet Model_Bull
A1: Deferred from historical-only v1

Sheet Scenario_Summary
A1: Deferred from historical-only v1

Sheet _ComponentMap
A1: id | B1: order | C1: title | D1: short_hint | E1: semantic_key | F1: category | G1: tab | H1: cell | I1: formula | J1: expected_value | K1: tolerance | L1: depends_on | M1: hints | N1: related_cells | O1: status | P1: family_id | Q1: family_order | R1: period_index | S1: period_end
A2: revenue_link__20230129 | B2: 1 | C2: Revenue historical source link | D2: Link Revenue from the Income Statement into Condensed Financials. | E2: condensed.revenue_link.2023-01-29 | F2: accounting | G2: Condensed Financials | H2: B34 | I2: ='Income Statement'!B19 | J2: 8110518 | K2: 0.01 | M2: Pull the Revenue line from the Income Statement for the same fiscal period. | O2: pending | P2: revenue_link | Q2: 1 | R2: 0 | S2: 2023-01-29
A3: revenue_link__20240128 | B3: 2 | C3: Revenue historical source link | D3: Link Revenue from the Income Statement into Condensed Financials. | E3: condensed.revenue_link.2024-01-28 | F3: accounting | G3: Condensed Financials | H3: C34 | I3: ='Income Statement'!C19 | J3: 9619278 | K3: 0.01 | M3: Pull the Revenue line from the Income Statement for the same fiscal period. | O3: pending | P3: revenue_link | Q3: 1 | R3: 1 | S3: 2024-01-28
A4: revenue_link__20250202 | B4: 3 | C4: Revenue historical source link | D4: Link Revenue from the Income Statement into Condensed Financials. | E4: condensed.revenue_link.2025-02-02 | F4: accounting | G4: Condensed Financials | H4: D34 | I4: ='Income Statement'!D19 | J4: 10588126 | K4: 0.01 | M4: Pull the Revenue line from the Income Statement for the same fiscal period. | O4: pending | P4: revenue_link | Q4: 1 | R4: 2 | S4: 2025-02-02
A5: revenue_link__20260201 | B5: 4 | C5: Revenue historical source link | D5: Link Revenue from the Income Statement into Condensed Financials. | E5: condensed.revenue_link.2026-02-01 | F5: accounting | G5: Condensed Financials | H5: E34 | I5: ='Income Statement'!E19 | J5: 11102600 | K5: 0.01 | M5: Pull the Revenue line from the Income Statement for the same fiscal period. | O5: pending | P5: revenue_link | Q5: 1 | R5: 3 | S5: 2026-02-01
A6: net_income_link__20230129 | B6: 5 | C6: Net Income historical source link | D6: Link Net Income from the Income Statement into Condensed Financials. | E6: condensed.net_income_link.2023-01-29 | F6: accounting | G6: Condensed Financials | H6: B35 | I6: ='Income Statement'!B18 | J6: 854800 | K6: 0.01 | M6: Pull Net Income from the Income Statement for the same fiscal period. | O6: pending | P6: net_income_link | Q6: 2 | R6: 0 | S6: 2023-01-29
A7: net_income_link__20240128 | B7: 6 | C7: Net Income historical source link | D7: Link Net Income from the Income Statement into Condensed Financials. | E7: condensed.net_income_link.2024-01-28 | F7: accounting | G7: Condensed Financials | H7: C35 | I7: ='Income Statement'!C18 | J7: 1550190 | K7: 0.01 | M7: Pull Net Income from the Income Statement for the same fiscal period. | O7: pending | P7: net_income_link | Q7: 2 | R7: 1 | S7: 2024-01-28
A8: net_income_link__20250202 | B8: 7 | C8: Net Income historical source link | D8: Link Net Income from the Income Statement into Condensed Financials. | E8: condensed.net_income_link.2025-02-02 | F8: accounting | G8: Condensed Financials | H8: D35 | I8: ='Income Statement'!D18 | J8: 1814616 | K8: 0.01 | M8: Pull Net Income from the Income Statement for the same fiscal period. | O8: pending | P8: net_income_link | Q8: 2 | R8: 2 | S8: 2025-02-02
A9: net_income_link__20260201 | B9: 8 | C9: Net Income historical source link | D9: Link Net Income from the Income Statement into Condensed Financials. | E9: condensed.net_income_link.2026-02-01 | F9: accounting | G9: Condensed Financials | H9: E35 | I9: ='Income Statement'!E18 | J9: 1579183 | K9: 0.01 | M9: Pull Net Income from the Income Statement for the same fiscal period. | O9: pending | P9: net_income_link | Q9: 2 | R9: 3 | S9: 2026-02-01
A10: effective_tax_rate_fy__20230129 | B10: 9 | C10: Effective tax rate | D10: Relate tax expense to pretax income using the model's sign convention. | E10: condensed.effective_tax_rate.2023-01-29 | F10: accounting | G10: Condensed Financials | H10: B38 | I10: =IF(B36=0,NA(),-B37/B36) | J10: -0.35853324 | K10: 0.01 | M10: Effective tax rate uses pretax income in the denominator.|Preserve the model's sign convention for tax expense.|A zero Pretax Income makes Effective Tax Rate undefined (#N/A). | O10: pending | P10: effective_tax_rate_fy | Q10: 3 | R10: 0 | S10: 2023-01-29
A11: effective_tax_rate_fy__20240128 | B11: 10 | C11: Effective tax rate | D11: Relate tax expense to pretax income using the model's sign convention. | E11: condensed.effective_tax_rate.2024-01-28 | F11: accounting | G11: Condensed Financials | H11: C38 | I11: =IF(C36=0,NA(),-C37/C36) | J11: -0.28750974 | K11: 0.01 | M11: Effective tax rate uses pretax income in the denominator.|Preserve the model's sign convention for tax expense.|A zero Pretax Income makes Effective Tax Rate undefined (#N/A). | O11: pending | P11: effective_tax_rate_fy | Q11: 3 | R11: 1 | S11: 2024-01-28
A12: effective_tax_rate_fy__20250202 | B12: 11 | C12: Effective tax rate | D12: Relate tax expense to pretax income using the model's sign convention. | E12: condensed.effective_tax_rate.2025-02-02 | F12: accounting | G12: Condensed Financials | H12: D38 | I12: =IF(D36=0,NA(),-D37/D36) | J12: -0.29558938 | K12: 0.01 | M12: Effective tax rate uses pretax income in the denominator.|Preserve the model's sign convention for tax expense.|A zero Pretax Income makes Effective Tax Rate undefined (#N/A). | O12: pending | P12: effective_tax_rate_fy | Q12: 3 | R12: 2 | S12: 2025-02-02
A13: effective_tax_rate_fy__20260201 | B13: 12 | C13: Effective tax rate | D13: Relate tax expense to pretax income using the model's sign convention. | E13: condensed.effective_tax_rate.2026-02-01 | F13: accounting | G13: Condensed Financials | H13: E38 | I13: =IF(E36=0,NA(),-E37/E36) | J13: -0.29468232 | K13: 0.01 | M13: Effective tax rate uses pretax income in the denominator.|Preserve the model's sign convention for tax expense.|A zero Pretax Income makes Effective Tax Rate undefined (#N/A). | O13: pending | P13: effective_tax_rate_fy | Q13: 3 | R13: 3 | S13: 2026-02-01
A14: owca_agg__20230129 | B14: 25 | C14: Operating working capital assets | D14: Aggregate the classified balance-sheet detail with the classification column. | E14: condensed.owca.2023-01-29 | F14: accounting | G14: Condensed Financials | H14: B44 | I14: =SUMIF($B$6:$B$31,"Operating Working Capital Asset",C$6:C$31) | J14: 2004586 | K14: 0.01 | M14: Use SUMIF over the classification column for Operating Working Capital Asset. | O14: pending | P14: owca_agg | Q14: 7 | R14: 0 | S14: 2023-01-29
A15: owca_agg__20240128 | B15: 26 | C15: Operating working capital assets | D15: Aggregate the classified balance-sheet detail with the classification column. | E15: condensed.owca.2024-01-28 | F15: accounting | G15: Condensed Financials | H15: C44 | I15: =SUMIF($B$6:$B$31,"Operating Working Capital Asset",D$6:D$31) | J15: 1816606 | K15: 0.01 | M15: Use SUMIF over the classification column for Operating Working Capital Asset. | O15: pending | P15: owca_agg | Q15: 7 | R15: 1 | S15: 2024-01-28
A16: owca_agg__20250202 | B16: 27 | C16: Operating working capital assets | D16: Aggregate the classified balance-sheet detail with the classification column. | E16: condensed.owca.2025-02-02 | F16: accounting | G16: Condensed Financials | H16: D44 | I16: =SUMIF($B$6:$B$31,"Operating Working Capital Asset",E$6:E$31) | J16: 1995966 | K16: 0.01 | M16: Use SUMIF over the classification column for Operating Working Capital Asset. | O16: pending | P16: owca_agg | Q16: 7 | R16: 2 | S16: 2025-02-02
A17: owca_agg__20260201 | B17: 28 | C17: Operating working capital assets | D17: Aggregate the classified balance-sheet detail with the classification column. | E17: condensed.owca.2026-02-01 | F17: accounting | G17: Condensed Financials | H17: E44 | I17: =SUMIF($B$6:$B$31,"Operating Working Capital Asset",F$6:F$31) | J17: 2455499 | K17: 0.01 | M17: Use SUMIF over the classification column for Operating Working Capital Asset. | O17: pending | P17: owca_agg | Q17: 7 | R17: 3 | S17: 2026-02-01
A18: owcl_agg__20230129 | B18: 29 | C18: Operating working capital liabilities | D18: Aggregate the classified balance-sheet detail with the classification column. | E18: condensed.owcl.2023-01-29 | F18: accounting | G18: Condensed Financials | H18: B45 | I18: =SUMIF($B$6:$B$31,"Operating Working Capital Liability",C$6:C$31) | J18: 1312781 | K18: 0.01 | M18: Use SUMIF over the classification column for Operating Working Capital Liability. | O18: pending | P18: owcl_agg | Q18: 8 | R18: 0 | S18: 2023-01-29
A19: owcl_agg__20240128 | B19: 30 | C19: Operating working capital liabilities | D19: Aggregate the classified balance-sheet detail with the classification column. | E19: condensed.owcl.2024-01-28 | F19: accounting | G19: Condensed Financials | H19: C45 | I19: =SUMIF($B$6:$B$31,"Operating Working Capital Liability",D$6:D$31) | J19: 1397855 | K19: 0.01 | M19: Use SUMIF over the classification column for Operating Working Capital Liability. | O19: pending | P19: owcl_agg | Q19: 8 | R19: 1 | S19: 2024-01-28
A20: owcl_agg__20250202 | B20: 31 | C20: Operating working capital liabilities | D20: Aggregate the classified balance-sheet detail with the classification column. | E20: condensed.owcl.2025-02-02 | F20: accounting | G20: Condensed Financials | H20: D45 | I20: =SUMIF($B$6:$B$31,"Operating Working Capital Liability",E$6:E$31) | J20: 1564476 | K20: 0.01 | M20: Use SUMIF over the classification column for Operating Working Capital Liability. | O20: pending | P20: owcl_agg | Q20: 8 | R20: 2 | S20: 2025-02-02
A21: owcl_agg__20260201 | B21: 32 | C21: Operating working capital liabilities | D21: Aggregate the classified balance-sheet detail with the classification column. | E21: condensed.owcl.2026-02-01 | F21: accounting | G21: Condensed Financials | H21: E45 | I21: =SUMIF($B$6:$B$31,"Operating Working Capital Liability",F$6:F$31) | J21: 1588824 | K21: 0.01 | M21: Use SUMIF over the classification column for Operating Working Capital Liability. | O21: pending | P21: owcl_agg | Q21: 8 | R21: 3 | S21: 2026-02-01
A22: nowc_agg__20230129 | B22: 33 | C22: Net Operating Working Capital (NOWC) | D22: Sum operating WC assets minus operating WC liabilities. | E22: condensed.nowc.2023-01-29 | F22: accounting | G22: Condensed Financials | H22: B46 | I22: =B44-B45 | J22: 691805 | K22: 0.01 | L22: owca_agg__20230129,owcl_agg__20230129 | M22: Use SUMIF over the classification column for 'Operating Working Capital Asset'.|Subtract SUMIF for 'Operating Working Capital Liability'.|NOWC = Op. WC Assets − Op. WC Liabilities. | O22: pending | P22: nowc_agg | Q22: 9 | R22: 0 | S22: 2023-01-29
A23: nowc_agg__20240128 | B23: 34 | C23: Net Operating Working Capital (NOWC) | D23: Sum operating WC assets minus operating WC liabilities. | E23: condensed.nowc.2024-01-28 | F23: accounting | G23: Condensed Financials | H23: C46 | I23: =C44-C45 | J23: 418751 | K23: 0.01 | L23: owca_agg__20240128,owcl_agg__20240128 | M23: Use SUMIF over the classification column for 'Operating Working Capital Asset'.|Subtract SUMIF for 'Operating Working Capital Liability'.|NOWC = Op. WC Assets − Op. WC Liabilities. | O23: pending | P23: nowc_agg | Q23: 9 | R23: 1 | S23: 2024-01-28
A24: nowc_agg__20250202 | B24: 35 | C24: Net Operating Working Capital (NOWC) | D24: Sum operating WC assets minus operating WC liabilities. | E24: condensed.nowc.2025-02-02 | F24: accounting | G24: Condensed Financials | H24: D46 | I24: =D44-D45 | J24: 431490 | K24: 0.01 | L24: owca_agg__20250202,owcl_agg__20250202 | M24: Use SUMIF over the classification column for 'Operating Working Capital Asset'.|Subtract SUMIF for 'Operating Working Capital Liability'.|NOWC = Op. WC Assets − Op. WC Liabilities. | O24: pending | P24: nowc_agg | Q24: 9 | R24: 2 | S24: 2025-02-02
A25: nowc_agg__20260201 | B25: 36 | C25: Net Operating Working Capital (NOWC) | D25: Sum operating WC assets minus operating WC liabilities. | E25: condensed.nowc.2026-02-01 | F25: accounting | G25: Condensed Financials | H25: E46 | I25: =E44-E45 | J25: 866675 | K25: 0.01 | L25: owca_agg__20260201,owcl_agg__20260201 | M25: Use SUMIF over the classification column for 'Operating Working Capital Asset'.|Subtract SUMIF for 'Operating Working Capital Liability'.|NOWC = Op. WC Assets − Op. WC Liabilities. | O25: pending | P25: nowc_agg | Q25: 9 | R25: 3 | S25: 2026-02-01
A26: olta_agg__20230129 | B26: 37 | C26: Operating long-term assets | D26: Aggregate the classified balance-sheet detail with the classification column. | E26: condensed.olta.2023-01-29 | F26: accounting | G26: Condensed Financials | H26: B47 | I26: =SUMIF($B$6:$B$31,"Operating Long-Term Asset",C$6:C$31) | J26: 2447585 | K26: 0.01 | M26: Use SUMIF over the classification column for Operating Long-Term Asset. | O26: pending | P26: olta_agg | Q26: 10 | R26: 0 | S26: 2023-01-29
A27: olta_agg__20240128 | B27: 38 | C27: Operating long-term assets | D27: Aggregate the classified balance-sheet detail with the classification column. | E27: condensed.olta.2024-01-28 | F27: accounting | G27: Condensed Financials | H27: C47 | I27: =SUMIF($B$6:$B$31,"Operating Long-Term Asset",D$6:D$31) | J27: 3031364 | K27: 0.01 | M27: Use SUMIF over the classification column for Operating Long-Term Asset. | O27: pending | P27: olta_agg | Q27: 10 | R27: 1 | S27: 2024-01-28
A28: olta_agg__20250202 | B28: 39 | C28: Operating long-term assets | D28: Aggregate the classified balance-sheet detail with the classification column. | E28: condensed.olta.2025-02-02 | F28: accounting | G28: Condensed Financials | H28: D47 | I28: =SUMIF($B$6:$B$31,"Operating Long-Term Asset",E$6:E$31) | J28: 3622990 | K28: 0.01 | M28: Use SUMIF over the classification column for Operating Long-Term Asset. | O28: pending | P28: olta_agg | Q28: 10 | R28: 2 | S28: 2025-02-02
A29: olta_agg__20260201 | B29: 40 | C29: Operating long-term assets | D29: Aggregate the classified balance-sheet detail with the classification column. | E29: condensed.olta.2026-02-01 | F29: accounting | G29: Condensed Financials | H29: E47 | I29: =SUMIF($B$6:$B$31,"Operating Long-Term Asset",F$6:F$31) | J29: 4194042 | K29: 0.01 | M29: Use SUMIF over the classification column for Operating Long-Term Asset. | O29: pending | P29: olta_agg | Q29: 10 | R29: 3 | S29: 2026-02-01
A30: oltl_agg__20230129 | B30: 41 | C30: Operating long-term liabilities | D30: Aggregate the classified balance-sheet detail with the classification column. | E30: condensed.oltl.2023-01-29 | F30: accounting | G30: Condensed Financials | H30: B48 | I30: =SUMIF($B$6:$B$31,"Operating Long-Term Liability",C$6:C$31) | J30: 1145458 | K30: 0.01 | M30: Use SUMIF over the classification column for Operating Long-Term Liability. | O30: pending | P30: oltl_agg | Q30: 11 | R30: 0 | S30: 2023-01-29
A31: oltl_agg__20240128 | B31: 42 | C31: Operating long-term liabilities | D31: Aggregate the classified balance-sheet detail with the classification column. | E31: condensed.oltl.2024-01-28 | F31: accounting | G31: Condensed Financials | H31: C48 | I31: =SUMIF($B$6:$B$31,"Operating Long-Term Liability",D$6:D$31) | J31: 1462005 | K31: 0.01 | M31: Use SUMIF over the classification column for Operating Long-Term Liability. | O31: pending | P31: oltl_agg | Q31: 11 | R31: 1 | S31: 2024-01-28
A32: oltl_agg__20250202 | B32: 43 | C32: Operating long-term liabilities | D32: Aggregate the classified balance-sheet detail with the classification column. | E32: condensed.oltl.2025-02-02 | F32: accounting | G32: Condensed Financials | H32: D48 | I32: =SUMIF($B$6:$B$31,"Operating Long-Term Liability",E$6:E$31) | J32: 1714769 | K32: 0.01 | M32: Use SUMIF over the classification column for Operating Long-Term Liability. | O32: pending | P32: oltl_agg | Q32: 11 | R32: 2 | S32: 2025-02-02
A33: oltl_agg__20260201 | B33: 44 | C33: Operating long-term liabilities | D33: Aggregate the classified balance-sheet detail with the classification column. | E33: condensed.oltl.2026-02-01 | F33: accounting | G33: Condensed Financials | H33: E48 | I33: =SUMIF($B$6:$B$31,"Operating Long-Term Liability",F$6:F$31) | J33: 1906079 | K33: 0.01 | M33: Use SUMIF over the classification column for Operating Long-Term Liability. | O33: pending | P33: oltl_agg | Q33: 11 | R33: 3 | S33: 2026-02-01
A34: nola_agg__20230129 | B34: 45 | C34: Net operating long-term assets (NOLA) | D34: Operating long-term assets less operating long-term liabilities. | E34: condensed.nola.2023-01-29 | F34: accounting | G34: Condensed Financials | H34: B49 | I34: =B47-B48 | J34: 1302127 | K34: 0.01 | L34: olta_agg__20230129,oltl_agg__20230129 | M34: NOLA = Operating LT Assets − Operating LT Liabilities. | O34: pending | P34: nola_agg | Q34: 12 | R34: 0 | S34: 2023-01-29
A35: nola_agg__20240128 | B35: 46 | C35: Net operating long-term assets (NOLA) | D35: Operating long-term assets less operating long-term liabilities. | E35: condensed.nola.2024-01-28 | F35: accounting | G35: Condensed Financials | H35: C49 | I35: =C47-C48 | J35: 1569359 | K35: 0.01 | L35: olta_agg__20240128,oltl_agg__20240128 | M35: NOLA = Operating LT Assets − Operating LT Liabilities. | O35: pending | P35: nola_agg | Q35: 12 | R35: 1 | S35: 2024-01-28
A36: nola_agg__20250202 | B36: 47 | C36: Net operating long-term assets (NOLA) | D36: Operating long-term assets less operating long-term liabilities. | E36: condensed.nola.2025-02-02 | F36: accounting | G36: Condensed Financials | H36: D49 | I36: =D47-D48 | J36: 1908221 | K36: 0.01 | L36: olta_agg__20250202,oltl_agg__20250202 | M36: NOLA = Operating LT Assets − Operating LT Liabilities. | O36: pending | P36: nola_agg | Q36: 12 | R36: 2 | S36: 2025-02-02
A37: nola_agg__20260201 | B37: 48 | C37: Net operating long-term assets (NOLA) | D37: Operating long-term assets less operating long-term liabilities. | E37: condensed.nola.2026-02-01 | F37: accounting | G37: Condensed Financials | H37: E49 | I37: =E47-E48 | J37: 2287963 | K37: 0.01 | L37: olta_agg__20260201,oltl_agg__20260201 | M37: NOLA = Operating LT Assets − Operating LT Liabilities. | O37: pending | P37: nola_agg | Q37: 12 | R37: 3 | S37: 2026-02-01
A38: noa_agg__20230129 | B38: 49 | C38: Net Operating Assets (NOA) | D38: NOWC plus net operating long-term assets. | E38: condensed.noa.2023-01-29 | F38: accounting | G38: Condensed Financials | H38: B50 | I38: =B46+B49 | J38: 1993932 | K38: 0.01 | L38: nowc_agg__20230129,nola_agg__20230129 | M38: Net Operating LT Assets = Op. LT Assets − Op. LT Liabilities (SUMIF).|NOA = NOWC + Net Operating LT Assets. | O38: pending | P38: noa_agg | Q38: 13 | R38: 0 | S38: 2023-01-29
A39: noa_agg__20240128 | B39: 50 | C39: Net Operating Assets (NOA) | D39: NOWC plus net operating long-term assets. | E39: condensed.noa.2024-01-28 | F39: accounting | G39: Condensed Financials | H39: C50 | I39: =C46+C49 | J39: 1988110 | K39: 0.01 | L39: nowc_agg__20240128,nola_agg__20240128 | M39: Net Operating LT Assets = Op. LT Assets − Op. LT Liabilities (SUMIF).|NOA = NOWC + Net Operating LT Assets. | O39: pending | P39: noa_agg | Q39: 13 | R39: 1 | S39: 2024-01-28
A40: noa_agg__20250202 | B40: 51 | C40: Net Operating Assets (NOA) | D40: NOWC plus net operating long-term assets. | E40: condensed.noa.2025-02-02 | F40: accounting | G40: Condensed Financials | H40: D50 | I40: =D46+D49 | J40: 2339711 | K40: 0.01 | L40: nowc_agg__20250202,nola_agg__20250202 | M40: Net Operating LT Assets = Op. LT Assets − Op. LT Liabilities (SUMIF).|NOA = NOWC + Net Operating LT Assets. | O40: pending | P40: noa_agg | Q40: 13 | R40: 2 | S40: 2025-02-02
...

Sheet _CheckContext
A1: BAV_CHECK_CONTEXT_V1
