Workbook

Sheet Trainer
A1: BAV Excel Trainer
A2: Complete each historical model-construction and earnings-quality diagnostic formula schedule left-to-right in dependency order. Run Check to validate the yellow formula cells against the treatment currently selected in Accounting Judgment column F (blank F uses the supplied reference treatment). Generated Condensed Financials classification links are system-controlled and validated by Check—do not edit them or columns D:E. When Normalization Judgment is present, choose Recurring vs Non-recurring in column F (blank uses the supplied reference); Earnings Normalization formulas are checked against that choice. Also complete Accounting Judgment and Normalization Judgment rationale/consequence when cases are present; those responses are not graded by Check. Compare them with the matching Answer Key.
A4: Order | B4: Schedule | C4: Period scope | D4: Tab | E4: Practice cells | F4: Depends on
A5: 1 | B5: Revenue historical source link | C5: 2023–2026 (4 cells) | D5: Condensed Financials | E5: B34:E34 | F5: —
A6: 2 | B6: Net Income historical source link | C6: 2023–2026 (4 cells) | D6: Condensed Financials | E6: B35:E35 | F6: —
A7: 3 | B7: Effective tax rate | C7: 2023–2026 (4 cells) | D7: Condensed Financials | E7: B38:E38 | F7: —
A8: 7 | B8: Operating working capital assets | C8: 2023–2026 (4 cells) | D8: Condensed Financials | E8: B44:E44 | F8: —
A9: 8 | B9: Operating working capital liabilities | C9: 2023–2026 (4 cells) | D9: Condensed Financials | E9: B45:E45 | F9: —
A10: 9 | B10: Net Operating Working Capital (NOWC) | C10: 2023–2026 (4 cells) | D10: Condensed Financials | E10: B46:E46 | F10: owca_agg, owcl_agg
A11: 10 | B11: Operating long-term assets | C11: 2023–2026 (4 cells) | D11: Condensed Financials | E11: B47:E47 | F11: —
A12: 11 | B12: Operating long-term liabilities | C12: 2023–2026 (4 cells) | D12: Condensed Financials | E12: B48:E48 | F12: —
A13: 12 | B13: Net operating long-term assets (NOLA) | C13: 2023–2026 (4 cells) | D13: Condensed Financials | E13: B49:E49 | F13: olta_agg, oltl_agg
A14: 13 | B14: Net Operating Assets (NOA) | C14: 2023–2026 (4 cells) | D14: Condensed Financials | E14: B50:E50 | F14: nowc_agg, nola_agg
A15: 14 | B15: Financial assets | C15: 2023–2026 (4 cells) | D15: Condensed Financials | E15: B51:E51 | F15: —
A16: 15 | B16: Financial liabilities | C16: 2023–2026 (4 cells) | D16: Condensed Financials | E16: B52:E52 | F16: —
... A78: 121 | B78: PP&E Capex / Revenue | C78: 2023–2026 (4 cells) | D78: ALT DuPont | E78: B63:E63 | F78: ppe_capex, revenue_link

Sheet Income Statement
A1: Company: lululemon athletica inc. (LULU)
A2: Statement: Income Statement
A3: Units: USD in Thousands
A4: Source: manual ingestion (US)
A6: Line Item | B6: 44955 | C6: 45319 | D6: 45690 | E6: 46054
A7: Foreign currency translation adjustment | B7: -65571 | C7: -23077 | D7: -253209 | E7: 253160
A8: Net investment hedge gains (losses) | B8: 8904 | C8: 11405 | D8: 93024 | E8: -59409
A9: Amortization of intangible assets | B9: 8752 | C9: 5010 | D9: 2735 | E9: 6961
A10: Basic earnings per share | B10: 6.7 | C10: 12.23 | D10: 14.67 | E10: 13.27
A11: Comprehensive income | B11: 798133 | C11: 1538518 | D11: 1654431 | E11: 1772934
A12: Cost of goods sold | B12: 3618178 | C12: 4009873 | D12: 4317315 | E12: 4818468
A13: Diluted earnings per share | B13: 6.68 | C13: 12.2 | D13: 14.64 | E13: 13.26
A14: Gross profit | B14: 4492340 | C14: 5609405 | D14: 6270811 | E14: 6284132
A15: Income before income tax expense | B15: 1332571 | C15: 2175735 | D15: 2576077 | E15: 2238967
A16: Income from operations | B16: 1328408 | C16: 2132676 | D16: 2505697 | E16: 2210615
A17: Income tax expense | B17: 477771 | C17: 625545 | D17: 761461 | E17: 659784
... A22: Selling, general and administrative expenses | B22: 2757447 | C22: 3397218 | D22: 3762379 | E22: 4066556

Sheet Balance Sheet
A1: Company: lululemon athletica inc. (LULU)
A2: Statement: Balance Sheet
A3: Units: USD in Thousands
A4: Source: manual ingestion (US)
A6: Line Item | B6: 44955 | C6: 45319 | D6: 45690 | E6: 46054
A7: Accounts receivable, net | B7: 132906 | C7: 124769 | D7: 120173 | E7: 190657
A8: Cash and cash equivalents | B8: 1154867 | C8: 2243971 | D8: 1984336 | E8: 1807202
A9: Inventories | B9: 1447367 | C9: 1323602 | D9: 1442081 | E9: 1700753
A10: Prepaid and receivable income taxes | B10: 185641 | C10: 183733 | D10: 182253 | E10: 352469
A11: Prepaid expenses and other current assets | B11: 238672 | C11: 184502 | D11: 251459 | E11: 211620
A12: Total current assets | B12: 3159453 | C12: 4060577 | D12: 3980302 | E12: 4262701
A13: Accounts payable | B13: 172732 | C13: 348441 | D13: 271406 | E13: 331421
A14: Accrued compensation and related expenses | B14: 248167 | C14: 326110 | D14: 204543 | E14: 187887
A15: Accrued liabilities and other | B15: 399223 | C15: 348555 | D15: 559463 | E15: 662982
A16: Current income taxes payable | B16: 174221 | C16: 12098 | D16: 183126 | E16: 43948
A17: Current lease liabilities | B17: 207972 | C17: 249270 | D17: 275154 | E17: 298724
... A27: Deferred income tax liabilities | B27: 55084 | C27: 29522 | D27: 98188 | E27: 52278
A28: Non-current income taxes payable | B28: 28555 | C28: 15864 | D28: 0
A29: Non-current lease liabilities | B29: 862362 | C29: 1154012 | D29: 1300637 | E29: 1499717
A30: Other non-current liabilities | B30: 20040 | C30: 29201 | D30: 40790 | E30: 55360
A31: Accumulated other comprehensive loss | B31: -252584 | C31: -264256 | D31: -424441 | E31: -230690
A32: Additional paid-in capital | B32: 474645 | C32: 575369 | D32: 638190 | E32: 669392
A33: Common stock | B33: 611 | C33: 606 | D33: 581 | E33: 557
A34: Retained earnings | B34: 2926127 | C34: 3920362 | D34: 4109717 | E34: 4522581
A35: Total stockholders' equity | B35: 3148799 | C35: 4232081 | D35: 4324047 | E35: 4961840
A36: Total assets | B36: 5607038 | C36: 7091941 | D36: 7603292 | E36: 8456743
A37: Total liabilities and stockholders' equity | B37: 5607038 | C37: 7091941 | D37: 7603292 | E37: 8456743
A38: Total liabilities | B38: 2458239 | C38: 2859860 | D38: 3279245 | E38: 3494903

Sheet Cash Flow Statement
A1: Company: lululemon athletica inc. (LULU)
A2: Statement: Cash Flow Statement
A3: Units: USD in Thousands
A4: Source: manual ingestion (US)
A6: Line Item | B6: 44955 | C6: 45319 | D6: 45690 | E6: 46054
A7: Net cash used in financing activities | B7: -467487 | C7: -548828 | D7: -1652508 | E7: -1208656
A8: Other financing activities | B8: -32 | C8: -32 | D8: -32 | E8: -11312
A9: Proceeds from settlement of stock-based compensation | B9: 11704 | C9: 42430 | D9: 19813 | E9: 8377
A10: Repurchase of common stock | B10: -444001 | C10: -558652 | D10: -1636879 | E10: -1178349
A11: Shares withheld related to net share settlement of stock-based compensation | B11: -35158 | C11: -32574 | D11: -35410 | E11: -27372
A12: Acquisition, net of cash acquired | B12: 0 | C12: 0 | D12: -154146 | E12: 0
A13: Net cash used in investing activities | B13: -569937 | C13: -654132 | D13: -798174 | E13: -662118
A14: Other investing activities | B14: 20916 | C14: -658 | D14: -5009 | E14: -8521
A15: Purchase of property and equipment | B15: -638657 | C15: -651865 | D15: -689232 | E15: -680802
A16: Settlement of net investment hedges | B16: 47804 | C16: -1609 | D16: 50213 | E16: 27205
A17: Accounts payable | B17: -107280 | C17: 177367 | D17: -57044 | E17: 45856
... A40: Increase (decrease) in cash and cash equivalents | B40: -105004 | C40: 1089104 | D40: -259635 | E40: -177134

Sheet Condensed Financials
A1: lululemon athletica inc. (LULU) — Condensed Financials
A4: BALANCE SHEET CLASSIFICATION
A5: Line Item | B5: Classification | C5: 44955 | D5: 45319 | E5: 45690 | F5: 46054 | G5: Notes
A6: Accounts receivable, net | B6: Operating Working Capital Asset | C6: 132906 | D6: 124769 | E6: 120173 | F6: 190657
A7: Cash and cash equivalents | B7: Financial Asset | C7: 1154867 | D7: 2243971 | E7: 1984336 | F7: 1807202
A8: Inventories | B8: Operating Working Capital Asset | C8: 1447367 | D8: 1323602 | E8: 1442081 | F8: 1700753
A9: Prepaid and receivable income taxes | B9: Operating Working Capital Asset | C9: 185641 | D9: 183733 | E9: 182253 | F9: 352469
A10: Prepaid expenses and other current assets | B10: Operating Working Capital Asset | C10: 238672 | D10: 184502 | E10: 251459 | F10: 211620
A11: Accounts payable | B11: Operating Working Capital Liability | C11: 172732 | D11: 348441 | E11: 271406 | F11: 331421
A12: Accrued compensation and related expenses | B12: Operating Working Capital Liability | C12: 248167 | D12: 326110 | E12: 204543 | F12: 187887
A13: Accrued liabilities and other | B13: Operating Working Capital Liability | C13: 399223 | D13: 348555 | E13: 559463 | F13: 662982
A14: Current income taxes payable | B14: Operating Working Capital Liability | C14: 174221 | D14: 12098 | E14: 183126 | F14: 43948
A15: Current lease liabilities | B15: =IF('Accounting Judgment'!$F$5="","Operating Long-Term Liability",'Accounting Judgment'!$F$5) | C15: 207972 | D15: 249270 | E15: 275154 | F15: 298724 | G15: ⚠ Review: Lease liability concept — operating vs financial judgment
A16: Other current liabilities | B16: =IF('Accounting Judgment'!$F$6="","Operating Working Capital Liability",'Accounting Judgment'!$F$6) | C16: 38405 | D16: 40308 | E16: 37586 | F16: 45954 | G16: ⚠ Review: Explicit residual balance-sheet concept identifies side/horizon but not economic nature — operating vs financial judgment
A17: Unredeemed gift card liability | B17: Operating Working Capital Liability | C17: 251478 | D17: 306479 | E17: 308352 | F17: 316632
A18: Deferred income tax assets | B18: Operating Long-Term Asset | C18: 6402 | D18: 9176 | E18: 17085 | F18: 24037 | G18: ⚠ Review: Deferred tax asset concept — operating vs exclude judgment
A19: Goodwill | B19: Operating Long-Term Asset | C19: 24144 | D19: 24083 | E19: 159518 | F19: 184911
A20: Intangible assets, net | B20: Operating Long-Term Asset | C20: 21961 | D20: 0 | E20: 11673 | F20: 6283
A21: Other non-current assets | B21: =IF('Accounting Judgment'!$F$7="","Operating Long-Term Asset",'Accounting Judgment'!$F$7) | C21: 156045 | D21: 186684 | E21: 237841 | F21: 314910 | G21: ⚠ Review: Explicit residual balance-sheet concept identifies side/horizon but not economic nature — operating vs financial judgment
A22: Property and equipment, net | B22: Operating Long-Term Asset | C22: 1269614 | D22: 1545811 | E22: 1780617 | F22: 2033720
A23: Right-of-use lease assets | B23: Operating Long-Term Asset | C23: 969419 | D23: 1265610 | E23: 1416256 | F23: 1630181 | G23: ⚠ Review: Lease/ROU asset concept — operating vs financial judgment
A24: Deferred income tax liabilities | B24: Operating Long-Term Liability | C24: 55084 | D24: 29522 | E24: 98188 | F24: 52278 | G24: ⚠ Review: Deferred tax liability concept — operating vs exclude judgment
A25: Non-current income taxes payable | B25: Operating Working Capital Liability | C25: 28555 | D25: 15864 | E25: 0
A26: Non-current lease liabilities | B26: =IF('Accounting Judgment'!$F$8="","Operating Long-Term Liability",'Accounting Judgment'!$F$8) | C26: 862362 | D26: 1154012 | E26: 1300637 | F26: 1499717 | G26: ⚠ Review: Lease liability concept — operating vs financial judgment
A27: Other non-current liabilities | B27: =IF('Accounting Judgment'!$F$9="","Operating Long-Term Liability",'Accounting Judgment'!$F$9) | C27: 20040 | D27: 29201 | E27: 40790 | F27: 55360 | G27: ⚠ Review: Explicit residual balance-sheet concept identifies side/horizon but not economic nature — operating vs financial judgment
A28: Accumulated other comprehensive loss | B28: Equity | C28: -252584 | D28: -264256 | E28: -424441 | F28: -230690
A29: Additional paid-in capital | B29: Equity | C29: 474645 | D29: 575369 | E29: 638190 | F29: 669392
A30: Common stock | B30: Equity | C30: 611 | D30: 606 | E30: 581 | F30: 557
A31: Retained earnings | B31: Equity | C31: 2926127 | D31: 3920362 | E31: 4109717 | F31: 4522581
A33: CONDENSED INCOME STATEMENT | B33: 44955 | C33: 45319 | D33: 45690 | E33: 46054
A34: Revenue
A35: Net Income
A36: Pretax Income | B36: ='Income Statement'!B15 | C36: ='Income Statement'!C15 | D36: ='Income Statement'!D15 | E36: ='Income Statement'!E15
A37: Tax Expense | B37: ='Income Statement'!B17 | C37: ='Income Statement'!C17 | D37: ='Income Statement'!D17 | E37: ='Income Statement'!E17
A38: Effective Tax Rate
A39: Net Interest | B39: Source unavailable | C39: Source unavailable | D39: Source unavailable | E39: Source unavailable
A40: Net Interest After Tax | B40: Source unavailable | C40: Source unavailable | D40: Source unavailable | E40: Source unavailable
A41: NOPAT | B41: Source unavailable | C41: Source unavailable | D41: Source unavailable | E41: Source unavailable
A43: CONDENSED BALANCE SHEET
A44: Operating Working Capital Assets
...

Sheet ALT DuPont
A1: lululemon athletica inc. — DuPont Decomposition
A2: ROE = RNOA + FLEV × Spread
A4: Metric | B4: 44955 | C4: 45319 | D4: 45690 | E4: 46054
A5: Sales Growth | B5: N/A
A6: NOPAT Margin | B6: Source unavailable | C6: Source unavailable | D6: Source unavailable | E6: Source unavailable
A7: RNOA | B7: N/A | C7: Source unavailable | D7: Source unavailable | E7: Source unavailable
A8: After-tax CoD | B8: N/A | C8: Source unavailable | D8: Source unavailable | E8: Source unavailable
A9: Spread | B9: N/A | C9: Source unavailable | D9: Source unavailable | E9: Source unavailable
A10: FLEV | B10: N/A
A11: ROE (decomposed) | B11: N/A | C11: Source unavailable | D11: Source unavailable | E11: Source unavailable
A12: Actual ROE | B12: N/A
A14: RNOA DRIVER DECOMPOSITION
A15: Average NOA | B15: N/A
A16: NOA Turnover | B16: N/A
A17: NOA Intensity | B17: N/A
A18: RNOA from Margin × Turnover | B18: N/A | C18: Source unavailable | D18: Source unavailable | E18: Source unavailable
A19: RNOA DRIVER CHECK | B19: N/A | C19: Source unavailable | D19: Source unavailable | E19: Source unavailable
A21: RNOA CHANGE ATTRIBUTION
A22: Change in NOPAT Margin | B22: N/A | C22: N/A | D22: Source unavailable | E22: Source unavailable
A23: Change in NOA Turnover | B23: N/A | C23: N/A
A24: Direct Change in RNOA | B24: N/A | C24: N/A | D24: Source unavailable | E24: Source unavailable
A25: Margin Effect on RNOA Change | B25: N/A | C25: N/A | D25: Source unavailable | E25: Source unavailable
A26: Turnover Effect on RNOA Change | B26: N/A | C26: N/A | D26: Source unavailable | E26: Source unavailable
A27: RNOA Change from Drivers | B27: N/A | C27: N/A | D27: Source unavailable | E27: Source unavailable
A28: RNOA CHANGE DRIVER CHECK | B28: N/A | C28: N/A | D28: Source unavailable | E28: Source unavailable
A30: ROE OPERATING / FINANCING ATTRIBUTION
A31: Financing Contribution to ROE | B31: N/A | C31: Source unavailable | D31: Source unavailable | E31: Source unavailable
A32: ROE LEVEL ATTRIBUTION CHECK | B32: N/A | C32: Source unavailable | D32: Source unavailable | E32: Source unavailable
A34: ROE CHANGE ATTRIBUTION
A35: Direct Change in Decomposed ROE | B35: N/A | C35: N/A | D35: Source unavailable | E35: Source unavailable
A36: Operating Effect on Change in ROE | B36: N/A | C36: N/A | D36: Source unavailable | E36: Source unavailable
A37: Leverage Effect on Change in ROE | B37: N/A | C37: N/A | D37: Source unavailable | E37: Source unavailable
A38: Spread Effect on Change in ROE | B38: N/A | C38: N/A | D38: Source unavailable | E38: Source unavailable
A39: Financing Effect on Change in ROE | B39: N/A | C39: N/A | D39: Source unavailable | E39: Source unavailable
A40: Change in ROE from Drivers | B40: N/A | C40: N/A | D40: Source unavailable | E40: Source unavailable
A41: ROE CHANGE ATTRIBUTION CHECK | B41: N/A | C41: N/A | D41: Source unavailable | E41: Source unavailable
A43: FIXED-ASSET INTENSITY CONTEXT
A44: Property, Plant & Equipment
A45: Depreciation & Amortisation
A46: Average PP&E | B46: N/A
...

Sheet Accounting Judgment
A1: Accounting Judgment
A2: The supplied treatment is the model's reference treatment, not a universal accounting truth. Compare it with the listed alternative(s), choose the treatment you would defend, and explain the economic consequence.
A3: Choose a treatment in column F only. That choice drives the matching Condensed Financials classification and downstream historical schedules; leaving F blank uses the supplied reference treatment. Columns D:E are display context and must not be edited. Enter your rationale and economic consequence in G:H. Formula Check grades formula cells against the treatment currently selected in F and validates that the generated classification links remain intact; it does not grade the judgment response itself. Do not edit the linked Condensed Financials classification cell directly.
A4: Order | B4: Line item | C4: Topic | D4: Supplied reference treatment | E4: Alternative(s) to evaluate | F4: Treatment to defend | G4: Rationale | H4: Economic consequence
A5: 1 | B5: Current lease liabilities | C5: Lease liability operating vs financing | D5: Operating Long-Term Liability | E5: Financial Liability
A6: 2 | B6: Other current liabilities | C6: Other current liability: operating vs financial | D6: Operating Working Capital Liability | E6: Financial Liability
A7: 3 | B7: Other non-current assets | C7: Other non-current asset: operating vs financial | D7: Operating Long-Term Asset | E7: Financial Asset
A8: 4 | B8: Non-current lease liabilities | C8: Lease liability operating vs financing | D8: Operating Long-Term Liability | E8: Financial Liability
A9: 5 | B9: Other non-current liabilities | C9: Other non-current liability: operating vs financial | D9: Operating Long-Term Liability | E9: Financial Liability

Sheet Earnings Quality
A1: lululemon athletica inc. — Earnings Quality
A2: Historical cash-conversion and accrual diagnostics. These are mechanical diagnostics, not an automatic quality score.
A4: Metric | B4: 44955 | C4: 45319 | D4: 45690 | E4: 46054
A5: Operating Cash Flow
A6: Reported Net Income | B6: ='Condensed Financials'!B35 | C6: ='Condensed Financials'!C35 | D6: ='Condensed Financials'!D35 | E6: ='Condensed Financials'!E35
A7: Cash Conversion Ratio
A8: Total Accruals (Net Income - CFO)
A10: Total Assets | B10: ='Balance Sheet'!B36 | C10: ='Balance Sheet'!C36 | D10: ='Balance Sheet'!D36 | E10: ='Balance Sheet'!E36
A11: Average Total Assets
A12: Accrual Ratio
A14: EARNINGS QUALITY TREND DIAGNOSTICS
A15: Change in Operating Cash Flow | B15: N/A
A16: Change in Cash Conversion Ratio | B16: N/A
A17: Change in Total Accruals | B17: N/A
A18: Change in Accrual Ratio | B18: N/A | C18: N/A
A19: EARNINGS QUALITY CHANGE CHECK | B19: N/A | C19: =IF(ABS(C17-((C6-B6)-C15))<0.01,"OK","CHECK") | D19: =IF(ABS(D17-((D6-C6)-D15))<0.01,"OK","CHECK") | E19: =IF(ABS(E17-((E6-D6)-E15))<0.01,"OK","CHECK")

Sheet Working Capital Analysis
A1: Working Capital Analysis
A2: Relate classified operating working capital to Revenue and identify how much incremental NOWC accompanies changes in sales.
A3: These are diagnostics, not automatic judgments. Positive Change in NOWC is an operating cash use; negative Change in NOWC is a release. Annual data alone does not prove seasonality or deterioration.
A5: Metric | B5: 44955 | C5: 45319 | D5: 45690 | E5: 46054
A6: Revenue | B6: ='Condensed Financials'!B34 | C6: ='Condensed Financials'!C34 | D6: ='Condensed Financials'!D34 | E6: ='Condensed Financials'!E34
A7: Operating Working Capital Assets | B7: ='Condensed Financials'!B44 | C7: ='Condensed Financials'!C44 | D7: ='Condensed Financials'!D44 | E7: ='Condensed Financials'!E44
A8: Operating Working Capital Liabilities | B8: ='Condensed Financials'!B45 | C8: ='Condensed Financials'!C45 | D8: ='Condensed Financials'!D45 | E8: ='Condensed Financials'!E45
A9: NOWC | B9: ='Condensed Financials'!B46 | C9: ='Condensed Financials'!C46 | D9: ='Condensed Financials'!D46 | E9: ='Condensed Financials'!E46
A11: OWCA / Revenue
A12: OWCL / Revenue
A13: NOWC / Revenue
A14: Change in Revenue | B14: N/A
A15: Change in NOWC | B15: N/A
A16: Incremental NOWC / Change in Revenue | B16: N/A
A18: WORKING-CAPITAL DRIVER DECOMPOSITION
A19: Change in OWCA | B19: N/A
A20: Change in OWCL | B20: N/A
A21: Change in NOWC from Components | B21: N/A
A22: Incremental OWCA / Change in Revenue | B22: N/A
A23: Incremental OWCL / Change in Revenue | B23: N/A
A24: DRIVER DECOMPOSITION CHECK | B24: N/A | C24: =IF(ABS(C21-C15)<0.01,"OK","CHECK") | D24: =IF(ABS(D21-D15)<0.01,"OK","CHECK") | E24: =IF(ABS(E21-E15)<0.01,"OK","CHECK")

Sheet Per Share Analysis
A1: lululemon athletica inc. — Per Share Analysis
A2: Historical per-share diagnostics using supplied diluted weighted-average shares. Share counts are source inputs, not practice cells.
A4: Metric | B4: 44955 | C4: 45319 | D4: 45690 | E4: 46054
A5: Reported Net Income | B5: ='Condensed Financials'!B35 | C5: ='Condensed Financials'!C35 | D5: ='Condensed Financials'!D35 | E5: ='Condensed Financials'!E35
A6: NOPAT | B6: Source unavailable | C6: Source unavailable | D6: Source unavailable | E6: Source unavailable
A7: Diluted Weighted-Average Shares | B7: 128017 | C7: 127060 | D7: 123935 | E7: 119068
A8: Share Basis: Reported basis
A9: Diluted EPS (Comparable Basis)
A10: NOPAT per Diluted Share | B10: Source unavailable | C10: Source unavailable | D10: Source unavailable | E10: Source unavailable
A12: Change in Diluted EPS | B12: N/A
A13: Change in Diluted Weighted-Average Shares | B13: N/A
A15: DILUTED EPS CHANGE ATTRIBUTION
A16: Change in Per-Share Earnings Numerator | B16: N/A
A17: Earnings Effect on Change in Diluted EPS | B17: N/A
A18: Share-Count Effect on Change in Diluted EPS | B18: N/A
A19: Diluted EPS Change from Drivers | B19: N/A
A20: DILUTED EPS CHANGE ATTRIBUTION CHECK | B20: N/A | C20: =IF(ABS(C19-C12)<0.0000001,"OK","CHECK") | D20: =IF(ABS(D19-D12)<0.0000001,"OK","CHECK") | E20: =IF(ABS(E19-E12)<0.0000001,"OK","CHECK")

Sheet Model_Bear
A1: Deferred from historical-only v1

Sheet Model_Base
A1: Deferred from historical-only v1

Sheet Model_Bull
A1: Deferred from historical-only v1

Sheet Scenario_Summary
A1: Deferred from historical-only v1
